Workbook

Sheet Summary (New)
B2: MMD INT QA Result
B4: Expected Launch Date | C4: 2025.07.16
B5: QA Date | C5: 2025.07.14
B6: Pass Rate | C6: =AVERAGE(D12,D15,D18,D21,D24,D27,D30) -> 0.97916667
B9: QA Elements | C9: All Page | E9: Product Detail | G9: Product List | I9: Blog Page | K9: Page (No PLP / PDP)
B10: Total | C10: =SUM(E10:L10) -> 48 | E10: =COUNTIF('Raw (New)'!$B:$B,'Summary (New)'!E9) -> 30 | G10: =COUNTIF('Raw (New)'!$B:$B,'Summary (New)'!G9) -> 12 | I10: =COUNTIF('Raw (New)'!$B:$B,'Summary (New)'!I9) -> 1 | K10: =COUNTIF('Raw (New)'!$B:$B,'Summary (New)'!K9) -> 5
B11: Status Code
B12: Pass | C12: =SUM(E12+G12+I12+K12) -> 48 | D12: =C12/C$10 -> 1 | E12: =COUNTIFS('Raw (New)'!$B:$B,'Summary (New)'!E$9,'Raw (New)'!$D:$D,"Pass") -> 30 | F12: =E12/E$10 -> 1 | G12: =COUNTIFS('Raw (New)'!$B:$B,'Summary (New)'!G$9,'Raw (New)'!$D:$D,"Pass") -> 12 | H12: =G12/G$10 -> 1 | I12: =COUNTIFS('Raw (New)'!$B:$B,'Summary (New)'!I$9,'Raw (New)'!$D:$D,"Pass") -> 1 | J12: =I12/I$10 -> 1 | K12: =COUNTIFS('Raw (New)'!$B:$B,'Summary (New)'!K$9,'Raw (New)'!$D:$D,"Pass") -> 5 | L12: =K12/K10 -> 1
B13: has issues (301, 302, 404) | C13: =SUM(E13+G13+I13+K13) -> 0 | D13: =C13/C$10 -> 0 | E13: =COUNTIFS('Raw (New)'!$B:$B,'Summary (New)'!E$9,'Raw (New)'!$D:$D,"<>Pass") -> 0 | F13: =E13/E$10 -> 0 | G13: =COUNTIFS('Raw (New)'!$B:$B,'Summary (New)'!G$9,'Raw (New)'!$D:$D,"<>Pass") -> 0 | H13: =G13/G$10 -> 0 | I13: =COUNTIFS('Raw (New)'!$B:$B,'Summary (New)'!I$9,'Raw (New)'!$D:$D,"<>Pass") -> 0 | J13: =I13/I$10 -> 0 | K13: =COUNTIFS('Raw (New)'!$B:$B,'Summary (New)'!K$9,'Raw (New)'!$D:$D,"<>Pass") -> 0 | L13: =K13/K10 -> 0
B14: Title
B15: Pass | C15: =SUM(E15+G15+I15+K15) -> 48 | D15: =C15/C$10 -> 1 | E15: =COUNTIFS('Raw (New)'!$B:$B,'Summary (New)'!E$9,'Raw (New)'!$F:$F,"Pass") -> 30 | F15: =E15/E$10 -> 1 | G15: =COUNTIFS('Raw (New)'!$B:$B,'Summary (New)'!G$9,'Raw (New)'!$F:$F,"Pass") -> 12 | H15: =G15/G$10 -> 1 | I15: =COUNTIFS('Raw (New)'!$B:$B,'Summary (New)'!I$9,'Raw (New)'!$F:$F,"Pass") -> 1 | J15: =I15/I$10 -> 1 | K15: =COUNTIFS('Raw (New)'!$B:$B,'Summary (New)'!K$9,'Raw (New)'!$F:$F,"Pass") -> 5 | L15: =K15/K$10 -> 1
B16: has issues (separator, typo, space) | C16: =SUM(E16+G16+I16+K16) -> 0 | D16: =C16/C$10 -> 0 | E16: =COUNTIFS('Raw (New)'!$B:$B,'Summary (New)'!E$9,'Raw (New)'!$F:$F,"<>Pass") -> 0 | F16: =E16/E$10 -> 0 | G16: =COUNTIFS('Raw (New)'!$B:$B,'Summary (New)'!G$9,'Raw (New)'!$F:$F,"<>Pass") -> 0 | H16: =G16/G$10 -> 0 | I16: =COUNTIFS('Raw (New)'!$B:$B,'Summary (New)'!I$9,'Raw (New)'!$F:$F,"<>Pass") -> 0 | J16: =I16/I$10 -> 0 | K16: =COUNTIFS('Raw (New)'!$B:$B,'Summary (New)'!K$9,'Raw (New)'!$F:$F,"<>Pass") -> 0 | L16: =K16/K$10 -> 0
B17: Meta Description
B18: Pass | C18: =SUM(E18+G18+I18+K18) -> 46 | D18: =C18/C$10 -> 0.95833333 | E18: =COUNTIFS('Raw (New)'!$B:$B,'Summary (New)'!E$9,'Raw (New)'!$H:$H,"Pass") -> 30 | F18: =E18/E$10 -> 1 | G18: =COUNTIFS('Raw (New)'!$B:$B,'Summary (New)'!G$9,'Raw (New)'!$H:$H,"Pass") -> 11 | H18: =G18/G$10 -> 0.91666667 | I18: =COUNTIFS('Raw (New)'!$B:$B,'Summary (New)'!I$9,'Raw (New)'!$H:$H,"Pass") -> 0 | J18: =I18/I$10 -> 0 | K18: =COUNTIFS('Raw (New)'!$B:$B,'Summary (New)'!K$9,'Raw (New)'!$H:$H,"Pass") -> 5 | L18: =K18/K$10 -> 1
B19: has issues (missing, duplicate) | C19: =SUM(E19+G19+I19+K19) -> 2 | D19: =C19/C$10 -> 0.041666667 | E19: =COUNTIFS('Raw (New)'!$B:$B,'Summary (New)'!E$9,'Raw (New)'!$H:$H,"<>Pass") -> 0 | F19: =E19/E$10 -> 0 | G19: =COUNTIFS('Raw (New)'!$B:$B,'Summary (New)'!G$9,'Raw (New)'!$H:$H,"<>Pass") -> 1 | H19: =G19/G$10 -> 0.083333333 | I19: =COUNTIFS('Raw (New)'!$B:$B,'Summary (New)'!I$9,'Raw (New)'!$H:$H,"<>Pass") -> 1 | J19: =I19/I$10 -> 1 | K19: =COUNTIFS('Raw (New)'!$B:$B,'Summary (New)'!K$9,'Raw (New)'!$H:$H,"<>Pass") -> 0 | L19: =K19/K$10 -> 0
B20: H1
B21: Pass | C21: =SUM(E21+G21+I21+K21) -> 46 | D21: =C21/C$10 -> 0.95833333 | E21: =COUNTIFS('Raw (New)'!$B:$B,'Summary (New)'!E$9,'Raw (New)'!$K:$K,"Pass") -> 28 | F21: =E21/E$10 -> 0.93333333 | G21: =COUNTIFS('Raw (New)'!$B:$B,'Summary (New)'!G$9,'Raw (New)'!$K:$K,"Pass") -> 12 | H21: =G21/G$10 -> 1 | I21: =COUNTIFS('Raw (New)'!$B:$B,'Summary (New)'!I$9,'Raw (New)'!$K:$K,"Pass") -> 1 | J21: =I21/I$10 -> 1 | K21: =COUNTIFS('Raw (New)'!$B:$B,'Summary (New)'!K$9,'Raw (New)'!$K:$K,"Pass") -> 5 | L21: =K21/K$10 -> 1
B22: has issues (missing) | C22: =SUM(E22+G22+I22+K22) -> 2 | D22: =C22/C$10 -> 0.041666667 | E22: =COUNTIFS('Raw (New)'!$B:$B,'Summary (New)'!E$9,'Raw (New)'!$K:$K,"<>Pass") -> 2 | F22: =E22/E$10 -> 0.066666667 | G22: =COUNTIFS('Raw (New)'!$B:$B,'Summary (New)'!G$9,'Raw (New)'!$K:$K,"<>Pass") -> 0 | H22: =G22/G$10 -> 0 | I22: =COUNTIFS('Raw (New)'!$B:$B,'Summary (New)'!I$9,'Raw (New)'!$K:$K,"<>Pass") -> 0 | J22: =I22/I$10 -> 0 | K22: =COUNTIFS('Raw (New)'!$B:$B,'Summary (New)'!K$9,'Raw (New)'!$K:$K,"<>Pass") -> 0 | L22: =K22/K$10 -> 0
B23: Canonical
B24: Pass | C24: =SUM(E24+G24+I24+K24) -> 48 | D24: =C24/C$10 -> 1 | E24: =COUNTIFS('Raw (New)'!$B:$B,'Summary (New)'!E$9,'Raw (New)'!$M:$M,"Pass") -> 30 | F24: =E24/E$10 -> 1 | G24: =COUNTIFS('Raw (New)'!$B:$B,'Summary (New)'!G$9,'Raw (New)'!$M:$M,"Pass") -> 12 | H24: =G24/G$10 -> 1 | I24: =COUNTIFS('Raw (New)'!$B:$B,'Summary (New)'!I$9,'Raw (New)'!$M:$M,"Pass") -> 1 | J24: =I24/I$10 -> 1 | K24: =COUNTIFS('Raw (New)'!$B:$B,'Summary (New)'!K$9,'Raw (New)'!$M:$M,"Pass") -> 5 | L24: =K24/K$10 -> 1
B25: has issues | C25: =SUM(E25+G25+I25+K25) -> 0 | D25: =C25/C$10 -> 0 | E25: =COUNTIFS('Raw (New)'!$B:$B,'Summary (New)'!E$9,'Raw (New)'!$M:$M,"<>Pass") -> 0 | F25: =E25/E$10 -> 0 | G25: =COUNTIFS('Raw (New)'!$B:$B,'Summary (New)'!G$9,'Raw (New)'!$M:$M,"<>Pass") -> 0 | H25: =G25/G$10 -> 0 | I25: =COUNTIFS('Raw (New)'!$B:$B,'Summary (New)'!I$9,'Raw (New)'!$M:$M,"<>Pass") -> 0 | J25: =I25/I$10 -> 0 | K25: =COUNTIFS('Raw (New)'!$B:$B,'Summary (New)'!K$9,'Raw (New)'!$M:$M,"<>Pass") -> 0 | L25: =K25/K$10 -> 0
B26: Social Tag
B27: Pass | C27: =SUM(E27+G27+I27+K27) -> 45 | D27: =C27/C$10 -> 0.9375 | E27: =COUNTIFS('Raw (New)'!$B:$B,'Summary (New)'!E$9,'Raw (New)'!$X:$X,"Pass") -> 30 | F27: =E27/E$10 -> 1 | G27: =COUNTIFS('Raw (New)'!$B:$B,'Summary (New)'!G$9,'Raw (New)'!$X:$X,"Pass") -> 11 | H27: =G27/G$10 -> 0.91666667 | I27: =COUNTIFS('Raw (New)'!$B:$B,'Summary (New)'!I$9,'Raw (New)'!$X:$X,"Pass") -> 0 | J27: =I27/I$10 -> 0 | K27: =COUNTIFS('Raw (New)'!$B:$B,'Summary (New)'!K$9,'Raw (New)'!$X:$X,"Pass") -> 4 | L27: =K27/K$10 -> 0.8
B28: has issues (duplicate, need check) | C28: =SUM(E28+G28+I28+K28) -> 3 | D28: =C28/C$10 -> 0.0625 | E28: =COUNTIFS('Raw (New)'!$B:$B,'Summary (New)'!E$9,'Raw (New)'!$X:$X,"<>Pass") -> 0 | F28: =E28/E$10 -> 0 | G28: =COUNTIFS('Raw (New)'!$B:$B,'Summary (New)'!G$9,'Raw (New)'!$X:$X,"<>Pass") -> 1 | H28: =G28/G$10 -> 0.083333333 | I28: =COUNTIFS('Raw (New)'!$B:$B,'Summary (New)'!I$9,'Raw (New)'!$X:$X,"<>Pass") -> 1 | J28: =I28/I$10 -> 1 | K28: =COUNTIFS('Raw (New)'!$B:$B,'Summary (New)'!K$9,'Raw (New)'!$X:$X,"<>Pass") -> 1 | L28: =K28/K$10 -> 0.2
B29: Schema
B30: Pass | C30: =SUM(E30+G30+I30+K30) -> 48 | D30: =C30/C$10 -> 1 | E30: =COUNTIFS('Raw (New)'!$B:$B,'Summary (New)'!E$9,'Raw (New)'!$AF:$AF,"Pass") -> 30 | F30: =E30/E$10 -> 1 | G30: =COUNTIFS('Raw (New)'!$B:$B,'Summary (New)'!G$9,'Raw (New)'!$AF:$AF,"Pass") -> 12 | H30: =G30/G$10 -> 1 | I30: =COUNTIFS('Raw (New)'!$B:$B,'Summary (New)'!I$9,'Raw (New)'!$AF:$AF,"Pass") -> 1 | J30: =I30/I$10 -> 1 | K30: =COUNTIFS('Raw (New)'!$B:$B,'Summary (New)'!K$9,'Raw (New)'!$AF:$AF,"Pass") -> 5 | L30: =K30/K$10 -> 1
B31: has issues (missing) | C31: =SUM(E31+G31+I31+K31) -> 0 | D31: =C31/C$10 -> 0 | E31: =COUNTIFS('Raw (New)'!$B:$B,'Summary (New)'!E$9,'Raw (New)'!$AF:$AF,"<>Pass") -> 0 | F31: =E31/E$10 -> 0 | G31: =COUNTIFS('Raw (New)'!$B:$B,'Summary (New)'!G$9,'Raw (New)'!$AF:$AF,"<>Pass") -> 0 | H31: =G31/G$10 -> 0 | I31: =COUNTIFS('Raw (New)'!$B:$B,'Summary (New)'!I$9,'Raw (New)'!$AF:$AF,"<>Pass") -> 0 | J31: =I31/I$10 -> 0 | K31: =COUNTIFS('Raw (New)'!$B:$B,'Summary (New)'!K$9,'Raw (New)'!$AF:$AF,"<>Pass") -> 0 | L31: =K31/K$10 -> 0

Sheet Raw (New)
A1: URL | B1: Segments | C1: Status Code | D1: Status QA | E1: Title 1 | F1: Title QA | G1: Meta Description 1 | H1: Meta Description QA | I1: H1-1 | J1: H1 Count | K1: H1 QA | L1: Canonical Link Element 1 | M1: Canonical QA | N1: og title 1 | O1: og description 1 | P1: og type 1 | Q1: og sitename 1 | R1: og image 1 | S1: og image 2 | T1: og url 1 | U1: twitter title 1 | V1: twitter description 1 | W1: twitter card 1 | X1: Social QA | Y1: Schema 1 | Z1: Schema 2 | AA1: Schema 3 | AB1: Schema 4 | AC1: Schema 5 | AD1: Schema 6 | AE1: Schema 7 | AF1: Schema QA
A2: https://mamonde-int.myshopify.com/blogs/news | B2: Blog Page | C2: 200 | D2: Pass | E2: News | Mamonde International | F2: Pass | H2: missing | I2: News | J2: 1 | K2: Pass | L2: https://mamonde-int.myshopify.com/blogs/news | M2: Pass | N2: News | Mamonde International | O2: Discover Your Beauty with Mamonde. Check out our new products, best-selling products, and our brand stories | P2: website | Q2: Mamonde International | R2: http://mamonde-int.myshopify.com/cdn/shop/files/20240123_final_KR-maminde-BI_OG_img.jpg?v=1752043424 | S2: https://mamonde-int.myshopify.com/cdn/shop/files/20240123_final_KR-maminde-BI_OG_img.jpg?v=1752043424 | T2: https://mamonde-int.myshopify.com/blogs/news | U2: News | Mamonde International | V2: Discover Your Beauty with Mamonde. Check out our new products, best-selling products, and our brand stories | W2: summary_large_image | X2: duplicate (check red marked cells) | Y2: BreadcrumbList | Z2: ListItem | AA2: Organization | AF2: Pass
A3: https://mamonde-int.myshopify.com/ | B3: Page (No PLP / PDP) | C3: 200 | D3: Pass | E3: Cosmetics, Skincare & Beauty Products Inspired by Flower | Mamonde International | F3: Pass | G3: Discover Your Beauty with Mamonde. Check out our new products, best-selling products, and our brand stories | H3: Pass | I3: Mamonde International | J3: 1 | K3: Pass | L3: https://mamonde-int.myshopify.com/ | M3: Pass | N3: Cosmetics, Skincare & Beauty Products Inspired by Flower | Mamonde International | O3: Discover Your Beauty with Mamonde. Check out our new products, best-selling products, and our brand stories | P3: website | Q3: Mamonde International | R3: http://mamonde-int.myshopify.com/cdn/shop/files/20240123_final_KR-maminde-BI_OG_img.jpg?v=1752043424 | S3: https://mamonde-int.myshopify.com/cdn/shop/files/20240123_final_KR-maminde-BI_OG_img.jpg?v=1752043424 | T3: https://mamonde-int.myshopify.com/ | U3: Cosmetics, Skincare & Beauty Products Inspired by Flower | Mamonde International | V3: Discover Your Beauty with Mamonde. Check out our new products, best-selling products, and our brand stories | W3: summary_large_image | X3: duplicate (check red marked cells) | Y3: BreadcrumbList | Z3: ListItem | AA3: Organization | AB3: SearchAction | AC3: WebSite | AF3: Pass
A4: https://mamonde-int.myshopify.com/pages/best | B4: Page (No PLP / PDP) | C4: 200 | D4: Pass | E4: Mamonde - Best Product List | Mamonde International | F4: Pass | G4: Mamonde Best - All Product List | H4: Pass | I4: BEST SELLER | J4: 1 | K4: Pass | L4: https://mamonde-int.myshopify.com/pages/best | M4: Pass | N4: Mamonde - Best Product List | Mamonde International | O4: Mamonde Best - All Product List | P4: website | Q4: Mamonde International | R4: http://mamonde-int.myshopify.com/cdn/shop/files/20240123_final_KR-maminde-BI_OG_img.jpg?v=1752043424 | S4: https://mamonde-int.myshopify.com/cdn/shop/files/20240123_final_KR-maminde-BI_OG_img.jpg?v=1752043424 | T4: https://mamonde-int.myshopify.com/pages/best | U4: Mamonde - Best Product List | Mamonde International | V4: Mamonde Best - All Product List | W4: summary_large_image | X4: Pass | Y4: BreadcrumbList | Z4: ListItem | AA4: Organization | AF4: Pass
A5: https://mamonde-int.myshopify.com/pages/brand-story | B5: Page (No PLP / PDP) | C5: 200 | D5: Pass | E5: Inspired by Flowers Mamonde Brand Story - Inspired by flowers | Mamonde International | F5: Pass | G5: Learn more about Mamonde, that accentuates a woman’s beauty. Mamonde Garden, Mamonde History, and Mamonde Boutique information | H5: Pass | I5: Brand Story | J5: 1 | K5: Pass | L5: https://mamonde-int.myshopify.com/pages/brand-story | M5: Pass | N5: Inspired by Flowers Mamonde Brand Story - Inspired by flowers | Mamonde International | O5: Learn more about Mamonde, that accentuates a woman’s beauty. Mamonde Garden, Mamonde History, and Mamonde Boutique information | P5: website | Q5: Mamonde International | R5: http://mamonde-int.myshopify.com/cdn/shop/files/20240123_final_KR-maminde-BI_OG_img.jpg?v=1752043424 | S5: https://mamonde-int.myshopify.com/cdn/shop/files/20240123_final_KR-maminde-BI_OG_img.jpg?v=1752043424 | T5: https://mamonde-int.myshopify.com/pages/brand-story | U5: Inspired by Flowers Mamonde Brand Story - Inspired by flowers | Mamonde International | V5: Learn more about Mamonde, that accentuates a woman’s beauty. Mamonde Garden, Mamonde History, and Mamonde Boutique information | W5: summary_large_image | X5: Pass | Y5: BreadcrumbList | Z5: ListItem | AA5: Organization | AF5: Pass
A6: https://mamonde-int.myshopify.com/pages/contents | B6: Page (No PLP / PDP) | C6: 200 | D6: Pass | E6: YouTube - Mamonde Contents | Mamonde International | F6: Pass | G6: You can watch all Mamonde video clips from all around world. Come and discover how brilliant Mamonde products can make you more beautiful | H6: Pass | I6: Contents | J6: 1 | K6: Pass | L6: https://mamonde-int.myshopify.com/pages/contents | M6: Pass | N6: YouTube - Mamonde Contents | Mamonde International | O6: You can watch all Mamonde video clips from all around world. Come and discover how brilliant Mamonde products can make you more beautiful | P6: website | Q6: Mamonde International | R6: http://mamonde-int.myshopify.com/cdn/shop/files/20240123_final_KR-maminde-BI_OG_img.jpg?v=1752043424 | S6: https://mamonde-int.myshopify.com/cdn/shop/files/20240123_final_KR-maminde-BI_OG_img.jpg?v=1752043424 | T6: https://mamonde-int.myshopify.com/pages/contents | U6: YouTube - Mamonde Contents | Mamonde International | V6: You can watch all Mamonde video clips from all around world. Come and discover how brilliant Mamonde products can make you more beautiful | W6: summary_large_image | X6: Pass | Y6: BreadcrumbList | Z6: ListItem | AA6: Organization | AF6: Pass
A7: https://mamonde-int.myshopify.com/pages/new | B7: Page (No PLP / PDP) | C7: 200 | D7: Pass | E7: Mamonde - New Product List | Mamonde International | F7: Pass | G7: Mamonde New - All Product List | H7: Pass | I7: NEW | J7: 1 | K7: Pass | L7: https://mamonde-int.myshopify.com/pages/new | M7: Pass | N7: Mamonde - New Product List | Mamonde International | O7: Mamonde New - All Product List | P7: website | Q7: Mamonde International | R7: http://mamonde-int.myshopify.com/cdn/shop/files/20240123_final_KR-maminde-BI_OG_img.jpg?v=1752043424 | S7: https://mamonde-int.myshopify.com/cdn/shop/files/20240123_final_KR-maminde-BI_OG_img.jpg?v=1752043424 | T7: https://mamonde-int.myshopify.com/pages/new | U7: Mamonde - New Product List | Mamonde International | V7: Mamonde New - All Product List | W7: summary_large_image | X7: Pass | Y7: BreadcrumbList | Z7: ListItem | AA7: Organization | AF7: Pass
A8: https://mamonde-int.myshopify.com/products/age-control-camellia-ampoule-mask | B8: Product Detail | C8: 200 | D8: Pass | E8: Age Control Camellia Ampoule Mask | Mamonde International | F8: Pass | G8: Simultaneous firming, radiance-boost and antioxidation! Slow aging mask for daily dose of nutrients and bounciness - Age Control Camellia Ampoule Mask | H8: Pass | I8: Age Control Camellia Ampoule Mask | J8: 1 | K8: Pass | L8: https://mamonde-int.myshopify.com/products/age-control-camellia-ampoule-mask | M8: Pass | N8: Age Control Camellia Ampoule Mask | Mamonde International | O8: Simultaneous firming, radiance-boost and antioxidation! Slow aging mask for daily dose of nutrients and bounciness - Age Control Camellia Ampoule Mask | P8: product | Q8: Mamonde International | R8: http://mamonde-int.myshopify.com/cdn/shop/files/pdp_mig_2024-10-21-241018_final_KR_agecontrol_mask_PDP_thumbnail_01_1.jpg?v=1751594967 | S8: https://mamonde-int.myshopify.com/cdn/shop/files/pdp_mig_2024-10-21-241018_final_KR_agecontrol_mask_PDP_thumbnail_01_1.jpg?v=1751594967 | T8: https://mamonde-int.myshopify.com/products/age-control-camellia-ampoule-mask | U8: Age Control Camellia Ampoule Mask | Mamonde International | V8: Simultaneous firming, radiance-boost and antioxidation! Slow aging mask for daily dose of nutrients and bounciness - Age Control Camellia Ampoule Mask | W8: summary_large_image | X8: Pass | Y8: Brand | Z8: BreadcrumbList | AA8: ImageObject | AB8: ListItem | AC8: Offer | AD8: Organization | AE8: Product | AF8: Pass
A9: https://mamonde-int.myshopify.com/products/age-control-camellia-cream | B9: Product Detail | C9: 200 | D9: Pass | E9: Age Control Camellia Cream | Mamonde International | F9: Pass | G9: Ultimate firming and nourishing cream, verified to have 5 benefits for slow aging in 4 weeks - Age Control Camellia Cream | H9: Pass | I9: Age Control Camellia Cream | J9: 1 | K9: Pass | L9: https://mamonde-int.myshopify.com/products/age-control-camellia-cream | M9: Pass | N9: Age Control Camellia Cream | Mamonde International | O9: Ultimate firming and nourishing cream, verified to have 5 benefits for slow aging in 4 weeks - Age Control Camellia Cream | P9: product | Q9: Mamonde International | R9: http://mamonde-int.myshopify.com/cdn/shop/files/pdp_mig_2024-10-21-241018_final_KR_agecontrol_cream_PDP_thumbnail_01_1.jpg?v=1751594987 | S9: https://mamonde-int.myshopify.com/cdn/shop/files/pdp_mig_2024-10-21-241018_final_KR_agecontrol_cream_PDP_thumbnail_01_1.jpg?v=1751594987 | T9: https://mamonde-int.myshopify.com/products/age-control-camellia-cream | U9: Age Control Camellia Cream | Mamonde International | V9: Ultimate firming and nourishing cream, verified to have 5 benefits for slow aging in 4 weeks - Age Control Camellia Cream | W9: summary_large_image | X9: Pass | Y9: Brand | Z9: BreadcrumbList | AA9: ImageObject | AB9: ListItem | AC9: Offer | AD9: Organization | AE9: Product | AF9: Pass
A10: https://mamonde-int.myshopify.com/products/age-control-camellia-emulsion | B10: Product Detail | C10: 200 | D10: Pass | E10: Age Control Camellia Emulsion | Mamonde International | F10: Pass | G10: Moisturizing and firming emulsion, a gentle oil-moisture balancing action for enhanced firmness - Age Control Camellia Emulsion | H10: Pass | I10: Age Control Camellia Emulsion | J10: 1 | K10: Pass | L10: https://mamonde-int.myshopify.com/products/age-control-camellia-emulsion | M10: Pass | N10: Age Control Camellia Emulsion | Mamonde International | O10: Moisturizing and firming emulsion, a gentle oil-moisture balancing action for enhanced firmness - Age Control Camellia Emulsion | P10: product | Q10: Mamonde International | R10: http://mamonde-int.myshopify.com/cdn/shop/files/pdp_mig_2024-10-21-241018_final_KR_agecontrol_emulsion_PDP_thumbnail_01_1.jpg?v=1751594981 | S10: https://mamonde-int.myshopify.com/cdn/shop/files/pdp_mig_2024-10-21-241018_final_KR_agecontrol_emulsion_PDP_thumbnail_01_1.jpg?v=1751594981 | T10: https://mamonde-int.myshopify.com/products/age-control-camellia-emulsion | U10: Age Control Camellia Emulsion | Mamonde International | V10: Moisturizing and firming emulsion, a gentle oil-moisture balancing action for enhanced firmness - Age Control Camellia Emulsion | W10: summary_large_image | X10: Pass | Y10: Brand | Z10: BreadcrumbList | AA10: ImageObject | AB10: ListItem | AC10: Offer | AD10: Organization | AE10: Product | AF10: Pass
A11: https://mamonde-int.myshopify.com/products/age-control-camellia-essence-water | B11: Product Detail | C11: 200 | D11: Pass | E11: Age Control Camellia Essence Water | Mamonde International | F11: Pass | G11: Moisturizing and firming essence water for improving inner-skin hydration from the first step - Age Control Camellia Essence Water | H11: Pass | I11: Age Control Camellia Essence Water | J11: 1 | K11: Pass | L11: https://mamonde-int.myshopify.com/products/age-control-camellia-essence-water | M11: Pass | N11: Age Control Camellia Essence Water | Mamonde International | O11: Moisturizing and firming essence water for improving inner-skin hydration from the first step - Age Control Camellia Essence Water | P11: product | Q11: Mamonde International | R11: http://mamonde-int.myshopify.com/cdn/shop/files/pdp_mig_2024-10-21-241018_final_KR_agecontrol_essence_PDP_thumbnail_01_1.jpg?v=1751594975 | S11: https://mamonde-int.myshopify.com/cdn/shop/files/pdp_mig_2024-10-21-241018_final_KR_agecontrol_essence_PDP_thumbnail_01_1.jpg?v=1751594975 | T11: https://mamonde-int.myshopify.com/products/age-control-camellia-essence-water | U11: Age Control Camellia Essence Water | Mamonde International | V11: Moisturizing and firming essence water for improving inner-skin hydration from the first step - Age Control Camellia Essence Water | W11: summary_large_image | X11: Pass | Y11: Brand | Z11: BreadcrumbList | AA11: ImageObject | AB11: ListItem | AC11: Offer | AD11: Organization | AE11: Product | AF11: Pass
A12: https://mamonde-int.myshopify.com/products/age-control-camellia-serum | B12: Product Detail | C12: 200 | D12: Pass | E12: Age Control Camellia Serum | Mamonde International | F12: Pass | G12: Ultimate firming serum, verified to have 5 benefits for slow aging in 4 weeks - Age Control Camellia Serum | H12: Pass | I12: Age Control Camellia Serum | J12: 1 | K12: Pass | L12: https://mamonde-int.myshopify.com/products/age-control-camellia-serum | M12: Pass | N12: Age Control Camellia Serum | Mamonde International | O12: Ultimate firming serum, verified to have 5 benefits for slow aging in 4 weeks - Age Control Camellia Serum | P12: product | Q12: Mamonde International | R12: http://mamonde-int.myshopify.com/cdn/shop/files/pdp_mig_2024-10-21-241018_final_KR_agecontrol_serum_PDP_thumbnail_01_1.jpg?v=1751594992 | S12: https://mamonde-int.myshopify.com/cdn/shop/files/pdp_mig_2024-10-21-241018_final_KR_agecontrol_serum_PDP_thumbnail_01_1.jpg?v=1751594992 | T12: https://mamonde-int.myshopify.com/products/age-control-camellia-serum | U12: Age Control Camellia Serum | Mamonde International | V12: Ultimate firming serum, verified to have 5 benefits for slow aging in 4 weeks - Age Control Camellia Serum | W12: summary_large_image | X12: Pass | Y12: Brand | Z12: BreadcrumbList | AA12: ImageObject | AB12: ListItem | AC12: Offer | AD12: Organization | AE12: Product | AF12: Pass
A13: https://mamonde-int.myshopify.com/products/amazing-deep-mint-cleansing-foam | B13: Product Detail | C13: 200 | D13: Pass | E13: Amazing Deep Mint Cleansing Foam | Mamonde International | F13: Pass | G13: Mildly alkaline foam cleanser with mint for complete removal of pore-clogging sebum - Amazing Deep Mint Cleansing Foam | H13: Pass | I13: Amazing Deep Mint Cleansing Foam | J13: 1 | K13: Pass | L13: https://mamonde-int.myshopify.com/products/amazing-deep-mint-cleansing-foam | M13: Pass | N13: Amazing Deep Mint Cleansing Foam | Mamonde International | O13: Mildly alkaline foam cleanser with mint for complete removal of pore-clogging sebum - Amazing Deep Mint Cleansing Foam | P13: product | Q13: Mamonde International | R13: http://mamonde-int.myshopify.com/cdn/shop/files/pdp_mig_2024-01-16-20240116_final_KR-Amazing-Deep-Mint-Cleansing-Foam_pdp_thumbnail_1_1.jpg?v=1751594907 | S13: https://mamonde-int.myshopify.com/cdn/shop/files/pdp_mig_2024-01-16-20240116_final_KR-Amazing-Deep-Mint-Cleansing-Foam_pdp_thumbnail_1_1.jpg?v=1751594907 | T13: https://mamonde-int.myshopify.com/products/amazing-deep-mint-cleansing-foam | U13: Amazing Deep Mint Cleansing Foam | Mamonde International | V13: Mildly alkaline foam cleanser with mint for complete removal of pore-clogging sebum - Amazing Deep Mint Cleansing Foam | W13: summary_large_image | X13: Pass | Y13: Brand | Z13: BreadcrumbList | AA13: ImageObject | AB13: ListItem | AC13: Offer | AD13: Organization | AE13: Product | AF13: Pass
A14: https://mamonde-int.myshopify.com/products/amazing-deep-mint-clenasing-balm | B14: Product Detail | C14: 200 | D14: Pass | E14: Amazing Deep Mint Cleansing Balm | Mamonde International | F14: Pass | G14: Pore care, exfoliation, sebum control, and soothing! A deep cleansing balm crafted with three super ingredients and AHA, BHA, PHA, aiming to soften sebum and effectively eliminate blackheads and heavy makeup. - Amazing Deep Mint Cleansing Balm | H14: Pass | I14: Amazing Deep Mint Cleansing Balm | J14: 2 | K14: multiple | L14: https://mamonde-int.myshopify.com/products/amazing-deep-mint-clenasing-balm | M14: Pass | N14: Amazing Deep Mint Cleansing Balm | Mamonde International | O14: Pore care, exfoliation, sebum control, and soothing! A deep cleansing balm crafted with three super ingredients and AHA, BHA, PHA, aiming to soften sebum and effectively eliminate blackheads and heavy makeup. - Amazing Deep Mint Cleansing Balm | P14: product | Q14: Mamonde International | R14: http://mamonde-int.myshopify.com/cdn/shop/files/pdp_mig_2023-12-01-20231110_final_AMAZING-DEEP-MINT-CLENASING-BALM_pdp_thumbnail_pc_1_1.jpg?v=1751594898 | S14: https://mamonde-int.myshopify.com/cdn/shop/files/pdp_mig_2023-12-01-20231110_final_AMAZING-DEEP-MINT-CLENASING-BALM_pdp_thumbnail_pc_1_1.jpg?v=1751594898 | T14: https://mamonde-int.myshopify.com/products/amazing-deep-mint-clenasing-balm | U14: Amazing Deep Mint Cleansing Balm | Mamonde International | V14: Pore care, exfoliation, sebum control, and soothing! A deep cleansing balm crafted with three super ingredients and AHA, BHA, PHA, aiming to soften sebum and effectively eliminate blackheads and heavy makeup. - Amazing Deep Mint Cleansing Balm | W14: summary_large_image | X14: Pass | Y14: Brand | Z14: BreadcrumbList | AA14: ImageObject | AB14: ListItem | AC14: Offer | AD14: Organization | AE14: Product | AF14: Pass
A15: https://mamonde-int.myshopify.com/products/calming-shot-azulene-ampoule | B15: Product Detail | C15: 200 | D15: Pass | E15: Calming Shot Azulene Ampoule | Mamonde International | F15: Pass | G15: Hydrating shot- Soothing shot- Calming Shot clears blemish spots! - Calming Shot Azulene Ampoule | H15: Pass | I15: Calming Shot Azulene Ampoule | J15: 1 | K15: Pass | L15: https://mamonde-int.myshopify.com/products/calming-shot-azulene-ampoule | M15: Pass | N15: Calming Shot Azulene Ampoule | Mamonde International | O15: Hydrating shot- Soothing shot- Calming Shot clears blemish spots! - Calming Shot Azulene Ampoule | P15: product | Q15: Mamonde International | R15: http://mamonde-int.myshopify.com/cdn/shop/files/pdp_mig_2025-02-25-250225_final_KR_01_Calming_Shot_Azulene_Ampoule_thumbnail_1.jpg?v=1751595041 | S15: https://mamonde-int.myshopify.com/cdn/shop/files/pdp_mig_2025-02-25-250225_final_KR_01_Calming_Shot_Azulene_Ampoule_thumbnail_1.jpg?v=1751595041 | T15: https://mamonde-int.myshopify.com/products/calming-shot-azulene-ampoule | U15: Calming Shot Azulene Ampoule | Mamonde International | V15: Hydrating shot- Soothing shot- Calming Shot clears blemish spots! - Calming Shot Azulene Ampoule | W15: summary_large_image | X15: Pass | Y15: Brand | Z15: BreadcrumbList | AA15: ImageObject | AB15: ListItem | AC15: Offer | AD15: Organization | AE15: Product | AF15: Pass
A16: https://mamonde-int.myshopify.com/products/calming-shot-azulene-ampoule-mask | B16: Product Detail | C16: 200 | D16: Pass | E16: Calming Shot Azulene Ampoule Mask | Mamonde International | F16: Pass | G16: Powerful soothing and effective antioxidation with azulene & niacinamide - Calming Shot Azulene Ampoule Mask | H16: Pass | I16: Calming Shot Azulene Ampoule Mask | J16: 1 | K16: Pass | L16: https://mamonde-int.myshopify.com/products/calming-shot-azulene-ampoule-mask | M16: Pass | N16: Calming Shot Azulene Ampoule Mask | Mamonde International | O16: Powerful soothing and effective antioxidation with azulene & niacinamide - Calming Shot Azulene Ampoule Mask | P16: product | Q16: Mamonde International | R16: http://mamonde-int.myshopify.com/cdn/shop/files/pdp_mig_2024-05-30-240529_final_KR_calming-shot-azulene-ampoule-mask_pdp_thumbnail_01_1.jpg?v=1751594965 | S16: https://mamonde-int.myshopify.com/cdn/shop/files/pdp_mig_2024-05-30-240529_final_KR_calming-shot-azulene-ampoule-mask_pdp_thumbnail_01_1.jpg?v=1751594965 | T16: https://mamonde-int.myshopify.com/products/calming-shot-azulene-ampoule-mask | U16: Calming Shot Azulene Ampoule Mask | Mamonde International | V16: Powerful soothing and effective antioxidation with azulene & niacinamide - Calming Shot Azulene Ampoule Mask | W16: summary_large_image | X16: Pass | Y16: Brand | Z16: BreadcrumbList | AA16: ImageObject | AB16: ListItem | AC16: Offer | AD16: Organization | AE16: Product | AF16: Pass
A17: https://mamonde-int.myshopify.com/products/calming-shot-azulene-cream | B17: Product Detail | C17: 200 | D17: Pass | E17: Calming Shot Azulene Cream | Mamonde International | F17: Pass | G17: 2-week blemish spot relief. Moisture shot reaching 20th layer of the stratum corneum! - Calming Shot Azulene Cream | H17: Pass | I17: Calming Shot Azulene Cream | J17: 1 | K17: Pass | L17: https://mamonde-int.myshopify.com/products/calming-shot-azulene-cream | M17: Pass | N17: Calming Shot Azulene Cream | Mamonde International | O17: 2-week blemish spot relief. Moisture shot reaching 20th layer of the stratum corneum! - Calming Shot Azulene Cream | P17: product | Q17: Mamonde International | R17: http://mamonde-int.myshopify.com/cdn/shop/files/pdp_mig_2025-02-25-250225_final_KR_01_calming_shot_azulene_cream_thumbnail_1.jpg?v=1751595031 | S17: https://mamonde-int.myshopify.com/cdn/shop/files/pdp_mig_2025-02-25-250225_final_KR_01_calming_shot_azulene_cream_thumbnail_1.jpg?v=1751595031 | T17: https://mamonde-int.myshopify.com/products/calming-shot-azulene-cream | U17: Calming Shot Azulene Cream | Mamonde International | V17: 2-week blemish spot relief. Moisture shot reaching 20th layer of the stratum corneum! - Calming Shot Azulene Cream | W17: summary_large_image | X17: Pass | Y17: Brand | Z17: BreadcrumbList | AA17: ImageObject | AB17: ListItem | AC17: Offer | AD17: Organization | AE17: Product | AF17: Pass
A18: https://mamonde-int.myshopify.com/products/calming-shot-azulene-suncream | B18: Product Detail | C18: 200 | D18: Pass | E18: Calming Shot Azulene Suncream SPF50+PA++++ | Mamonde International | F18: Pass | G18: Watery moistness！Mild moisturizing sunscreen with azulene！ - Calming Shot Azulene Suncream SPF50+PA++++ | H18: Pass | I18: Calming Shot Azulene Suncream SPF50+PA++++ | J18: 1 | K18: Pass | L18: https://mamonde-int.myshopify.com/products/calming-shot-azulene-suncream | M18: Pass | N18: Calming Shot Azulene Suncream SPF50+PA++++ | Mamonde International | O18: Watery moistness！Mild moisturizing sunscreen with azulene！ - Calming Shot Azulene Suncream SPF50+PA++++ | P18: product | Q18: Mamonde International | R18: http://mamonde-int.myshopify.com/cdn/shop/files/pdp_mig_2024-05-30-240528_final_KR_calming-shot-azulene-suncream-SPF50_pdp_thumbnail_01_1.jpg?v=1751594964 | S18: https://mamonde-int.myshopify.com/cdn/shop/files/pdp_mig_2024-05-30-240528_final_KR_calming-shot-azulene-suncream-SPF50_pdp_thumbnail_01_1.jpg?v=1751594964 | T18: https://mamonde-int.myshopify.com/products/calming-shot-azulene-suncream | U18: Calming Shot Azulene Suncream SPF50+PA++++ | Mamonde International | V18: Watery moistness！Mild moisturizing sunscreen with azulene！ - Calming Shot Azulene Suncream SPF50+PA++++ | W18: summary_large_image | X18: Pass | Y18: Brand | Z18: BreadcrumbList | AA18: ImageObject | AB18: ListItem | AC18: Offer | AD18: Organization | AE18: Product | AF18: Pass
A19: https://mamonde-int.myshopify.com/products/calming-shot-azulene-toner | B19: Product Detail | C19: 200 | D19: Pass | E19: Calming Shot Azulene Toner | Mamonde International | F19: Pass | G19: Relieves skin heat and washes down sebum. Hydrating, soothing and cooling toner, a welcome rain for skin - Calming Shot Azulene Toner | H19: Pass | I19: Calming Shot Azulene Toner | J19: 1 | K19: Pass | L19: https://mamonde-int.myshopify.com/products/calming-shot-azulene-toner | M19: Pass | N19: Calming Shot Azulene Toner | Mamonde International | O19: Relieves skin heat and washes down sebum. Hydrating, soothing and cooling toner, a welcome rain for skin - Calming Shot Azulene Toner | P19: product | Q19: Mamonde International | R19: http://mamonde-int.myshopify.com/cdn/shop/files/pdp_mig_2025-02-25-250225_final_KR_01_calming_shot_azulene_toner_thumbnail_1.jpg?v=1751595042 | S19: https://mamonde-int.myshopify.com/cdn/shop/files/pdp_mig_2025-02-25-250225_final_KR_01_calming_shot_azulene_toner_thumbnail_1.jpg?v=1751595042 | T19: https://mamonde-int.myshopify.com/products/calming-shot-azulene-toner | U19: Calming Shot Azulene Toner | Mamonde International | V19: Relieves skin heat and washes down sebum. Hydrating, soothing and cooling toner, a welcome rain for skin - Calming Shot Azulene Toner | W19: summary_large_image | X19: Pass | Y19: Brand | Z19: BreadcrumbList | AA19: ImageObject | AB19: ListItem | AC19: Offer | AD19: Organization | AE19: Product | AF19: Pass
... A37: https://mamonde-int.myshopify.com/products/probiotics-ceramide-ampoule-mask | B37: Product Detail | C37: 200 | D37: Pass | E37: Probiotics Ceramide Ampoule Mask | Mamonde International | F37: Pass | G37: Moisturizing ampoule mask to hydrate and firm your moisture barrier - Probiotics Ceramide Ampoule Mask | H37: Pass | I37: Probiotics Ceramide Ampoule Mask | J37: 1 | K37: Pass | L37: https://mamonde-int.myshopify.com/products/probiotics-ceramide-ampoule-mask | M37: Pass | N37: Probiotics Ceramide Ampoule Mask | Mamonde International | O37: Moisturizing ampoule mask to hydrate and firm your moisture barrier - Probiotics Ceramide Ampoule Mask | P37: product | Q37: Mamonde International | R37: http://mamonde-int.myshopify.com/cdn/shop/files/pdp_mig_2024-03-18-240311_final_KR_probiotics-ceramide-ampoule-mask_pdp_thumbnail_01_1.jpg?v=1751594942 | S37: https://mamonde-int.myshopify.com/cdn/shop/files/pdp_mig_2024-03-18-240311_final_KR_probiotics-ceramide-ampoule-mask_pdp_thumbnail_01_1.jpg?v=1751594942 | T37: https://mamonde-int.myshopify.com/products/probiotics-ceramide-ampoule-mask | U37: Probiotics Ceramide Ampoule Mask | Mamonde International | V37: Moisturizing ampoule mask to hydrate and firm your moisture barrier - Probiotics Ceramide Ampoule Mask | W37: summary_large_image | X37: Pass | Y37: Brand | Z37: BreadcrumbList | AA37: ImageObject | AB37: ListItem | AC37: Offer | AD37: Organization | AE37: Product | AF37: Pass
A38: https://mamonde-int.myshopify.com/collections/all | B38: Product List | C38: 200 | D38: Pass | E38: Products | Mamonde International | F38: Pass | H38: missing | I38: Products | J38: 1 | K38: Pass | L38: https://mamonde-int.myshopify.com/collections/all | M38: Pass | N38: Products | Mamonde International | O38: Discover Your Beauty with Mamonde. Check out our new products, best-selling products, and our brand stories | P38: website | Q38: Mamonde International | R38: http://mamonde-int.myshopify.com/cdn/shop/files/20240123_final_KR-maminde-BI_OG_img.jpg?v=1752043424 | S38: https://mamonde-int.myshopify.com/cdn/shop/files/20240123_final_KR-maminde-BI_OG_img.jpg?v=1752043424 | T38: https://mamonde-int.myshopify.com/collections/all | U38: Products | Mamonde International | V38: Discover Your Beauty with Mamonde. Check out our new products, best-selling products, and our brand stories | W38: summary_large_image | X38: duplicate (check red marked cells) | Y38: BreadcrumbList | Z38: ListItem | AA38: Organization | AF38: Pass
A39: https://mamonde-int.myshopify.com/collections/anti-aging | B39: Product List | C39: 200 | D39: Pass | E39: Anti-aging | Mamonde International | F39: Pass | G39: Mamonde - Skin Care Anti-aging All Product List | Mamonde | H39: Pass | I39: Anti-aging | J39: 1 | K39: Pass | L39: https://mamonde-int.myshopify.com/collections/anti-aging | M39: Pass | N39: Anti-aging | Mamonde International | O39: Mamonde - Skin Care Anti-aging All Product List | Mamonde | P39: website | Q39: Mamonde International | R39: http://mamonde-int.myshopify.com/cdn/shop/collections/upscale-PLP-banner-1920.jpg?v=1749446895 | S39: https://mamonde-int.myshopify.com/cdn/shop/collections/upscale-PLP-banner-1920.jpg?v=1749446895 | T39: https://mamonde-int.myshopify.com/collections/anti-aging | U39: Anti-aging | Mamonde International | V39: Mamonde - Skin Care Anti-aging All Product List | Mamonde | W39: summary_large_image | X39: Pass | Y39: BreadcrumbList | Z39: ListItem | AA39: Organization | AF39: Pass
A40: https://mamonde-int.myshopify.com/collections/cleansing | B40: Product List | C40: 200 | D40: Pass | E40: Cleansing | Mamonde International | F40: Pass | G40: Mamonde - Skin Care Cleansing All Product List | Mamonde | H40: Pass | I40: Cleansing | J40: 1 | K40: Pass | L40: https://mamonde-int.myshopify.com/collections/cleansing | M40: Pass | N40: Cleansing | Mamonde International | O40: Mamonde - Skin Care Cleansing All Product List | Mamonde | P40: website | Q40: Mamonde International | R40: http://mamonde-int.myshopify.com/cdn/shop/files/20240123_final_KR-maminde-BI_OG_img.jpg?v=1752043424 | S40: https://mamonde-int.myshopify.com/cdn/shop/files/20240123_final_KR-maminde-BI_OG_img.jpg?v=1752043424 | T40: https://mamonde-int.myshopify.com/collections/cleansing | U40: Cleansing | Mamonde International | V40: Mamonde - Skin Care Cleansing All Product List | Mamonde | W40: summary_large_image | X40: Pass | Y40: BreadcrumbList | Z40: ListItem | AA40: Organization | AF40: Pass
A41: https://mamonde-int.myshopify.com/collections/cream | B41: Product List | C41: 200 | D41: Pass | E41: Cream | Mamonde International | F41: Pass | G41: Mamonde - Skin Care Cream All Product List | Mamonde | H41: Pass | I41: Cream | J41: 1 | K41: Pass | L41: https://mamonde-int.myshopify.com/collections/cream | M41: Pass | N41: Cream | Mamonde International | O41: Mamonde - Skin Care Cream All Product List | Mamonde | P41: website | Q41: Mamonde International | R41: http://mamonde-int.myshopify.com/cdn/shop/files/20240123_final_KR-maminde-BI_OG_img.jpg?v=1752043424 | S41: https://mamonde-int.myshopify.com/cdn/shop/files/20240123_final_KR-maminde-BI_OG_img.jpg?v=1752043424 | T41: https://mamonde-int.myshopify.com/collections/cream | U41: Cream | Mamonde International | V41: Mamonde - Skin Care Cream All Product List | Mamonde | W41: summary_large_image | X41: Pass | Y41: BreadcrumbList | Z41: ListItem | AA41: Organization | AF41: Pass
A42: https://mamonde-int.myshopify.com/collections/essence | B42: Product List | C42: 200 | D42: Pass | E42: Essence/Ampoule/Serum | Mamonde International | F42: Pass | G42: Mamonde - Skin Care Essence/Ampoule/Serum All Product List | Mamonde | H42: Pass | I42: Essence/Ampoule/Serum | J42: 1 | K42: Pass | L42: https://mamonde-int.myshopify.com/collections/essence | M42: Pass | N42: Essence/Ampoule/Serum | Mamonde International | O42: Mamonde - Skin Care Essence/Ampoule/Serum All Product List | Mamonde | P42: website | Q42: Mamonde International | R42: http://mamonde-int.myshopify.com/cdn/shop/files/20240123_final_KR-maminde-BI_OG_img.jpg?v=1752043424 | S42: https://mamonde-int.myshopify.com/cdn/shop/files/20240123_final_KR-maminde-BI_OG_img.jpg?v=1752043424 | T42: https://mamonde-int.myshopify.com/collections/essence | U42: Essence/Ampoule/Serum | Mamonde International | V42: Mamonde - Skin Care Essence/Ampoule/Serum All Product List | Mamonde | W42: summary_large_image | X42: Pass | Y42: BreadcrumbList | Z42: ListItem | AA42: Organization | AF42: Pass
A43: https://mamonde-int.myshopify.com/collections/exfoliating | B43: Product List | C43: 200 | D43: Pass | E43: Exfoliating | Mamonde International | F43: Pass | G43: Mamonde - Skin Care Exfoliating All Product List | Mamonde | H43: Pass | I43: Exfoliating | J43: 1 | K43: Pass | L43: https://mamonde-int.myshopify.com/collections/exfoliating | M43: Pass | N43: Exfoliating | Mamonde International | O43: Mamonde - Skin Care Exfoliating All Product List | Mamonde | P43: website | Q43: Mamonde International | R43: http://mamonde-int.myshopify.com/cdn/shop/files/20240123_final_KR-maminde-BI_OG_img.jpg?v=1752043424 | S43: https://mamonde-int.myshopify.com/cdn/shop/files/20240123_final_KR-maminde-BI_OG_img.jpg?v=1752043424 | T43: https://mamonde-int.myshopify.com/collections/exfoliating | U43: Exfoliating | Mamonde International | V43: Mamonde - Skin Care Exfoliating All Product List | Mamonde | W43: summary_large_image | X43: Pass | Y43: BreadcrumbList | Z43: ListItem | AA43: Organization | AF43: Pass
A44: https://mamonde-int.myshopify.com/collections/mask | B44: Product List | C44: 200 | D44: Pass | E44: Mask | Mamonde International | F44: Pass | G44: Mamonde - Skin Care Mask All Product List | Mamonde | H44: Pass | I44: Mask | J44: 1 | K44: Pass | L44: https://mamonde-int.myshopify.com/collections/mask | M44: Pass | N44: Mask | Mamonde International | O44: Mamonde - Skin Care Mask All Product List | Mamonde | P44: website | Q44: Mamonde International | R44: http://mamonde-int.myshopify.com/cdn/shop/files/20240123_final_KR-maminde-BI_OG_img.jpg?v=1752043424 | S44: https://mamonde-int.myshopify.com/cdn/shop/files/20240123_final_KR-maminde-BI_OG_img.jpg?v=1752043424 | T44: https://mamonde-int.myshopify.com/collections/mask | U44: Mask | Mamonde International | V44: Mamonde - Skin Care Mask All Product List | Mamonde | W44: summary_large_image | X44: Pass | Y44: BreadcrumbList | Z44: ListItem | AA44: Organization | AF44: Pass
A45: https://mamonde-int.myshopify.com/collections/moisturizing | B45: Product List | C45: 200 | D45: Pass | E45: Moisturizing | Mamonde International | F45: Pass | G45: Mamonde - Skin Care Moisturizing All Product List | Mamonde | H45: Pass | I45: Moisturizing | J45: 1 | K45: Pass | L45: https://mamonde-int.myshopify.com/collections/moisturizing | M45: Pass | N45: Moisturizing | Mamonde International | O45: Mamonde - Skin Care Moisturizing All Product List | Mamonde | P45: website | Q45: Mamonde International | R45: http://mamonde-int.myshopify.com/cdn/shop/files/20240123_final_KR-maminde-BI_OG_img.jpg?v=1752043424 | S45: https://mamonde-int.myshopify.com/cdn/shop/files/20240123_final_KR-maminde-BI_OG_img.jpg?v=1752043424 | T45: https://mamonde-int.myshopify.com/collections/moisturizing | U45: Moisturizing | Mamonde International | V45: Mamonde - Skin Care Moisturizing All Product List | Mamonde | W45: summary_large_image | X45: Pass | Y45: BreadcrumbList | Z45: ListItem | AA45: Organization | AF45: Pass
A46: https://mamonde-int.myshopify.com/collections/oil-control | B46: Product List | C46: 200 | D46: Pass | E46: Oil-control | Mamonde International | F46: Pass | G46: Mamonde - Skin Care Oil-control All Product List | Mamonde | H46: Pass | I46: Oil-control | J46: 1 | K46: Pass | L46: https://mamonde-int.myshopify.com/collections/oil-control | M46: Pass | N46: Oil-control | Mamonde International | O46: Mamonde - Skin Care Oil-control All Product List | Mamonde | P46: website | Q46: Mamonde International | R46: http://mamonde-int.myshopify.com/cdn/shop/files/20240123_final_KR-maminde-BI_OG_img.jpg?v=1752043424 | S46: https://mamonde-int.myshopify.com/cdn/shop/files/20240123_final_KR-maminde-BI_OG_img.jpg?v=1752043424 | T46: https://mamonde-int.myshopify.com/collections/oil-control | U46: Oil-control | Mamonde International | V46: Mamonde - Skin Care Oil-control All Product List | Mamonde | W46: summary_large_image | X46: Pass | Y46: BreadcrumbList | Z46: ListItem | AA46: Organization | AF46: Pass
A47: https://mamonde-int.myshopify.com/collections/products | B47: Product List | C47: 200 | D47: Pass | E47: Skin Care | Mamonde International | F47: Pass | G47: Mamonde - Skin Care All All Product List | Mamonde | H47: Pass | I47: Skin Care | J47: 1 | K47: Pass | L47: https://mamonde-int.myshopify.com/collections/products | M47: Pass | N47: Skin Care | Mamonde International | O47: Mamonde - Skin Care All All Product List | Mamonde | P47: website | Q47: Mamonde International | R47: http://mamonde-int.myshopify.com/cdn/shop/collections/250210_final_KR_product_PLP-banner_1920_300.jpg?v=1749446980 | S47: https://mamonde-int.myshopify.com/cdn/shop/collections/250210_final_KR_product_PLP-banner_1920_300.jpg?v=1749446980 | T47: https://mamonde-int.myshopify.com/collections/products | U47: Skin Care | Mamonde International | V47: Mamonde - Skin Care All All Product List | Mamonde | W47: summary_large_image | X47: Pass | Y47: BreadcrumbList | Z47: ListItem | AA47: Organization | AF47: Pass
A48: https://mamonde-int.myshopify.com/collections/skin | B48: Product List | C48: 200 | D48: Pass | E48: Skin/Lotion | Mamonde International | F48: Pass | G48: Mamonde - Skin Care Skin/Lotion All Product List | Mamonde | H48: Pass | I48: Skin/Lotion | J48: 1 | K48: Pass | L48: https://mamonde-int.myshopify.com/collections/skin | M48: Pass | N48: Skin/Lotion | Mamonde International | O48: Mamonde - Skin Care Skin/Lotion All Product List | Mamonde | P48: website | Q48: Mamonde International | R48: http://mamonde-int.myshopify.com/cdn/shop/files/20240123_final_KR-maminde-BI_OG_img.jpg?v=1752043424 | S48: https://mamonde-int.myshopify.com/cdn/shop/files/20240123_final_KR-maminde-BI_OG_img.jpg?v=1752043424 | T48: https://mamonde-int.myshopify.com/collections/skin | U48: Skin/Lotion | Mamonde International | V48: Mamonde - Skin Care Skin/Lotion All Product List | Mamonde | W48: summary_large_image | X48: Pass | Y48: BreadcrumbList | Z48: ListItem | AA48: Organization | AF48: Pass
A49: https://mamonde-int.myshopify.com/collections/sunscreen | B49: Product List | C49: 200 | D49: Pass | E49: Sunscreen | Mamonde International | F49: Pass | G49: Mamonde - Skin Care Sunscreen All Product List | Mamonde | H49: Pass | I49: Sunscreen | J49: 1 | K49: Pass | L49: https://mamonde-int.myshopify.com/collections/sunscreen | M49: Pass | N49: Sunscreen | Mamonde International | O49: Mamonde - Skin Care Sunscreen All Product List | Mamonde | P49: website | Q49: Mamonde International | R49: http://mamonde-int.myshopify.com/cdn/shop/files/20240123_final_KR-maminde-BI_OG_img.jpg?v=1752043424 | S49: https://mamonde-int.myshopify.com/cdn/shop/files/20240123_final_KR-maminde-BI_OG_img.jpg?v=1752043424 | T49: https://mamonde-int.myshopify.com/collections/sunscreen | U49: Sunscreen | Mamonde International | V49: Mamonde - Skin Care Sunscreen All Product List | Mamonde | W49: summary_large_image | X49: Pass | Y49: BreadcrumbList | Z49: ListItem | AA49: Organization | AF49: Pass
A50: https://mamonde-int.myshopify.com/cart | C50: 0 | D50: need check (blocked by robots.txt)
A51: https://mamonde-int.myshopify.com/collections/products?sort_by=best-selling | C51: 0 | D51: need check (blocked by robots.txt)
A52: https://mamonde-int.myshopify.com/policies/terms-of-service | C52: 0 | D52: need check (blocked by robots.txt)
A53: https://mamonde-int.myshopify.com/search?q=AzuleneAmpoule | C53: 0 | D53: need check (blocked by robots.txt)
A54: https://mamonde-int.myshopify.com/search?q=CleansingBalm | C54: 0 | D54: need check (blocked by robots.txt)
A55: https://mamonde-int.myshopify.com/search?q=PoreShrinker | C55: 0 | D55: need check (blocked by robots.txt)
A56: https://mamonde-int.myshopify.com/search?q=RoseMask | C56: 0 | D56: need check (blocked by robots.txt)

Sheet Summary
B2: RYO HK QA Result
B4: Expected Launch Date | C4: 2025.07.30
B5: QA Date | C5: 2025.07.21
B6: Pass Rate | C6: =AVERAGE(D12,D15,D18,D21,D24,D27,D30,D33) -> 0.49395161
B9: QA Elements | C9: All Page | E9: Product Detail | G9: Product List | I9: Blog Page | K9: Page (No PLP / PDP)
B10: Total | C10: =SUM(E10:L10) -> 62 | E10: =COUNTIF(Raw!$C:$C,Summary!E9) -> 19 | G10: =COUNTIF(Raw!$C:$C,Summary!G9) -> 21 | I10: =COUNTIF(Raw!$C:$C,Summary!I9) -> 7 | K10: =COUNTIF(Raw!$C:$C,Summary!K9) -> 15
B11: Address
B12: Pass | C12: =SUM(E12+G12+I12+K12) -> 50 | D12: =C12/C$10 -> 0.80645161 | E12: =COUNTIFS(Raw!$C:$C,Summary!E$9,Raw!$B:$B,"Pass") -> 19 | F12: =E12/E$10 -> 1 | G12: =COUNTIFS(Raw!$C:$C,Summary!G$9,Raw!$B:$B,"Pass") -> 14 | H12: =G12/G$10 -> 0.66666667 | I12: =COUNTIFS(Raw!$C:$C,Summary!I$9,Raw!$B:$B,"Pass") -> 2 | J12: =I12/I$10 -> 0.28571429 | K12: =COUNTIFS(Raw!$C:$C,Summary!K$9,Raw!$B:$B,"Pass") -> 15 | L12: =K12/K10 -> 1
B13: has issues (not english) | C13: =SUM(E13+G13+I13+K13) -> 12 | D13: =C13/C$10 -> 0.19354839 | E13: =COUNTIFS(Raw!$C:$C,Summary!E$9,Raw!$B:$B,"<>Pass") -> 0 | F13: =E13/E$10 -> 0 | G13: =COUNTIFS(Raw!$C:$C,Summary!G$9,Raw!$B:$B,"<>Pass") -> 7 | H13: =G13/G$10 -> 0.33333333 | I13: =COUNTIFS(Raw!$C:$C,Summary!I$9,Raw!$B:$B,"<>Pass") -> 5 | J13: =I13/I$10 -> 0.71428571 | K13: =COUNTIFS(Raw!$C:$C,Summary!K$9,Raw!$B:$B,"<>Pass") -> 0 | L13: =K13/K10 -> 0
B14: Status Code
B15: Pass | C15: =SUM(E15+G15+I15+K15) -> 56 | D15: =C15/C$10 -> 0.90322581 | E15: =COUNTIFS(Raw!$C:$C,Summary!E$9,Raw!$E:$E,"Pass") -> 19 | F15: =E15/E$10 -> 1 | G15: =COUNTIFS(Raw!$C:$C,Summary!G$9,Raw!$E:$E,"Pass") -> 21 | H15: =G15/G$10 -> 1 | I15: =COUNTIFS(Raw!$C:$C,Summary!I$9,Raw!$E:$E,"Pass") -> 2 | J15: =I15/I$10 -> 0.28571429 | K15: =COUNTIFS(Raw!$C:$C,Summary!K$9,Raw!$E:$E,"Pass") -> 14 | L15: =K15/K10 -> 0.93333333
B16: has issues (301, 302, 404) | C16: =SUM(E16+G16+I16+K16) -> 6 | D16: =C16/C$10 -> 0.096774194 | E16: =COUNTIFS(Raw!$C:$C,Summary!E$9,Raw!$E:$E,"<>Pass") -> 0 | F16: =E16/E$10 -> 0 | G16: =COUNTIFS(Raw!$C:$C,Summary!G$9,Raw!$E:$E,"<>Pass") -> 0 | H16: =G16/G$10 -> 0 | I16: =COUNTIFS(Raw!$C:$C,Summary!I$9,Raw!$E:$E,"<>Pass") -> 5 | J16: =I16/I$10 -> 0.71428571 | K16: =COUNTIFS(Raw!$C:$C,Summary!K$9,Raw!$E:$E,"<>Pass") -> 1 | L16: =K16/K10 -> 0.066666667
B17: Title
B18: Pass | C18: =SUM(E18+G18+I18+K18) -> 28 | D18: =C18/C$10 -> 0.4516129 | E18: =COUNTIFS(Raw!$C:$C,Summary!E$9,Raw!$G:$G,"Pass") -> 19 | F18: =E18/E$10 -> 1 | G18: =COUNTIFS(Raw!$C:$C,Summary!G$9,Raw!$G:$G,"Pass") -> 0 | H18: =G18/G$10 -> 0 | I18: =COUNTIFS(Raw!$C:$C,Summary!I$9,Raw!$G:$G,"Pass") -> 0 | J18: =I18/I$10 -> 0 | K18: =COUNTIFS(Raw!$C:$C,Summary!K$9,Raw!$G:$G,"Pass") -> 9 | L18: =K18/K$10 -> 0.6
B19: has issues (separator, typo, space) | C19: =SUM(E19+G19+I19+K19) -> 34 | D19: =C19/C$10 -> 0.5483871 | E19: =COUNTIFS(Raw!$C:$C,Summary!E$9,Raw!$G:$G,"<>Pass") -> 0 | F19: =E19/E$10 -> 0 | G19: =COUNTIFS(Raw!$C:$C,Summary!G$9,Raw!$G:$G,"<>Pass") -> 21 | H19: =G19/G$10 -> 1 | I19: =COUNTIFS(Raw!$C:$C,Summary!I$9,Raw!$G:$G,"<>Pass") -> 7 | J19: =I19/I$10 -> 1 | K19: =COUNTIFS(Raw!$C:$C,Summary!K$9,Raw!$G:$G,"<>Pass") -> 6 | L19: =K19/K$10 -> 0.4
B20: Meta Description
B21: Pass | C21: =SUM(E21+G21+I21+K21) -> 24 | D21: =C21/C$10 -> 0.38709677 | E21: =COUNTIFS(Raw!$C:$C,Summary!E$9,Raw!$I:$I,"Pass") -> 19 | F21: =E21/E$10 -> 1 | G21: =COUNTIFS(Raw!$C:$C,Summary!G$9,Raw!$I:$I,"Pass") -> 4 | H21: =G21/G$10 -> 0.19047619 | I21: =COUNTIFS(Raw!$C:$C,Summary!I$9,Raw!$I:$I,"Pass") -> 0 | J21: =I21/I$10 -> 0 | K21: =COUNTIFS(Raw!$C:$C,Summary!K$9,Raw!$I:$I,"Pass") -> 1 | L21: =K21/K$10 -> 0.066666667
B22: has issues (missing, duplicate) | C22: =SUM(E22+G22+I22+K22) -> 38 | D22: =C22/C$10 -> 0.61290323 | E22: =COUNTIFS(Raw!$C:$C,Summary!E$9,Raw!$I:$I,"<>Pass") -> 0 | F22: =E22/E$10 -> 0 | G22: =COUNTIFS(Raw!$C:$C,Summary!G$9,Raw!$I:$I,"<>Pass") -> 17 | H22: =G22/G$10 -> 0.80952381 | I22: =COUNTIFS(Raw!$C:$C,Summary!I$9,Raw!$I:$I,"<>Pass") -> 7 | J22: =I22/I$10 -> 1 | K22: =COUNTIFS(Raw!$C:$C,Summary!K$9,Raw!$I:$I,"<>Pass") -> 14 | L22: =K22/K$10 -> 0.93333333
B23: H1
B24: Pass | C24: =SUM(E24+G24+I24+K24) -> 8 | D24: =C24/C$10 -> 0.12903226 | E24: =COUNTIFS(Raw!$C:$C,Summary!E$9,Raw!$L:$L,"Pass") -> 0 | F24: =E24/E$10 -> 0 | G24: =COUNTIFS(Raw!$C:$C,Summary!G$9,Raw!$L:$L,"Pass") -> 0 | H24: =G24/G$10 -> 0 | I24: =COUNTIFS(Raw!$C:$C,Summary!I$9,Raw!$L:$L,"Pass") -> 0 | J24: =I24/I$10 -> 0 | K24: =COUNTIFS(Raw!$C:$C,Summary!K$9,Raw!$L:$L,"Pass") -> 8 | L24: =K24/K$10 -> 0.53333333
B25: has issues (missing) | C25: =SUM(E25+G25+I25+K25) -> 54 | D25: =C25/C$10 -> 0.87096774 | E25: =COUNTIFS(Raw!$C:$C,Summary!E$9,Raw!$L:$L,"<>Pass") -> 19 | F25: =E25/E$10 -> 1 | G25: =COUNTIFS(Raw!$C:$C,Summary!G$9,Raw!$L:$L,"<>Pass") -> 21 | H25: =G25/G$10 -> 1 | I25: =COUNTIFS(Raw!$C:$C,Summary!I$9,Raw!$L:$L,"<>Pass") -> 7 | J25: =I25/I$10 -> 1 | K25: =COUNTIFS(Raw!$C:$C,Summary!K$9,Raw!$L:$L,"<>Pass") -> 7 | L25: =K25/K$10 -> 0.46666667
B26: Canonical
B27: Pass | C27: =SUM(E27+G27+I27+K27) -> 58 | D27: =C27/C$10 -> 0.93548387 | E27: =COUNTIFS(Raw!$C:$C,Summary!E$9,Raw!$N:$N,"Pass") -> 19 | F27: =E27/E$10 -> 1 | G27: =COUNTIFS(Raw!$C:$C,Summary!G$9,Raw!$N:$N,"Pass") -> 21 | H27: =G27/G$10 -> 1 | I27: =COUNTIFS(Raw!$C:$C,Summary!I$9,Raw!$N:$N,"Pass") -> 4 | J27: =I27/I$10 -> 0.57142857 | K27: =COUNTIFS(Raw!$C:$C,Summary!K$9,Raw!$N:$N,"Pass") -> 14 | L27: =K27/K$10 -> 0.93333333
B28: has issues | C28: =SUM(E28+G28+I28+K28) -> 4 | D28: =C28/C$10 -> 0.064516129 | E28: =COUNTIFS(Raw!$C:$C,Summary!E$9,Raw!$N:$N,"<>Pass") -> 0 | F28: =E28/E$10 -> 0 | G28: =COUNTIFS(Raw!$C:$C,Summary!G$9,Raw!$N:$N,"<>Pass") -> 0 | H28: =G28/G$10 -> 0 | I28: =COUNTIFS(Raw!$C:$C,Summary!I$9,Raw!$N:$N,"<>Pass") -> 3 | J28: =I28/I$10 -> 0.42857143 | K28: =COUNTIFS(Raw!$C:$C,Summary!K$9,Raw!$N:$N,"<>Pass") -> 1 | L28: =K28/K$10 -> 0.066666667
B29: Social Tag
B30: Pass | C30: =SUM(E30+G30+I30+K30) -> 21 | D30: =C30/C$10 -> 0.33870968 | E30: =COUNTIFS(Raw!$C:$C,Summary!E$9,Raw!$Y:$Y,"Pass") -> 19 | F30: =E30/E$10 -> 1 | G30: =COUNTIFS(Raw!$C:$C,Summary!G$9,Raw!$Y:$Y,"Pass") -> 2 | H30: =G30/G$10 -> 0.095238095 | I30: =COUNTIFS(Raw!$C:$C,Summary!I$9,Raw!$Y:$Y,"Pass") -> 0 | J30: =I30/I$10 -> 0 | K30: =COUNTIFS(Raw!$C:$C,Summary!K$9,Raw!$Y:$Y,"Pass") -> 0 | L30: =K30/K$10 -> 0
B31: has issues (duplicate, need check) | C31: =SUM(E31+G31+I31+K31) -> 41 | D31: =C31/C$10 -> 0.66129032 | E31: =COUNTIFS(Raw!$C:$C,Summary!E$9,Raw!$Y:$Y,"<>Pass") -> 0 | F31: =E31/E$10 -> 0 | G31: =COUNTIFS(Raw!$C:$C,Summary!G$9,Raw!$Y:$Y,"<>Pass") -> 19 | H31: =G31/G$10 -> 0.9047619 | I31: =COUNTIFS(Raw!$C:$C,Summary!I$9,Raw!$Y:$Y,"<>Pass") -> 7 | J31: =I31/I$10 -> 1 | K31: =COUNTIFS(Raw!$C:$C,Summary!K$9,Raw!$Y:$Y,"<>Pass") -> 15 | L31: =K31/K$10 -> 1
B32: Schema
B33: Pass | C33: =SUM(E33+G33+I33+K33) -> 0 | D33: =C33/C$10 -> 0 | E33: =COUNTIFS(Raw!$C:$C,Summary!E$9,Raw!$AK:$AK,"Pass") -> 0 | F33: =E33/E$10 -> 0 | G33: =COUNTIFS(Raw!$C:$C,Summary!G$9,Raw!$AK:$AK,"Pass") -> 0 | H33: =G33/G$10 -> 0 | I33: =COUNTIFS(Raw!$C:$C,Summary!I$9,Raw!$AK:$AK,"Pass") -> 0 | J33: =I33/I$10 -> 0 | K33: =COUNTIFS(Raw!$C:$C,Summary!K$9,Raw!$AK:$AK,"Pass") -> 0 | L33: =K33/K$10 -> 0
B34: has issues (missing) | C34: =SUM(E34+G34+I34+K34) -> 62 | D34: =C34/C$10 -> 1 | E34: =COUNTIFS(Raw!$C:$C,Summary!E$9,Raw!$AK:$AK,"<>Pass") -> 19 | F34: =E34/E$10 -> 1 | G34: =COUNTIFS(Raw!$C:$C,Summary!G$9,Raw!$AK:$AK,"<>Pass") -> 21 | H34: =G34/G$10 -> 1 | I34: =COUNTIFS(Raw!$C:$C,Summary!I$9,Raw!$AK:$AK,"<>Pass") -> 7 | J34: =I34/I$10 -> 1 | K34: =COUNTIFS(Raw!$C:$C,Summary!K$9,Raw!$AK:$AK,"<>Pass") -> 15 | L34: =K34/K$10 -> 1

Sheet Raw
A1: Address | B1: Address QA | C1: Segments | D1: Status Code | E1: Status Code QA | F1: Title 1 | G1: Title QA | H1: Meta Description 1 | I1: Meta Description QA | J1: H1-1 | K1: H1 Count 1 | L1: H1 QA | M1: Canonical Link Element 1 | N1: Canonical QA | O1: og title 1 | P1: og description 1 | Q1: og type 1 | R1: og sitename 1 | S1: og image 1 | T1: og image 2 | U1: og url 1 | V1: twitter title 1 | W1: twitter description 1 | X1: twitter card 1 | Y1: Social Tag QA | Z1: Type-1 | AA1: Type-2 | AB1: Type-3 | AC1: Type-4 | AD1: Type-5 | AE1: Type-6 | AF1: Type-7 | AG1: Schema QA
A2: https://ryo-hk.myshopify.com/ | B2: Pass | C2: Page (No PLP / PDP) | D2: 200 | E2: Pass | F2: 呂 RYO 官方網站 | RYO Hong Kong | G2: Pass | H2: 呂Ryo以獨有的「頭皮科學」研究經驗融合韓方成分進行產品研發，解決顧客的頭皮困擾、實現頭皮的最佳均衡狀態。 | I2: Pass | L2: missing | M2: https://ryo-hk.myshopify.com/ | N2: Pass | O2: 呂 RYO 官方網站 | RYO Hong Kong | P2: 呂Ryo以獨有的「頭皮科學」研究經驗融合韓方成分進行產品研發，解決顧客的頭皮困擾、實現頭皮的最佳均衡狀態。 | Q2: website | R2: RYO HK | S2: http://ryo-hk.myshopify.com/cdn/shop/files/ryo_og_image.jpg?v=1749606307 | T2: https://ryo-hk.myshopify.com/cdn/shop/files/ryo_og_image.jpg?v=1749606307 | U2: https://ryo-hk.myshopify.com/ | V2: 呂 RYO 官方網站 | RYO Hong Kong | W2: 呂Ryo以獨有的「頭皮科學」研究經驗融合韓方成分進行產品研發，解決顧客的頭皮困擾、實現頭皮的最佳均衡狀態。 | X2: summary_large_image | Y2: duplicate (check red marked cells) | Z2: BreadcrumbList | AA2: ListItem | AB2: Organization | AC2: SearchAction | AD2: WebSite | AG2: Pass
A3: https://ryo-hk.myshopify.com/blogs/brand-video/1325601_24084 | B3: hyphen recommended instead of underbar | C3: Blog Page | D3: 200 | E3: Pass | F3: 呂RYO 全新升級｜領先科研防脫之旅 | G3: missing " | {brand}{country}" | I3: missing | L3: missing | M3: https://ryo-hk.myshopify.com/blogs/brand-video/1325601_24084 | N3: Pass | O3: 呂RYO 全新升級｜領先科研防脫之旅 | P3: 呂Ryo以獨有的「頭皮科學」研究經驗融合韓方成分進行產品研發，解決顧客的頭皮困擾、實現頭皮的最佳均衡狀態。 | Q3: article | R3: RYO HK | S3: http://ryo-hk.myshopify.com/cdn/shop/files/ryo_og_image.jpg?v=1749606307 | T3: https://ryo-hk.myshopify.com/cdn/shop/files/ryo_og_image.jpg?v=1749606307 | U3: https://ryo-hk.myshopify.com/blogs/brand-video/1325601_24084 | V3: 呂RYO 全新升級｜領先科研防脫之旅 | W3: 呂Ryo以獨有的「頭皮科學」研究經驗融合韓方成分進行產品研發，解決顧客的頭皮困擾、實現頭皮的最佳均衡狀態。 | X3: summary_large_image | Y3: duplicate (check red marked cells) | AG3: Pass
A4: https://ryo-hk.myshopify.com/blogs/news | B4: Pass | C4: Blog Page | D4: 200 | E4: Pass | F4: News | G4: missing " | {brand}{country}" | I4: missing | J4: ASK AESTURA | K4: 1 | L4: check brand name | M4: https://ryo-hk.myshopify.com/blogs/news | N4: Pass | O4: News | P4: 呂Ryo以獨有的「頭皮科學」研究經驗融合韓方成分進行產品研發，解決顧客的頭皮困擾、實現頭皮的最佳均衡狀態。 | Q4: website | R4: RYO HK | S4: http://ryo-hk.myshopify.com/cdn/shop/files/ryo_og_image.jpg?v=1749606307 | T4: https://ryo-hk.myshopify.com/cdn/shop/files/ryo_og_image.jpg?v=1749606307 | U4: https://ryo-hk.myshopify.com/blogs/news | V4: News | W4: 呂Ryo以獨有的「頭皮科學」研究經驗融合韓方成分進行產品研發，解決顧客的頭皮困擾、實現頭皮的最佳均衡狀態。 | X4: summary_large_image | Y4: duplicate (check red marked cells) | Z4: BreadcrumbList | AA4: ListItem | AB4: Organization | AG4: Pass
A5: https://ryo-hk.myshopify.com/collections/beautiful-aging-care | B5: Pass | C5: Product List | D5: 200 | E5: Pass | F5: 修復明顯脫髮 | G5: missing " | {brand}{country}" | I5: missing | K5: 5 | L5: multiple | M5: https://ryo-hk.myshopify.com/collections/beautiful-aging-care | N5: Pass | O5: 修復明顯脫髮 | P5: 呂Ryo以獨有的「頭皮科學」研究經驗融合韓方成分進行產品研發，解決顧客的頭皮困擾、實現頭皮的最佳均衡狀態。 | Q5: website | R5: RYO HK | S5: http://ryo-hk.myshopify.com/cdn/shop/files/ryo_og_image.jpg?v=1749606307 | T5: https://ryo-hk.myshopify.com/cdn/shop/files/ryo_og_image.jpg?v=1749606307 | U5: https://ryo-hk.myshopify.com/collections/beautiful-aging-care | V5: 修復明顯脫髮 | W5: 呂Ryo以獨有的「頭皮科學」研究經驗融合韓方成分進行產品研發，解決顧客的頭皮困擾、實現頭皮的最佳均衡狀態。 | X5: summary_large_image | Y5: duplicate (check red marked cells) | Z5: BreadcrumbList | AA5: ListItem | AB5: Organization | AG5: Pass
A6: https://ryo-hk.myshopify.com/collections/bestseller-item | B6: Pass | C6: Product List | D6: 200 | E6: Pass | F6: BEST SELLER ITEM l RYO HK | G6: missing " | {brand}{country}" | H6: 给大家介绍一下厉的畅销单品 | I6: Pass | K6: 5 | L6: multiple | M6: https://ryo-hk.myshopify.com/collections/bestseller-item | N6: Pass | O6: BEST SELLER ITEM l RYO HK | P6: 给大家介绍一下厉的畅销单品 | Q6: website | R6: RYO HK | S6: http://ryo-hk.myshopify.com/cdn/shop/files/ryo_og_image.jpg?v=1749606307 | T6: https://ryo-hk.myshopify.com/cdn/shop/files/ryo_og_image.jpg?v=1749606307 | U6: https://ryo-hk.myshopify.com/collections/bestseller-item | V6: BEST SELLER ITEM l RYO HK | W6: 给大家介绍一下厉的畅销单品 | X6: summary_large_image | Y6: Pass | Z6: BreadcrumbList | AA6: ListItem | AB6: Organization | AG6: Pass
