Workbook

Sheet Summary
B2: 이니스프리 TW QA Result
B4: Expected Launch Date | C4: 2026.02.24
B5: QA Date | C5: 2026.02.12
B6: Pass Rate | C6: =AVERAGE(D12,D15,D18,D21,D24,D27,D30,D33) -> 0.85104423
B9: QA Elements | C9: All Page | E9: Product Detail | G9: Product List | I9: Blog Page | K9: Page (No PLP / PDP)
B10: Total | C10: =SUM(E10:L10) -> 407 | E10: =COUNTIF('QA 결과'!$D:$D,Summary!E9) -> 181 | G10: =COUNTIF('QA 결과'!$D:$D,Summary!G9) -> 125 | I10: =COUNTIF('QA 결과'!$D:$D,Summary!I9) -> 59 | K10: =COUNTIF('QA 결과'!$D:$D,Summary!K9) -> 42
B11: Address
B12: Pass | C12: =SUM(E12+G12+I12+K12) -> 390 | D12: =C12/C$10 -> 0.95823096 | E12: =COUNTIFS('QA 결과'!$D:$D,Summary!E$9,'QA 결과'!$C:$C,"Pass") -> 166 | F12: =E12/E$10 -> 0.91712707 | G12: =COUNTIFS('QA 결과'!$D:$D,Summary!G$9,'QA 결과'!$C:$C,"Pass") -> 124 | H12: =G12/G$10 -> 0.992 | I12: =COUNTIFS('QA 결과'!$D:$D,Summary!I$9,'QA 결과'!$C:$C,"Pass") -> 58 | J12: =I12/I$10 -> 0.98305085 | K12: =COUNTIFS('QA 결과'!$D:$D,Summary!K$9,'QA 결과'!$C:$C,"Pass") -> 42 | L12: =K12/K10 -> 1
B13: has issues (not english) | C13: =SUM(E13+G13+I13+K13) -> 17 | D13: =C13/C$10 -> 0.041769042 | E13: =COUNTIFS('QA 결과'!$D:$D,Summary!E$9,'QA 결과'!$C:$C,"<>Pass") -> 15 | F13: =E13/E$10 -> 0.082872928 | G13: =COUNTIFS('QA 결과'!$D:$D,Summary!G$9,'QA 결과'!$C:$C,"<>Pass") -> 1 | H13: =G13/G$10 -> 0.008 | I13: =COUNTIFS('QA 결과'!$D:$D,Summary!I$9,'QA 결과'!$C:$C,"<>Pass") -> 1 | J13: =I13/I$10 -> 0.016949153 | K13: =COUNTIFS('QA 결과'!$D:$D,Summary!K$9,'QA 결과'!$C:$C,"<>Pass") -> 0 | L13: =K13/K10 -> 0
B14: Status Code
B15: Pass | C15: =SUM(E15+G15+I15+K15) -> 407 | D15: =C15/C$10 -> 1 | E15: =COUNTIFS('QA 결과'!$D:$D,Summary!E$9,'QA 결과'!$F:$F,"Pass") -> 181 | F15: =E15/E$10 -> 1 | G15: =COUNTIFS('QA 결과'!$D:$D,Summary!G$9,'QA 결과'!$F:$F,"Pass") -> 125 | H15: =G15/G$10 -> 1 | I15: =COUNTIFS('QA 결과'!$D:$D,Summary!I$9,'QA 결과'!$F:$F,"Pass") -> 59 | J15: =I15/I$10 -> 1 | K15: =COUNTIFS('QA 결과'!$D:$D,Summary!K$9,'QA 결과'!$F:$F,"Pass") -> 42 | L15: =K15/K10 -> 1
B16: has issues (301, 302, 404) | C16: =SUM(E16+G16+I16+K16) -> 0 | D16: =C16/C$10 -> 0 | E16: =COUNTIFS('QA 결과'!$D:$D,Summary!E$9,'QA 결과'!$F:$F,"<>Pass") -> 0 | F16: =E16/E$10 -> 0 | G16: =COUNTIFS('QA 결과'!$D:$D,Summary!G$9,'QA 결과'!$F:$F,"<>Pass") -> 0 | H16: =G16/G$10 -> 0 | I16: =COUNTIFS('QA 결과'!$D:$D,Summary!I$9,'QA 결과'!$F:$F,"<>Pass") -> 0 | J16: =I16/I$10 -> 0 | K16: =COUNTIFS('QA 결과'!$D:$D,Summary!K$9,'QA 결과'!$F:$F,"<>Pass") -> 0 | L16: =K16/K10 -> 0
B17: Title
B18: Pass | C18: =SUM(E18+G18+I18+K18) -> 399 | D18: =C18/C$10 -> 0.98034398 | E18: =COUNTIFS('QA 결과'!$D:$D,Summary!E$9,'QA 결과'!$H:$H,"Pass") -> 178 | F18: =E18/E$10 -> 0.98342541 | G18: =COUNTIFS('QA 결과'!$D:$D,Summary!G$9,'QA 결과'!$H:$H,"Pass") -> 125 | H18: =G18/G$10 -> 1 | I18: =COUNTIFS('QA 결과'!$D:$D,Summary!I$9,'QA 결과'!$H:$H,"Pass") -> 59 | J18: =I18/I$10 -> 1 | K18: =COUNTIFS('QA 결과'!$D:$D,Summary!K$9,'QA 결과'!$H:$H,"Pass") -> 37 | L18: =K18/K$10 -> 0.88095238
B19: has issues (separator, typo, space) | C19: =SUM(E19+G19+I19+K19) -> 8 | D19: =C19/C$10 -> 0.01965602 | E19: =COUNTIFS('QA 결과'!$D:$D,Summary!E$9,'QA 결과'!$H:$H,"<>Pass") -> 3 | F19: =E19/E$10 -> 0.016574586 | G19: =COUNTIFS('QA 결과'!$D:$D,Summary!G$9,'QA 결과'!$H:$H,"<>Pass") -> 0 | H19: =G19/G$10 -> 0 | I19: =COUNTIFS('QA 결과'!$D:$D,Summary!I$9,'QA 결과'!$H:$H,"<>Pass") -> 0 | J19: =I19/I$10 -> 0 | K19: =COUNTIFS('QA 결과'!$D:$D,Summary!K$9,'QA 결과'!$H:$H,"<>Pass") -> 5 | L19: =K19/K$10 -> 0.11904762
B20: Meta Description
B21: Pass | C21: =SUM(E21+G21+I21+K21) -> 277 | D21: =C21/C$10 -> 0.68058968 | E21: =COUNTIFS('QA 결과'!$D:$D,Summary!E$9,'QA 결과'!$J:$J,"Pass") -> 146 | F21: =E21/E$10 -> 0.80662983 | G21: =COUNTIFS('QA 결과'!$D:$D,Summary!G$9,'QA 결과'!$J:$J,"Pass") -> 76 | H21: =G21/G$10 -> 0.608 | I21: =COUNTIFS('QA 결과'!$D:$D,Summary!I$9,'QA 결과'!$J:$J,"Pass") -> 34 | J21: =I21/I$10 -> 0.57627119 | K21: =COUNTIFS('QA 결과'!$D:$D,Summary!K$9,'QA 결과'!$J:$J,"Pass") -> 21 | L21: =K21/K$10 -> 0.5
B22: has issues (missing, duplicate) | C22: =SUM(E22+G22+I22+K22) -> 130 | D22: =C22/C$10 -> 0.31941032 | E22: =COUNTIFS('QA 결과'!$D:$D,Summary!E$9,'QA 결과'!$J:$J,"<>Pass") -> 35 | F22: =E22/E$10 -> 0.19337017 | G22: =COUNTIFS('QA 결과'!$D:$D,Summary!G$9,'QA 결과'!$J:$J,"<>Pass") -> 49 | H22: =G22/G$10 -> 0.392 | I22: =COUNTIFS('QA 결과'!$D:$D,Summary!I$9,'QA 결과'!$J:$J,"<>Pass") -> 25 | J22: =I22/I$10 -> 0.42372881 | K22: =COUNTIFS('QA 결과'!$D:$D,Summary!K$9,'QA 결과'!$J:$J,"<>Pass") -> 21 | L22: =K22/K$10 -> 0.5
B23: H1
B24: Pass | C24: =SUM(E24+G24+I24+K24) -> 382 | D24: =C24/C$10 -> 0.93857494 | E24: =COUNTIFS('QA 결과'!$D:$D,Summary!E$9,'QA 결과'!$M:$M,"Pass") -> 178 | F24: =E24/E$10 -> 0.98342541 | G24: =COUNTIFS('QA 결과'!$D:$D,Summary!G$9,'QA 결과'!$M:$M,"Pass") -> 125 | H24: =G24/G$10 -> 1 | I24: =COUNTIFS('QA 결과'!$D:$D,Summary!I$9,'QA 결과'!$M:$M,"Pass") -> 52 | J24: =I24/I$10 -> 0.88135593 | K24: =COUNTIFS('QA 결과'!$D:$D,Summary!K$9,'QA 결과'!$M:$M,"Pass") -> 27 | L24: =K24/K$10 -> 0.64285714
B25: has issues (missing) | C25: =SUM(E25+G25+I25+K25) -> 25 | D25: =C25/C$10 -> 0.061425061 | E25: =COUNTIFS('QA 결과'!$D:$D,Summary!E$9,'QA 결과'!$M:$M,"<>Pass") -> 3 | F25: =E25/E$10 -> 0.016574586 | G25: =COUNTIFS('QA 결과'!$D:$D,Summary!G$9,'QA 결과'!$M:$M,"<>Pass") -> 0 | H25: =G25/G$10 -> 0 | I25: =COUNTIFS('QA 결과'!$D:$D,Summary!I$9,'QA 결과'!$M:$M,"<>Pass") -> 7 | J25: =I25/I$10 -> 0.11864407 | K25: =COUNTIFS('QA 결과'!$D:$D,Summary!K$9,'QA 결과'!$M:$M,"<>Pass") -> 15 | L25: =K25/K$10 -> 0.35714286
B26: Canonical
B27: Pass | C27: =SUM(E27+G27+I27+K27) -> 386 | D27: =C27/C$10 -> 0.94840295 | E27: =COUNTIFS('QA 결과'!$D:$D,Summary!E$9,'QA 결과'!$O:$O,"Pass") -> 176 | F27: =E27/E$10 -> 0.97237569 | G27: =COUNTIFS('QA 결과'!$D:$D,Summary!G$9,'QA 결과'!$O:$O,"Pass") -> 123 | H27: =G27/G$10 -> 0.984 | I27: =COUNTIFS('QA 결과'!$D:$D,Summary!I$9,'QA 결과'!$O:$O,"Pass") -> 48 | J27: =I27/I$10 -> 0.81355932 | K27: =COUNTIFS('QA 결과'!$D:$D,Summary!K$9,'QA 결과'!$O:$O,"Pass") -> 39 | L27: =K27/K$10 -> 0.92857143
B28: has issues | C28: =SUM(E28+G28+I28+K28) -> 21 | D28: =C28/C$10 -> 0.051597052 | E28: =COUNTIFS('QA 결과'!$D:$D,Summary!E$9,'QA 결과'!$O:$O,"<>Pass") -> 5 | F28: =E28/E$10 -> 0.027624309 | G28: =COUNTIFS('QA 결과'!$D:$D,Summary!G$9,'QA 결과'!$O:$O,"<>Pass") -> 2 | H28: =G28/G$10 -> 0.016 | I28: =COUNTIFS('QA 결과'!$D:$D,Summary!I$9,'QA 결과'!$O:$O,"<>Pass") -> 11 | J28: =I28/I$10 -> 0.18644068 | K28: =COUNTIFS('QA 결과'!$D:$D,Summary!K$9,'QA 결과'!$O:$O,"<>Pass") -> 3 | L28: =K28/K$10 -> 0.071428571
B29: Social Tag
B30: Pass | C30: =SUM(E30+G30+I30+K30) -> 364 | D30: =C30/C$10 -> 0.89434889 | E30: =COUNTIFS('QA 결과'!$D:$D,Summary!E$9,'QA 결과'!$Z:$Z,"Pass") -> 148 | F30: =E30/E$10 -> 0.81767956 | G30: =COUNTIFS('QA 결과'!$D:$D,Summary!G$9,'QA 결과'!$Z:$Z,"Pass") -> 118 | H30: =G30/G$10 -> 0.944 | I30: =COUNTIFS('QA 결과'!$D:$D,Summary!I$9,'QA 결과'!$Z:$Z,"Pass") -> 57 | J30: =I30/I$10 -> 0.96610169 | K30: =COUNTIFS('QA 결과'!$D:$D,Summary!K$9,'QA 결과'!$Z:$Z,"Pass") -> 41 | L30: =K30/K$10 -> 0.97619048
B31: has issues (duplicate, need check) | C31: =SUM(E31+G31+I31+K31) -> 43 | D31: =C31/C$10 -> 0.10565111 | E31: =COUNTIFS('QA 결과'!$D:$D,Summary!E$9,'QA 결과'!$Z:$Z,"<>Pass") -> 33 | F31: =E31/E$10 -> 0.18232044 | G31: =COUNTIFS('QA 결과'!$D:$D,Summary!G$9,'QA 결과'!$Z:$Z,"<>Pass") -> 7 | H31: =G31/G$10 -> 0.056 | I31: =COUNTIFS('QA 결과'!$D:$D,Summary!I$9,'QA 결과'!$Z:$Z,"<>Pass") -> 2 | J31: =I31/I$10 -> 0.033898305 | K31: =COUNTIFS('QA 결과'!$D:$D,Summary!K$9,'QA 결과'!$Z:$Z,"<>Pass") -> 1 | L31: =K31/K$10 -> 0.023809524
B32: Schema
B33: Pass | C33: =SUM(E33+G33+I33+K33) -> 166 | D33: =C33/C$10 -> 0.40786241 | E33: =COUNTIFS('QA 결과'!$D:$D,Summary!E$9,'QA 결과'!$AF:$AF,"Pass") -> 0 | F33: =E33/E$10 -> 0 | G33: =COUNTIFS('QA 결과'!$D:$D,Summary!G$9,'QA 결과'!$AF:$AF,"Pass") -> 120 | H33: =G33/G$10 -> 0.96 | I33: =COUNTIFS('QA 결과'!$D:$D,Summary!I$9,'QA 결과'!$AF:$AF,"Pass") -> 34 | J33: =I33/I$10 -> 0.57627119 | K33: =COUNTIFS('QA 결과'!$D:$D,Summary!K$9,'QA 결과'!$AF:$AF,"Pass") -> 12 | L33: =K33/K$10 -> 0.28571429
B34: has issues (missing) | C34: =SUM(E34+G34+I34+K34) -> 241 | D34: =C34/C$10 -> 0.59213759 | E34: =COUNTIFS('QA 결과'!$D:$D,Summary!E$9,'QA 결과'!$AF:$AF,"<>Pass") -> 181 | F34: =E34/E$10 -> 1 | G34: =COUNTIFS('QA 결과'!$D:$D,Summary!G$9,'QA 결과'!$AF:$AF,"<>Pass") -> 5 | H34: =G34/G$10 -> 0.04 | I34: =COUNTIFS('QA 결과'!$D:$D,Summary!I$9,'QA 결과'!$AF:$AF,"<>Pass") -> 25 | J34: =I34/I$10 -> 0.42372881 | K34: =COUNTIFS('QA 결과'!$D:$D,Summary!K$9,'QA 결과'!$AF:$AF,"<>Pass") -> 30 | L34: =K34/K$10 -> 0.71428571

Sheet Raw (QA 완료)
A1: Address | B1: Address QA | C1: Segments | D1: Status Code | E1: Status Code QA | F1: Title 1 | G1: Title QA | H1: Meta Description 1 | I1: Meta Description QA | J1: H1-1 | K1: H1 Count 1 | L1: H1 QA | M1: Canonical Link Element 1 | N1: Canonical QA | O1: og title 1 | P1: og description 1 | Q1: og type 1 | R1: og sitename 1 | S1: og image 1 | T1: og image 2 | U1: og url 1 | V1: twitter title 1 | W1: twitter description 1 | X1: twitter card 1 | Y1: Social Tag QA | Z1: Type-1 | AA1: Type-2 | AB1: Type-3 | AC1: Type-4 | AD1: Type-5 | AE1: Schema QA | AF1: Overall Comment
A2: {=INDEX('raw-sheet'!$A$2:$ZZ$1000, ROW(A1), MATCH(A$1, 'raw-sheet'!$A$1:$ZZ$1, 0))} -> https://innisfree-taiwan.myshopify.com/ | B2: Pass | C2: {=INDEX('raw-sheet'!$A$2:$ZZ$1000, ROW(C1), MATCH(C$1, 'raw-sheet'!$A$1:$ZZ$1, 0))} -> Page (No PLP / PDP) | D2: {=INDEX('raw-sheet'!$A$2:$ZZ$1000, ROW(D1), MATCH(D$1, 'raw-sheet'!$A$1:$ZZ$1, 0))} -> 200 | E2: =IF(D2=200,"Pass","Not") -> Pass | F2: {=INDEX('raw-sheet'!$A$2:$ZZ$1000, ROW(F1), MATCH(F$1, 'raw-sheet'!$A$1:$ZZ$1, 0))} -> innisfree 台灣官方網站 & 線上購物 官網下單滿千免運_x000D_ | INNISFREE Taiwan | G2: Pass | H2: {=INDEX('raw-sheet'!$A$2:$ZZ$1000, ROW(H1), MATCH(H$1, 'raw-sheet'!$A$1:$ZZ$1, 0))} -> innisfree 來自韓國濟州島的No.1自然主義美妝保養品牌，不僅將濟州島清新潔淨的空氣、溫暖和煦的陽光、純淨天然的水源、肥沃健康的土壤、自然純粹的植物養分注入保養品，更為消費者打造健康與美麗。| innisfree Taiwan | I2: Pass | J2: {=INDEX('raw-sheet'!$A$2:$ZZ$1000, ROW(J1), MATCH(J$1, 'raw-sheet'!$A$1:$ZZ$1, 0))} -> INNISFREE Taiwan | K2: {=INDEX('raw-sheet'!$A$2:$ZZ$1000, ROW(K1), MATCH(K$1, 'raw-sheet'!$A$1:$ZZ$1, 0))} -> 1 | L2: Pass | M2: {=INDEX('raw-sheet'!$A$2:$ZZ$1000, ROW(M1), MATCH(M$1, 'raw-sheet'!$A$1:$ZZ$1, 0))} -> https://innisfree-taiwan.myshopify.com/ | N2: =IF(A2=M2,"Pass","Not") -> Pass | O2: {=INDEX('raw-sheet'!$A$2:$ZZ$1000, ROW(O1), MATCH(O$1, 'raw-sheet'!$A$1:$ZZ$1, 0))} -> innisfree 台灣官方網站 & 線上購物 官網下單滿千免運 | INNISFREE Taiwan | P2: {=INDEX('raw-sheet'!$A$2:$ZZ$1000, ROW(P1), MATCH(P$1, 'raw-sheet'!$A$1:$ZZ$1, 0))} -> innisfree 來自韓國濟州島的No.1自然主義美妝保養品牌，不僅將濟州島清新潔淨的空氣、溫暖和煦的陽光、純淨天然的水源、肥沃健康的土壤、自然純粹的植物養分注入保養品，更為消費者打造健康與美麗。| innisfree Taiwan | Q2: {=INDEX('raw-sheet'!$A$2:$ZZ$1000, ROW(Q1), MATCH(Q$1, 'raw-sheet'!$A$1:$ZZ$1, 0))} -> website | R2: {=INDEX('raw-sheet'!$A$2:$ZZ$1000, ROW(R1), MATCH(R$1, 'raw-sheet'!$A$1:$ZZ$1, 0))} -> INNISFREE Taiwan | S2: {=INDEX('raw-sheet'!$A$2:$ZZ$1000, ROW(S1), MATCH(S$1, 'raw-sheet'!$A$1:$ZZ$1, 0))} -> http://innisfree-taiwan.myshopify.com/cdn/shop/files/logo.png?v=1767594135 | T2: {=INDEX('raw-sheet'!$A$2:$ZZ$1000, ROW(T1), MATCH(T$1, 'raw-sheet'!$A$1:$ZZ$1, 0))} -> https://innisfree-taiwan.myshopify.com/cdn/shop/files/logo.png?v=1767594135 | U2: {=INDEX('raw-sheet'!$A$2:$ZZ$1000, ROW(U1), MATCH(U$1, 'raw-sheet'!$A$1:$ZZ$1, 0))} -> https://innisfree-taiwan.myshopify.com/ | V2: {=INDEX('raw-sheet'!$A$2:$ZZ$1000, ROW(V1), MATCH(V$1, 'raw-sheet'!$A$1:$ZZ$1, 0))} -> innisfree 台灣官方網站 & 線上購物 官網下單滿千免運 | INNISFREE Taiwan | ... X2: {=INDEX('raw-sheet'!$A$2:$ZZ$1000, ROW(X1), MATCH(X$1, 'raw-sheet'!$A$1:$ZZ$1, 0))} -> summary_large_image | Y2: duplicate desc. | Z2: =VLOOKUP($A2,'raw-schema'!$A:$R,14,0) -> Organization | AA2: =VLOOKUP($A2,'raw-schema'!$A:$R,15,0) -> SearchAction | AB2: =VLOOKUP($A2,'raw-schema'!$A:$R,16,0) -> WebSite | AC2: =VLOOKUP($A2,'raw-schema'!$A:$R,17,0) -> 0 | AD2: =VLOOKUP($A2,'raw-schema'!$A:$R,18,0) -> 0 | AE2: Schema 보강 필요 (Page)
A3: {=INDEX('raw-sheet'!$A$2:$ZZ$1000, ROW(A2), MATCH(A$1, 'raw-sheet'!$A$1:$ZZ$1, 0))} -> https://innisfree-taiwan.myshopify.com/a/service | C3: {=INDEX('raw-sheet'!$A$2:$ZZ$1000, ROW(C2), MATCH(C$1, 'raw-sheet'!$A$1:$ZZ$1, 0))} -> 0 | D3: {=INDEX('raw-sheet'!$A$2:$ZZ$1000, ROW(D2), MATCH(D$1, 'raw-sheet'!$A$1:$ZZ$1, 0))} -> 404 | E3: =IF(D3=200,"Pass","Not") -> Not | F3: {=INDEX('raw-sheet'!$A$2:$ZZ$1000, ROW(F2), MATCH(F$1, 'raw-sheet'!$A$1:$ZZ$1, 0))} -> 0 | H3: {=INDEX('raw-sheet'!$A$2:$ZZ$1000, ROW(H2), MATCH(H$1, 'raw-sheet'!$A$1:$ZZ$1, 0))} -> 0 | J3: {=INDEX('raw-sheet'!$A$2:$ZZ$1000, ROW(J2), MATCH(J$1, 'raw-sheet'!$A$1:$ZZ$1, 0))} -> 0 | K3: {=INDEX('raw-sheet'!$A$2:$ZZ$1000, ROW(K2), MATCH(K$1, 'raw-sheet'!$A$1:$ZZ$1, 0))} -> 0 | M3: {=INDEX('raw-sheet'!$A$2:$ZZ$1000, ROW(M2), MATCH(M$1, 'raw-sheet'!$A$1:$ZZ$1, 0))} -> 0 | N3: =IF(A3=M3,"Pass","Not") -> Not | O3: {=INDEX('raw-sheet'!$A$2:$ZZ$1000, ROW(O2), MATCH(O$1, 'raw-sheet'!$A$1:$ZZ$1, 0))} -> 0 | P3: {=INDEX('raw-sheet'!$A$2:$ZZ$1000, ROW(P2), MATCH(P$1, 'raw-sheet'!$A$1:$ZZ$1, 0))} -> 0 | Q3: {=INDEX('raw-sheet'!$A$2:$ZZ$1000, ROW(Q2), MATCH(Q$1, 'raw-sheet'!$A$1:$ZZ$1, 0))} -> 0 | R3: {=INDEX('raw-sheet'!$A$2:$ZZ$1000, ROW(R2), MATCH(R$1, 'raw-sheet'!$A$1:$ZZ$1, 0))} -> 0 | S3: {=INDEX('raw-sheet'!$A$2:$ZZ$1000, ROW(S2), MATCH(S$1, 'raw-sheet'!$A$1:$ZZ$1, 0))} -> 0 | T3: {=INDEX('raw-sheet'!$A$2:$ZZ$1000, ROW(T2), MATCH(T$1, 'raw-sheet'!$A$1:$ZZ$1, 0))} -> 0 | U3: {=INDEX('raw-sheet'!$A$2:$ZZ$1000, ROW(U2), MATCH(U$1, 'raw-sheet'!$A$1:$ZZ$1, 0))} -> 0 | V3: {=INDEX('raw-sheet'!$A$2:$ZZ$1000, ROW(V2), MATCH(V$1, 'raw-sheet'!$A$1:$ZZ$1, 0))} -> 0 | ... X3: {=INDEX('raw-sheet'!$A$2:$ZZ$1000, ROW(X2), MATCH(X$1, 'raw-sheet'!$A$1:$ZZ$1, 0))} -> 0 | Z3: =VLOOKUP($A3,'raw-schema'!$A:$R,14,0) -> #N/A | AA3: =VLOOKUP($A3,'raw-schema'!$A:$R,15,0) -> #N/A | AB3: =VLOOKUP($A3,'raw-schema'!$A:$R,16,0) -> #N/A | AC3: =VLOOKUP($A3,'raw-schema'!$A:$R,17,0) -> #N/A | AD3: =VLOOKUP($A3,'raw-schema'!$A:$R,18,0) -> #N/A | AF3: 404 링크 (404 Inlinks 시트 참조)
A4: {=INDEX('raw-sheet'!$A$2:$ZZ$1000, ROW(A3), MATCH(A$1, 'raw-sheet'!$A$1:$ZZ$1, 0))} -> https://innisfree-taiwan.myshopify.com/account | C4: {=INDEX('raw-sheet'!$A$2:$ZZ$1000, ROW(C3), MATCH(C$1, 'raw-sheet'!$A$1:$ZZ$1, 0))} -> 0 | D4: {=INDEX('raw-sheet'!$A$2:$ZZ$1000, ROW(D3), MATCH(D$1, 'raw-sheet'!$A$1:$ZZ$1, 0))} -> 302 | E4: =IF(D4=200,"Pass","Not") -> Not | F4: {=INDEX('raw-sheet'!$A$2:$ZZ$1000, ROW(F3), MATCH(F$1, 'raw-sheet'!$A$1:$ZZ$1, 0))} -> 0 | H4: {=INDEX('raw-sheet'!$A$2:$ZZ$1000, ROW(H3), MATCH(H$1, 'raw-sheet'!$A$1:$ZZ$1, 0))} -> 0 | J4: {=INDEX('raw-sheet'!$A$2:$ZZ$1000, ROW(J3), MATCH(J$1, 'raw-sheet'!$A$1:$ZZ$1, 0))} -> 0 | K4: {=INDEX('raw-sheet'!$A$2:$ZZ$1000, ROW(K3), MATCH(K$1, 'raw-sheet'!$A$1:$ZZ$1, 0))} -> 0 | M4: {=INDEX('raw-sheet'!$A$2:$ZZ$1000, ROW(M3), MATCH(M$1, 'raw-sheet'!$A$1:$ZZ$1, 0))} -> 0 | N4: =IF(A4=M4,"Pass","Not") -> Not | O4: {=INDEX('raw-sheet'!$A$2:$ZZ$1000, ROW(O3), MATCH(O$1, 'raw-sheet'!$A$1:$ZZ$1, 0))} -> 0 | P4: {=INDEX('raw-sheet'!$A$2:$ZZ$1000, ROW(P3), MATCH(P$1, 'raw-sheet'!$A$1:$ZZ$1, 0))} -> 0 | Q4: {=INDEX('raw-sheet'!$A$2:$ZZ$1000, ROW(Q3), MATCH(Q$1, 'raw-sheet'!$A$1:$ZZ$1, 0))} -> 0 | R4: {=INDEX('raw-sheet'!$A$2:$ZZ$1000, ROW(R3), MATCH(R$1, 'raw-sheet'!$A$1:$ZZ$1, 0))} -> 0 | S4: {=INDEX('raw-sheet'!$A$2:$ZZ$1000, ROW(S3), MATCH(S$1, 'raw-sheet'!$A$1:$ZZ$1, 0))} -> 0 | T4: {=INDEX('raw-sheet'!$A$2:$ZZ$1000, ROW(T3), MATCH(T$1, 'raw-sheet'!$A$1:$ZZ$1, 0))} -> 0 | U4: {=INDEX('raw-sheet'!$A$2:$ZZ$1000, ROW(U3), MATCH(U$1, 'raw-sheet'!$A$1:$ZZ$1, 0))} -> 0 | V4: {=INDEX('raw-sheet'!$A$2:$ZZ$1000, ROW(V3), MATCH(V$1, 'raw-sheet'!$A$1:$ZZ$1, 0))} -> 0 | ... X4: {=INDEX('raw-sheet'!$A$2:$ZZ$1000, ROW(X3), MATCH(X$1, 'raw-sheet'!$A$1:$ZZ$1, 0))} -> 0 | Z4: =VLOOKUP($A4,'raw-schema'!$A:$R,14,0) -> #N/A | AA4: =VLOOKUP($A4,'raw-schema'!$A:$R,15,0) -> #N/A | AB4: =VLOOKUP($A4,'raw-schema'!$A:$R,16,0) -> #N/A | AC4: =VLOOKUP($A4,'raw-schema'!$A:$R,17,0) -> #N/A | AD4: =VLOOKUP($A4,'raw-schema'!$A:$R,18,0) -> #N/A | AF4: 예외 적용 (blocked by robots.txt)
A5: {=INDEX('raw-sheet'!$A$2:$ZZ$1000, ROW(A4), MATCH(A$1, 'raw-sheet'!$A$1:$ZZ$1, 0))} -> https://innisfree-taiwan.myshopify.com/account/addresses | C5: {=INDEX('raw-sheet'!$A$2:$ZZ$1000, ROW(C4), MATCH(C$1, 'raw-sheet'!$A$1:$ZZ$1, 0))} -> 0 | D5: {=INDEX('raw-sheet'!$A$2:$ZZ$1000, ROW(D4), MATCH(D$1, 'raw-sheet'!$A$1:$ZZ$1, 0))} -> 302 | E5: =IF(D5=200,"Pass","Not") -> Not | F5: {=INDEX('raw-sheet'!$A$2:$ZZ$1000, ROW(F4), MATCH(F$1, 'raw-sheet'!$A$1:$ZZ$1, 0))} -> 0 | H5: {=INDEX('raw-sheet'!$A$2:$ZZ$1000, ROW(H4), MATCH(H$1, 'raw-sheet'!$A$1:$ZZ$1, 0))} -> 0 | J5: {=INDEX('raw-sheet'!$A$2:$ZZ$1000, ROW(J4), MATCH(J$1, 'raw-sheet'!$A$1:$ZZ$1, 0))} -> 0 | K5: {=INDEX('raw-sheet'!$A$2:$ZZ$1000, ROW(K4), MATCH(K$1, 'raw-sheet'!$A$1:$ZZ$1, 0))} -> 0 | M5: {=INDEX('raw-sheet'!$A$2:$ZZ$1000, ROW(M4), MATCH(M$1, 'raw-sheet'!$A$1:$ZZ$1, 0))} -> 0 | N5: =IF(A5=M5,"Pass","Not") -> Not | O5: {=INDEX('raw-sheet'!$A$2:$ZZ$1000, ROW(O4), MATCH(O$1, 'raw-sheet'!$A$1:$ZZ$1, 0))} -> 0 | P5: {=INDEX('raw-sheet'!$A$2:$ZZ$1000, ROW(P4), MATCH(P$1, 'raw-sheet'!$A$1:$ZZ$1, 0))} -> 0 | Q5: {=INDEX('raw-sheet'!$A$2:$ZZ$1000, ROW(Q4), MATCH(Q$1, 'raw-sheet'!$A$1:$ZZ$1, 0))} -> 0 | R5: {=INDEX('raw-sheet'!$A$2:$ZZ$1000, ROW(R4), MATCH(R$1, 'raw-sheet'!$A$1:$ZZ$1, 0))} -> 0 | S5: {=INDEX('raw-sheet'!$A$2:$ZZ$1000, ROW(S4), MATCH(S$1, 'raw-sheet'!$A$1:$ZZ$1, 0))} -> 0 | T5: {=INDEX('raw-sheet'!$A$2:$ZZ$1000, ROW(T4), MATCH(T$1, 'raw-sheet'!$A$1:$ZZ$1, 0))} -> 0 | U5: {=INDEX('raw-sheet'!$A$2:$ZZ$1000, ROW(U4), MATCH(U$1, 'raw-sheet'!$A$1:$ZZ$1, 0))} -> 0 | V5: {=INDEX('raw-sheet'!$A$2:$ZZ$1000, ROW(V4), MATCH(V$1, 'raw-sheet'!$A$1:$ZZ$1, 0))} -> 0 | ... X5: {=INDEX('raw-sheet'!$A$2:$ZZ$1000, ROW(X4), MATCH(X$1, 'raw-sheet'!$A$1:$ZZ$1, 0))} -> 0 | Z5: =VLOOKUP($A5,'raw-schema'!$A:$R,14,0) -> #N/A | AA5: =VLOOKUP($A5,'raw-schema'!$A:$R,15,0) -> #N/A | AB5: =VLOOKUP($A5,'raw-schema'!$A:$R,16,0) -> #N/A | AC5: =VLOOKUP($A5,'raw-schema'!$A:$R,17,0) -> #N/A | AD5: =VLOOKUP($A5,'raw-schema'!$A:$R,18,0) -> #N/A | AF5: 예외 적용 (blocked by robots.txt)
A6: {=INDEX('raw-sheet'!$A$2:$ZZ$1000, ROW(A5), MATCH(A$1, 'raw-sheet'!$A$1:$ZZ$1, 0))} -> https://innisfree-taiwan.myshopify.com/account/login | B6: Pass | C6: {=INDEX('raw-sheet'!$A$2:$ZZ$1000, ROW(C5), MATCH(C$1, 'raw-sheet'!$A$1:$ZZ$1, 0))} -> 0 | D6: {=INDEX('raw-sheet'!$A$2:$ZZ$1000, ROW(D5), MATCH(D$1, 'raw-sheet'!$A$1:$ZZ$1, 0))} -> 200 | E6: =IF(D6=200,"Pass","Not") -> Pass | F6: {=INDEX('raw-sheet'!$A$2:$ZZ$1000, ROW(F5), MATCH(F$1, 'raw-sheet'!$A$1:$ZZ$1, 0))} -> 帳號_x000D_ | INNISFREE Taiwan | G6: Pass | H6: {=INDEX('raw-sheet'!$A$2:$ZZ$1000, ROW(H5), MATCH(H$1, 'raw-sheet'!$A$1:$ZZ$1, 0))} -> 0 | I6: Pass | J6: {=INDEX('raw-sheet'!$A$2:$ZZ$1000, ROW(J5), MATCH(J$1, 'raw-sheet'!$A$1:$ZZ$1, 0))} -> 重設密碼 | K6: {=INDEX('raw-sheet'!$A$2:$ZZ$1000, ROW(K5), MATCH(K$1, 'raw-sheet'!$A$1:$ZZ$1, 0))} -> 2 | L6: Pass | M6: {=INDEX('raw-sheet'!$A$2:$ZZ$1000, ROW(M5), MATCH(M$1, 'raw-sheet'!$A$1:$ZZ$1, 0))} -> https://innisfree-taiwan.myshopify.com/account/login | N6: =IF(A6=M6,"Pass","Not") -> Pass | O6: {=INDEX('raw-sheet'!$A$2:$ZZ$1000, ROW(O5), MATCH(O$1, 'raw-sheet'!$A$1:$ZZ$1, 0))} -> 帳號 | INNISFREE Taiwan | P6: {=INDEX('raw-sheet'!$A$2:$ZZ$1000, ROW(P5), MATCH(P$1, 'raw-sheet'!$A$1:$ZZ$1, 0))} -> innisfree 來自韓國濟州島的No.1自然主義美妝保養品牌，不僅將濟州島清新潔淨的空氣、溫暖和煦的陽光、純淨天然的水源、肥沃健康的土壤、自然純粹的植物養分注入保養品，更為消費者打造健康與美麗。| innisfree Taiwan | Q6: {=INDEX('raw-sheet'!$A$2:$ZZ$1000, ROW(Q5), MATCH(Q$1, 'raw-sheet'!$A$1:$ZZ$1, 0))} -> website | R6: {=INDEX('raw-sheet'!$A$2:$ZZ$1000, ROW(R5), MATCH(R$1, 'raw-sheet'!$A$1:$ZZ$1, 0))} -> INNISFREE Taiwan | S6: {=INDEX('raw-sheet'!$A$2:$ZZ$1000, ROW(S5), MATCH(S$1, 'raw-sheet'!$A$1:$ZZ$1, 0))} -> http://innisfree-taiwan.myshopify.com/cdn/shop/files/logo.png?v=1767594135 | T6: {=INDEX('raw-sheet'!$A$2:$ZZ$1000, ROW(T5), MATCH(T$1, 'raw-sheet'!$A$1:$ZZ$1, 0))} -> https://innisfree-taiwan.myshopify.com/cdn/shop/files/logo.png?v=1767594135 | U6: {=INDEX('raw-sheet'!$A$2:$ZZ$1000, ROW(U5), MATCH(U$1, 'raw-sheet'!$A$1:$ZZ$1, 0))} -> https://innisfree-taiwan.myshopify.com/account/login | V6: {=INDEX('raw-sheet'!$A$2:$ZZ$1000, ROW(V5), MATCH(V$1, 'raw-sheet'!$A$1:$ZZ$1, 0))} -> 帳號 | INNISFREE Taiwan | ... X6: {=INDEX('raw-sheet'!$A$2:$ZZ$1000, ROW(X5), MATCH(X$1, 'raw-sheet'!$A$1:$ZZ$1, 0))} -> summary_large_image | Y6: Pass | Z6: =VLOOKUP($A6,'raw-schema'!$A:$R,14,0) -> Organization | AA6: =VLOOKUP($A6,'raw-schema'!$A:$R,15,0) -> 0 | AB6: =VLOOKUP($A6,'raw-schema'!$A:$R,16,0) -> 0 | AC6: =VLOOKUP($A6,'raw-schema'!$A:$R,17,0) -> 0 | AD6: =VLOOKUP($A6,'raw-schema'!$A:$R,18,0) -> 0 | AE6: Pass | AF6: 예외 적용 (blocked by robots.txt)
A7: {=INDEX('raw-sheet'!$A$2:$ZZ$1000, ROW(A6), MATCH(A$1, 'raw-sheet'!$A$1:$ZZ$1, 0))} -> https://innisfree-taiwan.myshopify.com/account/login?return_url=%2Faccount | B7: Pass | C7: {=INDEX('raw-sheet'!$A$2:$ZZ$1000, ROW(C6), MATCH(C$1, 'raw-sheet'!$A$1:$ZZ$1, 0))} -> 0 | D7: {=INDEX('raw-sheet'!$A$2:$ZZ$1000, ROW(D6), MATCH(D$1, 'raw-sheet'!$A$1:$ZZ$1, 0))} -> 200 | E7: =IF(D7=200,"Pass","Not") -> Pass | F7: {=INDEX('raw-sheet'!$A$2:$ZZ$1000, ROW(F6), MATCH(F$1, 'raw-sheet'!$A$1:$ZZ$1, 0))} -> 帳號_x000D_ | INNISFREE Taiwan | G7: Pass | H7: {=INDEX('raw-sheet'!$A$2:$ZZ$1000, ROW(H6), MATCH(H$1, 'raw-sheet'!$A$1:$ZZ$1, 0))} -> 0 | I7: Pass | J7: {=INDEX('raw-sheet'!$A$2:$ZZ$1000, ROW(J6), MATCH(J$1, 'raw-sheet'!$A$1:$ZZ$1, 0))} -> 重設密碼 | K7: {=INDEX('raw-sheet'!$A$2:$ZZ$1000, ROW(K6), MATCH(K$1, 'raw-sheet'!$A$1:$ZZ$1, 0))} -> 2 | L7: Pass | M7: {=INDEX('raw-sheet'!$A$2:$ZZ$1000, ROW(M6), MATCH(M$1, 'raw-sheet'!$A$1:$ZZ$1, 0))} -> https://innisfree-taiwan.myshopify.com/account/login | N7: =IF(A7=M7,"Pass","Not") -> Not | O7: {=INDEX('raw-sheet'!$A$2:$ZZ$1000, ROW(O6), MATCH(O$1, 'raw-sheet'!$A$1:$ZZ$1, 0))} -> 帳號 | INNISFREE Taiwan | P7: {=INDEX('raw-sheet'!$A$2:$ZZ$1000, ROW(P6), MATCH(P$1, 'raw-sheet'!$A$1:$ZZ$1, 0))} -> innisfree 來自韓國濟州島的No.1自然主義美妝保養品牌，不僅將濟州島清新潔淨的空氣、溫暖和煦的陽光、純淨天然的水源、肥沃健康的土壤、自然純粹的植物養分注入保養品，更為消費者打造健康與美麗。| innisfree Taiwan | Q7: {=INDEX('raw-sheet'!$A$2:$ZZ$1000, ROW(Q6), MATCH(Q$1, 'raw-sheet'!$A$1:$ZZ$1, 0))} -> website | R7: {=INDEX('raw-sheet'!$A$2:$ZZ$1000, ROW(R6), MATCH(R$1, 'raw-sheet'!$A$1:$ZZ$1, 0))} -> INNISFREE Taiwan | S7: {=INDEX('raw-sheet'!$A$2:$ZZ$1000, ROW(S6), MATCH(S$1, 'raw-sheet'!$A$1:$ZZ$1, 0))} -> http://innisfree-taiwan.myshopify.com/cdn/shop/files/logo.png?v=1767594135 | T7: {=INDEX('raw-sheet'!$A$2:$ZZ$1000, ROW(T6), MATCH(T$1, 'raw-sheet'!$A$1:$ZZ$1, 0))} -> https://innisfree-taiwan.myshopify.com/cdn/shop/files/logo.png?v=1767594135 | U7: {=INDEX('raw-sheet'!$A$2:$ZZ$1000, ROW(U6), MATCH(U$1, 'raw-sheet'!$A$1:$ZZ$1, 0))} -> https://innisfree-taiwan.myshopify.com/account/login | V7: {=INDEX('raw-sheet'!$A$2:$ZZ$1000, ROW(V6), MATCH(V$1, 'raw-sheet'!$A$1:$ZZ$1, 0))} -> 帳號 | INNISFREE Taiwan | ... X7: {=INDEX('raw-sheet'!$A$2:$ZZ$1000, ROW(X6), MATCH(X$1, 'raw-sheet'!$A$1:$ZZ$1, 0))} -> summary_large_image | Y7: Pass | Z7: =VLOOKUP($A7,'raw-schema'!$A:$R,14,0) -> Organization | AA7: =VLOOKUP($A7,'raw-schema'!$A:$R,15,0) -> 0 | AB7: =VLOOKUP($A7,'raw-schema'!$A:$R,16,0) -> 0 | AC7: =VLOOKUP($A7,'raw-schema'!$A:$R,17,0) -> 0 | AD7: =VLOOKUP($A7,'raw-schema'!$A:$R,18,0) -> 0 | AE7: Pass | AF7: 예외 적용 (blocked by robots.txt)
A8: {=INDEX('raw-sheet'!$A$2:$ZZ$1000, ROW(A7), MATCH(A$1, 'raw-sheet'!$A$1:$ZZ$1, 0))} -> https://innisfree-taiwan.myshopify.com/account/login?return_url=%2Faccount%2Faddresses | B8: Pass | C8: {=INDEX('raw-sheet'!$A$2:$ZZ$1000, ROW(C7), MATCH(C$1, 'raw-sheet'!$A$1:$ZZ$1, 0))} -> 0 | D8: {=INDEX('raw-sheet'!$A$2:$ZZ$1000, ROW(D7), MATCH(D$1, 'raw-sheet'!$A$1:$ZZ$1, 0))} -> 200 | E8: =IF(D8=200,"Pass","Not") -> Pass | F8: {=INDEX('raw-sheet'!$A$2:$ZZ$1000, ROW(F7), MATCH(F$1, 'raw-sheet'!$A$1:$ZZ$1, 0))} -> 帳號_x000D_ | INNISFREE Taiwan | G8: Pass | H8: {=INDEX('raw-sheet'!$A$2:$ZZ$1000, ROW(H7), MATCH(H$1, 'raw-sheet'!$A$1:$ZZ$1, 0))} -> 0 | I8: Pass | J8: {=INDEX('raw-sheet'!$A$2:$ZZ$1000, ROW(J7), MATCH(J$1, 'raw-sheet'!$A$1:$ZZ$1, 0))} -> 重設密碼 | K8: {=INDEX('raw-sheet'!$A$2:$ZZ$1000, ROW(K7), MATCH(K$1, 'raw-sheet'!$A$1:$ZZ$1, 0))} -> 2 | L8: Pass | M8: {=INDEX('raw-sheet'!$A$2:$ZZ$1000, ROW(M7), MATCH(M$1, 'raw-sheet'!$A$1:$ZZ$1, 0))} -> https://innisfree-taiwan.myshopify.com/account/login | N8: =IF(A8=M8,"Pass","Not") -> Not | O8: {=INDEX('raw-sheet'!$A$2:$ZZ$1000, ROW(O7), MATCH(O$1, 'raw-sheet'!$A$1:$ZZ$1, 0))} -> 帳號 | INNISFREE Taiwan | P8: {=INDEX('raw-sheet'!$A$2:$ZZ$1000, ROW(P7), MATCH(P$1, 'raw-sheet'!$A$1:$ZZ$1, 0))} -> innisfree 來自韓國濟州島的No.1自然主義美妝保養品牌，不僅將濟州島清新潔淨的空氣、溫暖和煦的陽光、純淨天然的水源、肥沃健康的土壤、自然純粹的植物養分注入保養品，更為消費者打造健康與美麗。| innisfree Taiwan | Q8: {=INDEX('raw-sheet'!$A$2:$ZZ$1000, ROW(Q7), MATCH(Q$1, 'raw-sheet'!$A$1:$ZZ$1, 0))} -> website | R8: {=INDEX('raw-sheet'!$A$2:$ZZ$1000, ROW(R7), MATCH(R$1, 'raw-sheet'!$A$1:$ZZ$1, 0))} -> INNISFREE Taiwan | S8: {=INDEX('raw-sheet'!$A$2:$ZZ$1000, ROW(S7), MATCH(S$1, 'raw-sheet'!$A$1:$ZZ$1, 0))} -> http://innisfree-taiwan.myshopify.com/cdn/shop/files/logo.png?v=1767594135 | T8: {=INDEX('raw-sheet'!$A$2:$ZZ$1000, ROW(T7), MATCH(T$1, 'raw-sheet'!$A$1:$ZZ$1, 0))} -> https://innisfree-taiwan.myshopify.com/cdn/shop/files/logo.png?v=1767594135 | U8: {=INDEX('raw-sheet'!$A$2:$ZZ$1000, ROW(U7), MATCH(U$1, 'raw-sheet'!$A$1:$ZZ$1, 0))} -> https://innisfree-taiwan.myshopify.com/account/login | V8: {=INDEX('raw-sheet'!$A$2:$ZZ$1000, ROW(V7), MATCH(V$1, 'raw-sheet'!$A$1:$ZZ$1, 0))} -> 帳號 | INNISFREE Taiwan | ... X8: {=INDEX('raw-sheet'!$A$2:$ZZ$1000, ROW(X7), MATCH(X$1, 'raw-sheet'!$A$1:$ZZ$1, 0))} -> summary_large_image | Y8: Pass | Z8: =VLOOKUP($A8,'raw-schema'!$A:$R,14,0) -> Organization | AA8: =VLOOKUP($A8,'raw-schema'!$A:$R,15,0) -> 0 | AB8: =VLOOKUP($A8,'raw-schema'!$A:$R,16,0) -> 0 | AC8: =VLOOKUP($A8,'raw-schema'!$A:$R,17,0) -> 0 | AD8: =VLOOKUP($A8,'raw-schema'!$A:$R,18,0) -> 0 | AE8: Pass | AF8: 예외 적용 (blocked by robots.txt)
A9: {=INDEX('raw-sheet'!$A$2:$ZZ$1000, ROW(A8), MATCH(A$1, 'raw-sheet'!$A$1:$ZZ$1, 0))} -> https://innisfree-taiwan.myshopify.com/account/register | B9: Pass | C9: {=INDEX('raw-sheet'!$A$2:$ZZ$1000, ROW(C8), MATCH(C$1, 'raw-sheet'!$A$1:$ZZ$1, 0))} -> 0 | D9: {=INDEX('raw-sheet'!$A$2:$ZZ$1000, ROW(D8), MATCH(D$1, 'raw-sheet'!$A$1:$ZZ$1, 0))} -> 200 | E9: =IF(D9=200,"Pass","Not") -> Pass | F9: {=INDEX('raw-sheet'!$A$2:$ZZ$1000, ROW(F8), MATCH(F$1, 'raw-sheet'!$A$1:$ZZ$1, 0))} -> 建立帳號_x000D_ | INNISFREE Taiwan | G9: Pass | H9: {=INDEX('raw-sheet'!$A$2:$ZZ$1000, ROW(H8), MATCH(H$1, 'raw-sheet'!$A$1:$ZZ$1, 0))} -> 0 | I9: Pass | J9: {=INDEX('raw-sheet'!$A$2:$ZZ$1000, ROW(J8), MATCH(J$1, 'raw-sheet'!$A$1:$ZZ$1, 0))} -> 註冊 | K9: {=INDEX('raw-sheet'!$A$2:$ZZ$1000, ROW(K8), MATCH(K$1, 'raw-sheet'!$A$1:$ZZ$1, 0))} -> 1 | L9: Pass | M9: {=INDEX('raw-sheet'!$A$2:$ZZ$1000, ROW(M8), MATCH(M$1, 'raw-sheet'!$A$1:$ZZ$1, 0))} -> https://innisfree-taiwan.myshopify.com/account/register | N9: =IF(A9=M9,"Pass","Not") -> Pass | O9: {=INDEX('raw-sheet'!$A$2:$ZZ$1000, ROW(O8), MATCH(O$1, 'raw-sheet'!$A$1:$ZZ$1, 0))} -> 建立帳號 | INNISFREE Taiwan | P9: {=INDEX('raw-sheet'!$A$2:$ZZ$1000, ROW(P8), MATCH(P$1, 'raw-sheet'!$A$1:$ZZ$1, 0))} -> innisfree 來自韓國濟州島的No.1自然主義美妝保養品牌，不僅將濟州島清新潔淨的空氣、溫暖和煦的陽光、純淨天然的水源、肥沃健康的土壤、自然純粹的植物養分注入保養品，更為消費者打造健康與美麗。| innisfree Taiwan | Q9: {=INDEX('raw-sheet'!$A$2:$ZZ$1000, ROW(Q8), MATCH(Q$1, 'raw-sheet'!$A$1:$ZZ$1, 0))} -> website | R9: {=INDEX('raw-sheet'!$A$2:$ZZ$1000, ROW(R8), MATCH(R$1, 'raw-sheet'!$A$1:$ZZ$1, 0))} -> INNISFREE Taiwan | S9: {=INDEX('raw-sheet'!$A$2:$ZZ$1000, ROW(S8), MATCH(S$1, 'raw-sheet'!$A$1:$ZZ$1, 0))} -> http://innisfree-taiwan.myshopify.com/cdn/shop/files/logo.png?v=1767594135 | T9: {=INDEX('raw-sheet'!$A$2:$ZZ$1000, ROW(T8), MATCH(T$1, 'raw-sheet'!$A$1:$ZZ$1, 0))} -> https://innisfree-taiwan.myshopify.com/cdn/shop/files/logo.png?v=1767594135 | U9: {=INDEX('raw-sheet'!$A$2:$ZZ$1000, ROW(U8), MATCH(U$1, 'raw-sheet'!$A$1:$ZZ$1, 0))} -> https://innisfree-taiwan.myshopify.com/account/register | V9: {=INDEX('raw-sheet'!$A$2:$ZZ$1000, ROW(V8), MATCH(V$1, 'raw-sheet'!$A$1:$ZZ$1, 0))} -> 建立帳號 | INNISFREE Taiwan | ... X9: {=INDEX('raw-sheet'!$A$2:$ZZ$1000, ROW(X8), MATCH(X$1, 'raw-sheet'!$A$1:$ZZ$1, 0))} -> summary_large_image | Y9: Pass | Z9: =VLOOKUP($A9,'raw-schema'!$A:$R,14,0) -> Organization | AA9: =VLOOKUP($A9,'raw-schema'!$A:$R,15,0) -> 0 | AB9: =VLOOKUP($A9,'raw-schema'!$A:$R,16,0) -> 0 | AC9: =VLOOKUP($A9,'raw-schema'!$A:$R,17,0) -> 0 | AD9: =VLOOKUP($A9,'raw-schema'!$A:$R,18,0) -> 0 | AE9: Pass | AF9: 예외 적용 (blocked by robots.txt)
A10: {=INDEX('raw-sheet'!$A$2:$ZZ$1000, ROW(A9), MATCH(A$1, 'raw-sheet'!$A$1:$ZZ$1, 0))} -> https://innisfree-taiwan.myshopify.com/blogs/event | B10: Pass | C10: {=INDEX('raw-sheet'!$A$2:$ZZ$1000, ROW(C9), MATCH(C$1, 'raw-sheet'!$A$1:$ZZ$1, 0))} -> Blog Page | D10: {=INDEX('raw-sheet'!$A$2:$ZZ$1000, ROW(D9), MATCH(D$1, 'raw-sheet'!$A$1:$ZZ$1, 0))} -> 200 | E10: =IF(D10=200,"Pass","Not") -> Pass | F10: {=INDEX('raw-sheet'!$A$2:$ZZ$1000, ROW(F9), MATCH(F$1, 'raw-sheet'!$A$1:$ZZ$1, 0))} -> 活動_x000D_ | INNISFREE Taiwan | G10: duplicate | H10: {=INDEX('raw-sheet'!$A$2:$ZZ$1000, ROW(H9), MATCH(H$1, 'raw-sheet'!$A$1:$ZZ$1, 0))} -> 0 | I10: missing | J10: {=INDEX('raw-sheet'!$A$2:$ZZ$1000, ROW(J9), MATCH(J$1, 'raw-sheet'!$A$1:$ZZ$1, 0))} -> 活動 | K10: {=INDEX('raw-sheet'!$A$2:$ZZ$1000, ROW(K9), MATCH(K$1, 'raw-sheet'!$A$1:$ZZ$1, 0))} -> 1 | L10: duplicate | M10: {=INDEX('raw-sheet'!$A$2:$ZZ$1000, ROW(M9), MATCH(M$1, 'raw-sheet'!$A$1:$ZZ$1, 0))} -> https://innisfree-taiwan.myshopify.com/blogs/event | N10: =IF(A10=M10,"Pass","Not") -> Pass | O10: {=INDEX('raw-sheet'!$A$2:$ZZ$1000, ROW(O9), MATCH(O$1, 'raw-sheet'!$A$1:$ZZ$1, 0))} -> 活動 | INNISFREE Taiwan | P10: {=INDEX('raw-sheet'!$A$2:$ZZ$1000, ROW(P9), MATCH(P$1, 'raw-sheet'!$A$1:$ZZ$1, 0))} -> innisfree 來自韓國濟州島的No.1自然主義美妝保養品牌，不僅將濟州島清新潔淨的空氣、溫暖和煦的陽光、純淨天然的水源、肥沃健康的土壤、自然純粹的植物養分注入保養品，更為消費者打造健康與美麗。| innisfree Taiwan | Q10: {=INDEX('raw-sheet'!$A$2:$ZZ$1000, ROW(Q9), MATCH(Q$1, 'raw-sheet'!$A$1:$ZZ$1, 0))} -> website | R10: {=INDEX('raw-sheet'!$A$2:$ZZ$1000, ROW(R9), MATCH(R$1, 'raw-sheet'!$A$1:$ZZ$1, 0))} -> INNISFREE Taiwan | S10: {=INDEX('raw-sheet'!$A$2:$ZZ$1000, ROW(S9), MATCH(S$1, 'raw-sheet'!$A$1:$ZZ$1, 0))} -> http://innisfree-taiwan.myshopify.com/cdn/shop/files/logo.png?v=1767594135 | T10: {=INDEX('raw-sheet'!$A$2:$ZZ$1000, ROW(T9), MATCH(T$1, 'raw-sheet'!$A$1:$ZZ$1, 0))} -> https://innisfree-taiwan.myshopify.com/cdn/shop/files/logo.png?v=1767594135 | U10: {=INDEX('raw-sheet'!$A$2:$ZZ$1000, ROW(U9), MATCH(U$1, 'raw-sheet'!$A$1:$ZZ$1, 0))} -> https://innisfree-taiwan.myshopify.com/blogs/event | V10: {=INDEX('raw-sheet'!$A$2:$ZZ$1000, ROW(V9), MATCH(V$1, 'raw-sheet'!$A$1:$ZZ$1, 0))} -> 活動 | INNISFREE Taiwan | ... X10: {=INDEX('raw-sheet'!$A$2:$ZZ$1000, ROW(X9), MATCH(X$1, 'raw-sheet'!$A$1:$ZZ$1, 0))} -> summary_large_image | Y10: duplicate title duplicate desc. | Z10: =VLOOKUP($A10,'raw-schema'!$A:$R,14,0) -> Organization | AA10: =VLOOKUP($A10,'raw-schema'!$A:$R,15,0) -> 0 | AB10: =VLOOKUP($A10,'raw-schema'!$A:$R,16,0) -> 0 | AC10: =VLOOKUP($A10,'raw-schema'!$A:$R,17,0) -> 0 | AD10: =VLOOKUP($A10,'raw-schema'!$A:$R,18,0) -> 0 | AE10: Schema 보강 필요 (Blog)
A11: {=INDEX('raw-sheet'!$A$2:$ZZ$1000, ROW(A10), MATCH(A$1, 'raw-sheet'!$A$1:$ZZ$1, 0))} -> https://innisfree-taiwan.myshopify.com/blogs/event/gift-set_event-list | B11: underbar("_") x hyphen is recommended | C11: {=INDEX('raw-sheet'!$A$2:$ZZ$1000, ROW(C10), MATCH(C$1, 'raw-sheet'!$A$1:$ZZ$1, 0))} -> Blog Page | D11: {=INDEX('raw-sheet'!$A$2:$ZZ$1000, ROW(D10), MATCH(D$1, 'raw-sheet'!$A$1:$ZZ$1, 0))} -> 200 | E11: =IF(D11=200,"Pass","Not") -> Pass | F11: {=INDEX('raw-sheet'!$A$2:$ZZ$1000, ROW(F10), MATCH(F$1, 'raw-sheet'!$A$1:$ZZ$1, 0))} -> Gift set_Event List_x000D_ | INNISFREE Taiwan | G11: Pass | H11: {=INDEX('raw-sheet'!$A$2:$ZZ$1000, ROW(H10), MATCH(H$1, 'raw-sheet'!$A$1:$ZZ$1, 0))} -> 0 | I11: missing | J11: {=INDEX('raw-sheet'!$A$2:$ZZ$1000, ROW(J10), MATCH(J$1, 'raw-sheet'!$A$1:$ZZ$1, 0))} -> Gift set_Event List | K11: {=INDEX('raw-sheet'!$A$2:$ZZ$1000, ROW(K10), MATCH(K$1, 'raw-sheet'!$A$1:$ZZ$1, 0))} -> 1 | L11: Pass | M11: {=INDEX('raw-sheet'!$A$2:$ZZ$1000, ROW(M10), MATCH(M$1, 'raw-sheet'!$A$1:$ZZ$1, 0))} -> https://innisfree-taiwan.myshopify.com/blogs/event/gift-set_event-list | N11: =IF(A11=M11,"Pass","Not") -> Pass | O11: {=INDEX('raw-sheet'!$A$2:$ZZ$1000, ROW(O10), MATCH(O$1, 'raw-sheet'!$A$1:$ZZ$1, 0))} -> Gift set_Event List | INNISFREE Taiwan | P11: {=INDEX('raw-sheet'!$A$2:$ZZ$1000, ROW(P10), MATCH(P$1, 'raw-sheet'!$A$1:$ZZ$1, 0))} -> innisfree 來自韓國濟州島的No.1自然主義美妝保養品牌，不僅將濟州島清新潔淨的空氣、溫暖和煦的陽光、純淨天然的水源、肥沃健康的土壤、自然純粹的植物養分注入保養品，更為消費者打造健康與美麗。| innisfree Taiwan | Q11: {=INDEX('raw-sheet'!$A$2:$ZZ$1000, ROW(Q10), MATCH(Q$1, 'raw-sheet'!$A$1:$ZZ$1, 0))} -> article | R11: {=INDEX('raw-sheet'!$A$2:$ZZ$1000, ROW(R10), MATCH(R$1, 'raw-sheet'!$A$1:$ZZ$1, 0))} -> INNISFREE Taiwan | S11: {=INDEX('raw-sheet'!$A$2:$ZZ$1000, ROW(S10), MATCH(S$1, 'raw-sheet'!$A$1:$ZZ$1, 0))} -> http://innisfree-taiwan.myshopify.com/cdn/shop/articles/Gift_set_Event_List_PC__963x600_1256ad40-bdd5-472a-99dd-26407920d6ec.jpg?v=1770101796 | T11: {=INDEX('raw-sheet'!$A$2:$ZZ$1000, ROW(T10), MATCH(T$1, 'raw-sheet'!$A$1:$ZZ$1, 0))} -> https://innisfree-taiwan.myshopify.com/cdn/shop/articles/Gift_set_Event_List_PC__963x600_1256ad40-bdd5-472a-99dd-26407920d6ec.jpg?v=1770101796 | U11: {=INDEX('raw-sheet'!$A$2:$ZZ$1000, ROW(U10), MATCH(U$1, 'raw-sheet'!$A$1:$ZZ$1, 0))} -> https://innisfree-taiwan.myshopify.com/blogs/event/gift-set_event-list | V11: {=INDEX('raw-sheet'!$A$2:$ZZ$1000, ROW(V10), MATCH(V$1, 'raw-sheet'!$A$1:$ZZ$1, 0))} -> Gift set_Event List | INNISFREE Taiwan | ... X11: {=INDEX('raw-sheet'!$A$2:$ZZ$1000, ROW(X10), MATCH(X$1, 'raw-sheet'!$A$1:$ZZ$1, 0))} -> summary_large_image | Y11: duplicate desc. | Z11: =VLOOKUP($A11,'raw-schema'!$A:$R,14,0) -> Article | AA11: =VLOOKUP($A11,'raw-schema'!$A:$R,15,0) -> Organization | AB11: =VLOOKUP($A11,'raw-schema'!$A:$R,16,0) -> Person | AC11: =VLOOKUP($A11,'raw-schema'!$A:$R,17,0) -> WebPage | AD11: =VLOOKUP($A11,'raw-schema'!$A:$R,18,0) -> 0 | AE11: Schema 보강 필요 (Blog)
A12: {=INDEX('raw-sheet'!$A$2:$ZZ$1000, ROW(A11), MATCH(A$1, 'raw-sheet'!$A$1:$ZZ$1, 0))} -> https://innisfree-taiwan.myshopify.com/blogs/event/leave-a-review-and-get-a-free-face-mask | B12: Pass | C12: {=INDEX('raw-sheet'!$A$2:$ZZ$1000, ROW(C11), MATCH(C$1, 'raw-sheet'!$A$1:$ZZ$1, 0))} -> Blog Page | D12: {=INDEX('raw-sheet'!$A$2:$ZZ$1000, ROW(D11), MATCH(D$1, 'raw-sheet'!$A$1:$ZZ$1, 0))} -> 200 | E12: =IF(D12=200,"Pass","Not") -> Pass | F12: {=INDEX('raw-sheet'!$A$2:$ZZ$1000, ROW(F11), MATCH(F$1, 'raw-sheet'!$A$1:$ZZ$1, 0))} -> 填心得 領面膜！_x000D_ | INNISFREE Taiwan | G12: Pass | H12: {=INDEX('raw-sheet'!$A$2:$ZZ$1000, ROW(H11), MATCH(H$1, 'raw-sheet'!$A$1:$ZZ$1, 0))} -> 0 | I12: missing | J12: {=INDEX('raw-sheet'!$A$2:$ZZ$1000, ROW(J11), MATCH(J$1, 'raw-sheet'!$A$1:$ZZ$1, 0))} -> 填心得 領面膜！ | K12: {=INDEX('raw-sheet'!$A$2:$ZZ$1000, ROW(K11), MATCH(K$1, 'raw-sheet'!$A$1:$ZZ$1, 0))} -> 1 | L12: Pass | M12: {=INDEX('raw-sheet'!$A$2:$ZZ$1000, ROW(M11), MATCH(M$1, 'raw-sheet'!$A$1:$ZZ$1, 0))} -> https://innisfree-taiwan.myshopify.com/blogs/event/leave-a-review-and-get-a-free-face-mask | N12: =IF(A12=M12,"Pass","Not") -> Pass | O12: {=INDEX('raw-sheet'!$A$2:$ZZ$1000, ROW(O11), MATCH(O$1, 'raw-sheet'!$A$1:$ZZ$1, 0))} -> 填心得 領面膜！ | INNISFREE Taiwan | P12: {=INDEX('raw-sheet'!$A$2:$ZZ$1000, ROW(P11), MATCH(P$1, 'raw-sheet'!$A$1:$ZZ$1, 0))} -> innisfree 來自韓國濟州島的No.1自然主義美妝保養品牌，不僅將濟州島清新潔淨的空氣、溫暖和煦的陽光、純淨天然的水源、肥沃健康的土壤、自然純粹的植物養分注入保養品，更為消費者打造健康與美麗。| innisfree Taiwan | Q12: {=INDEX('raw-sheet'!$A$2:$ZZ$1000, ROW(Q11), MATCH(Q$1, 'raw-sheet'!$A$1:$ZZ$1, 0))} -> article | R12: {=INDEX('raw-sheet'!$A$2:$ZZ$1000, ROW(R11), MATCH(R$1, 'raw-sheet'!$A$1:$ZZ$1, 0))} -> INNISFREE Taiwan | S12: {=INDEX('raw-sheet'!$A$2:$ZZ$1000, ROW(S11), MATCH(S$1, 'raw-sheet'!$A$1:$ZZ$1, 0))} -> http://innisfree-taiwan.myshopify.com/cdn/shop/articles/377_EV0102_attimg_origin_a54ebf7e-6a2b-4bb2-a2d0-aeee77f64cd7.jpg?v=1769748350 | T12: {=INDEX('raw-sheet'!$A$2:$ZZ$1000, ROW(T11), MATCH(T$1, 'raw-sheet'!$A$1:$ZZ$1, 0))} -> https://innisfree-taiwan.myshopify.com/cdn/shop/articles/377_EV0102_attimg_origin_a54ebf7e-6a2b-4bb2-a2d0-aeee77f64cd7.jpg?v=1769748350 | U12: {=INDEX('raw-sheet'!$A$2:$ZZ$1000, ROW(U11), MATCH(U$1, 'raw-sheet'!$A$1:$ZZ$1, 0))} -> https://innisfree-taiwan.myshopify.com/blogs/event/leave-a-review-and-get-a-free-face-mask | V12: {=INDEX('raw-sheet'!$A$2:$ZZ$1000, ROW(V11), MATCH(V$1, 'raw-sheet'!$A$1:$ZZ$1, 0))} -> 填心得 領面膜！ | INNISFREE Taiwan | ... X12: {=INDEX('raw-sheet'!$A$2:$ZZ$1000, ROW(X11), MATCH(X$1, 'raw-sheet'!$A$1:$ZZ$1, 0))} -> summary_large_image | Y12: duplicate desc. | Z12: =VLOOKUP($A12,'raw-schema'!$A:$R,14,0) -> Article | AA12: =VLOOKUP($A12,'raw-schema'!$A:$R,15,0) -> Organization | AB12: =VLOOKUP($A12,'raw-schema'!$A:$R,16,0) -> Person | AC12: =VLOOKUP($A12,'raw-schema'!$A:$R,17,0) -> WebPage | AD12: =VLOOKUP($A12,'raw-schema'!$A:$R,18,0) -> 0 | AE12: Schema 보강 필요 (Blog)
A13: {=INDEX('raw-sheet'!$A$2:$ZZ$1000, ROW(A12), MATCH(A$1, 'raw-sheet'!$A$1:$ZZ$1, 0))} -> https://innisfree-taiwan.myshopify.com/blogs/event/monthly-vip-exclusive-offers | B13: Pass | C13: {=INDEX('raw-sheet'!$A$2:$ZZ$1000, ROW(C12), MATCH(C$1, 'raw-sheet'!$A$1:$ZZ$1, 0))} -> Blog Page | D13: {=INDEX('raw-sheet'!$A$2:$ZZ$1000, ROW(D12), MATCH(D$1, 'raw-sheet'!$A$1:$ZZ$1, 0))} -> 200 | E13: =IF(D13=200,"Pass","Not") -> Pass | F13: {=INDEX('raw-sheet'!$A$2:$ZZ$1000, ROW(F12), MATCH(F$1, 'raw-sheet'!$A$1:$ZZ$1, 0))} -> 👑每月VIP專屬優惠👑_x000D_ | INNISFREE Taiwan | G13: Pass | H13: {=INDEX('raw-sheet'!$A$2:$ZZ$1000, ROW(H12), MATCH(H$1, 'raw-sheet'!$A$1:$ZZ$1, 0))} -> 0 | I13: missing | J13: {=INDEX('raw-sheet'!$A$2:$ZZ$1000, ROW(J12), MATCH(J$1, 'raw-sheet'!$A$1:$ZZ$1, 0))} -> 👑每月VIP專屬優惠👑 | K13: {=INDEX('raw-sheet'!$A$2:$ZZ$1000, ROW(K12), MATCH(K$1, 'raw-sheet'!$A$1:$ZZ$1, 0))} -> 1 | L13: Pass | M13: {=INDEX('raw-sheet'!$A$2:$ZZ$1000, ROW(M12), MATCH(M$1, 'raw-sheet'!$A$1:$ZZ$1, 0))} -> https://innisfree-taiwan.myshopify.com/blogs/event/monthly-vip-exclusive-offers | N13: =IF(A13=M13,"Pass","Not") -> Pass | O13: {=INDEX('raw-sheet'!$A$2:$ZZ$1000, ROW(O12), MATCH(O$1, 'raw-sheet'!$A$1:$ZZ$1, 0))} -> 👑每月VIP專屬優惠👑 | INNISFREE Taiwan | P13: {=INDEX('raw-sheet'!$A$2:$ZZ$1000, ROW(P12), MATCH(P$1, 'raw-sheet'!$A$1:$ZZ$1, 0))} -> innisfree 來自韓國濟州島的No.1自然主義美妝保養品牌，不僅將濟州島清新潔淨的空氣、溫暖和煦的陽光、純淨天然的水源、肥沃健康的土壤、自然純粹的植物養分注入保養品，更為消費者打造健康與美麗。| innisfree Taiwan | Q13: {=INDEX('raw-sheet'!$A$2:$ZZ$1000, ROW(Q12), MATCH(Q$1, 'raw-sheet'!$A$1:$ZZ$1, 0))} -> article | R13: {=INDEX('raw-sheet'!$A$2:$ZZ$1000, ROW(R12), MATCH(R$1, 'raw-sheet'!$A$1:$ZZ$1, 0))} -> INNISFREE Taiwan | S13: {=INDEX('raw-sheet'!$A$2:$ZZ$1000, ROW(S12), MATCH(S$1, 'raw-sheet'!$A$1:$ZZ$1, 0))} -> http://innisfree-taiwan.myshopify.com/cdn/shop/articles/pdp_mig_323ab24c_374_EV0102_attimg_origin_jpg.jpg?v=1768455377 | T13: {=INDEX('raw-sheet'!$A$2:$ZZ$1000, ROW(T12), MATCH(T$1, 'raw-sheet'!$A$1:$ZZ$1, 0))} -> https://innisfree-taiwan.myshopify.com/cdn/shop/articles/pdp_mig_323ab24c_374_EV0102_attimg_origin_jpg.jpg?v=1768455377 | U13: {=INDEX('raw-sheet'!$A$2:$ZZ$1000, ROW(U12), MATCH(U$1, 'raw-sheet'!$A$1:$ZZ$1, 0))} -> https://innisfree-taiwan.myshopify.com/blogs/event/monthly-vip-exclusive-offers | V13: {=INDEX('raw-sheet'!$A$2:$ZZ$1000, ROW(V12), MATCH(V$1, 'raw-sheet'!$A$1:$ZZ$1, 0))} -> 👑每月VIP專屬優惠👑 | INNISFREE Taiwan | ... X13: {=INDEX('raw-sheet'!$A$2:$ZZ$1000, ROW(X12), MATCH(X$1, 'raw-sheet'!$A$1:$ZZ$1, 0))} -> summary_large_image | Y13: duplicate desc. | Z13: =VLOOKUP($A13,'raw-schema'!$A:$R,14,0) -> Article | AA13: =VLOOKUP($A13,'raw-schema'!$A:$R,15,0) -> Organization | AB13: =VLOOKUP($A13,'raw-schema'!$A:$R,16,0) -> Person | AC13: =VLOOKUP($A13,'raw-schema'!$A:$R,17,0) -> WebPage | AD13: =VLOOKUP($A13,'raw-schema'!$A:$R,18,0) -> 0 | AE13: Schema 보강 필요 (Blog)
A14: {=INDEX('raw-sheet'!$A$2:$ZZ$1000, ROW(A13), MATCH(A$1, 'raw-sheet'!$A$1:$ZZ$1, 0))} -> https://innisfree-taiwan.myshopify.com/blogs/event/pdrn-anniversary-celebration | B14: Pass | C14: {=INDEX('raw-sheet'!$A$2:$ZZ$1000, ROW(C13), MATCH(C$1, 'raw-sheet'!$A$1:$ZZ$1, 0))} -> Blog Page | D14: {=INDEX('raw-sheet'!$A$2:$ZZ$1000, ROW(D13), MATCH(D$1, 'raw-sheet'!$A$1:$ZZ$1, 0))} -> 200 | E14: =IF(D14=200,"Pass","Not") -> Pass | F14: {=INDEX('raw-sheet'!$A$2:$ZZ$1000, ROW(F13), MATCH(F$1, 'raw-sheet'!$A$1:$ZZ$1, 0))} -> 🥳PDRN上市周年慶🎊🎂_x000D_ | INNISFREE Taiwan | G14: Pass | H14: {=INDEX('raw-sheet'!$A$2:$ZZ$1000, ROW(H13), MATCH(H$1, 'raw-sheet'!$A$1:$ZZ$1, 0))} -> 0 | I14: missing | J14: {=INDEX('raw-sheet'!$A$2:$ZZ$1000, ROW(J13), MATCH(J$1, 'raw-sheet'!$A$1:$ZZ$1, 0))} -> 🥳PDRN上市周年慶🎊🎂 | K14: {=INDEX('raw-sheet'!$A$2:$ZZ$1000, ROW(K13), MATCH(K$1, 'raw-sheet'!$A$1:$ZZ$1, 0))} -> 1 | L14: Pass | M14: {=INDEX('raw-sheet'!$A$2:$ZZ$1000, ROW(M13), MATCH(M$1, 'raw-sheet'!$A$1:$ZZ$1, 0))} -> https://innisfree-taiwan.myshopify.com/blogs/event/pdrn-anniversary-celebration | N14: =IF(A14=M14,"Pass","Not") -> Pass | O14: {=INDEX('raw-sheet'!$A$2:$ZZ$1000, ROW(O13), MATCH(O$1, 'raw-sheet'!$A$1:$ZZ$1, 0))} -> 🥳PDRN上市周年慶🎊🎂 | INNISFREE Taiwan | P14: {=INDEX('raw-sheet'!$A$2:$ZZ$1000, ROW(P13), MATCH(P$1, 'raw-sheet'!$A$1:$ZZ$1, 0))} -> innisfree 來自韓國濟州島的No.1自然主義美妝保養品牌，不僅將濟州島清新潔淨的空氣、溫暖和煦的陽光、純淨天然的水源、肥沃健康的土壤、自然純粹的植物養分注入保養品，更為消費者打造健康與美麗。| innisfree Taiwan | Q14: {=INDEX('raw-sheet'!$A$2:$ZZ$1000, ROW(Q13), MATCH(Q$1, 'raw-sheet'!$A$1:$ZZ$1, 0))} -> article | R14: {=INDEX('raw-sheet'!$A$2:$ZZ$1000, ROW(R13), MATCH(R$1, 'raw-sheet'!$A$1:$ZZ$1, 0))} -> INNISFREE Taiwan | S14: {=INDEX('raw-sheet'!$A$2:$ZZ$1000, ROW(S13), MATCH(S$1, 'raw-sheet'!$A$1:$ZZ$1, 0))} -> http://innisfree-taiwan.myshopify.com/cdn/shop/articles/376_EV0102_attimg_origin.jpg?v=1768455380 | T14: {=INDEX('raw-sheet'!$A$2:$ZZ$1000, ROW(T13), MATCH(T$1, 'raw-sheet'!$A$1:$ZZ$1, 0))} -> https://innisfree-taiwan.myshopify.com/cdn/shop/articles/376_EV0102_attimg_origin.jpg?v=1768455380 | U14: {=INDEX('raw-sheet'!$A$2:$ZZ$1000, ROW(U13), MATCH(U$1, 'raw-sheet'!$A$1:$ZZ$1, 0))} -> https://innisfree-taiwan.myshopify.com/blogs/event/pdrn-anniversary-celebration | V14: {=INDEX('raw-sheet'!$A$2:$ZZ$1000, ROW(V13), MATCH(V$1, 'raw-sheet'!$A$1:$ZZ$1, 0))} -> 🥳PDRN上市周年慶🎊🎂 | INNISFREE Taiwan | ... X14: {=INDEX('raw-sheet'!$A$2:$ZZ$1000, ROW(X13), MATCH(X$1, 'raw-sheet'!$A$1:$ZZ$1, 0))} -> summary_large_image | Y14: duplicate desc. | Z14: =VLOOKUP($A14,'raw-schema'!$A:$R,14,0) -> Article | AA14: =VLOOKUP($A14,'raw-schema'!$A:$R,15,0) -> Organization | AB14: =VLOOKUP($A14,'raw-schema'!$A:$R,16,0) -> Person | AC14: =VLOOKUP($A14,'raw-schema'!$A:$R,17,0) -> WebPage | AD14: =VLOOKUP($A14,'raw-schema'!$A:$R,18,0) -> 0 | AE14: Schema 보강 필요 (Blog)
A15: {=INDEX('raw-sheet'!$A$2:$ZZ$1000, ROW(A14), MATCH(A$1, 'raw-sheet'!$A$1:$ZZ$1, 0))} -> https://innisfree-taiwan.myshopify.com/blogs/event/tagged/active | B15: Pass | C15: {=INDEX('raw-sheet'!$A$2:$ZZ$1000, ROW(C14), MATCH(C$1, 'raw-sheet'!$A$1:$ZZ$1, 0))} -> Blog Page | D15: {=INDEX('raw-sheet'!$A$2:$ZZ$1000, ROW(D14), MATCH(D$1, 'raw-sheet'!$A$1:$ZZ$1, 0))} -> 200 | E15: =IF(D15=200,"Pass","Not") -> Pass | F15: {=INDEX('raw-sheet'!$A$2:$ZZ$1000, ROW(F14), MATCH(F$1, 'raw-sheet'!$A$1:$ZZ$1, 0))} -> 活動_x000D_ – tagged "active" | INNISFREE Taiwan | G15: Pass | H15: {=INDEX('raw-sheet'!$A$2:$ZZ$1000, ROW(H14), MATCH(H$1, 'raw-sheet'!$A$1:$ZZ$1, 0))} -> 0 | I15: missing | J15: {=INDEX('raw-sheet'!$A$2:$ZZ$1000, ROW(J14), MATCH(J$1, 'raw-sheet'!$A$1:$ZZ$1, 0))} -> 活動 | K15: {=INDEX('raw-sheet'!$A$2:$ZZ$1000, ROW(K14), MATCH(K$1, 'raw-sheet'!$A$1:$ZZ$1, 0))} -> 1 | L15: duplicate | M15: {=INDEX('raw-sheet'!$A$2:$ZZ$1000, ROW(M14), MATCH(M$1, 'raw-sheet'!$A$1:$ZZ$1, 0))} -> https://innisfree-taiwan.myshopify.com/blogs/event/tagged/active | N15: =IF(A15=M15,"Pass","Not") -> Pass | O15: {=INDEX('raw-sheet'!$A$2:$ZZ$1000, ROW(O14), MATCH(O$1, 'raw-sheet'!$A$1:$ZZ$1, 0))} -> 活動 | INNISFREE Taiwan | P15: {=INDEX('raw-sheet'!$A$2:$ZZ$1000, ROW(P14), MATCH(P$1, 'raw-sheet'!$A$1:$ZZ$1, 0))} -> innisfree 來自韓國濟州島的No.1自然主義美妝保養品牌，不僅將濟州島清新潔淨的空氣、溫暖和煦的陽光、純淨天然的水源、肥沃健康的土壤、自然純粹的植物養分注入保養品，更為消費者打造健康與美麗。| innisfree Taiwan | Q15: {=INDEX('raw-sheet'!$A$2:$ZZ$1000, ROW(Q14), MATCH(Q$1, 'raw-sheet'!$A$1:$ZZ$1, 0))} -> website | R15: {=INDEX('raw-sheet'!$A$2:$ZZ$1000, ROW(R14), MATCH(R$1, 'raw-sheet'!$A$1:$ZZ$1, 0))} -> INNISFREE Taiwan | S15: {=INDEX('raw-sheet'!$A$2:$ZZ$1000, ROW(S14), MATCH(S$1, 'raw-sheet'!$A$1:$ZZ$1, 0))} -> http://innisfree-taiwan.myshopify.com/cdn/shop/files/logo.png?v=1767594135 | T15: {=INDEX('raw-sheet'!$A$2:$ZZ$1000, ROW(T14), MATCH(T$1, 'raw-sheet'!$A$1:$ZZ$1, 0))} -> https://innisfree-taiwan.myshopify.com/cdn/shop/files/logo.png?v=1767594135 | U15: {=INDEX('raw-sheet'!$A$2:$ZZ$1000, ROW(U14), MATCH(U$1, 'raw-sheet'!$A$1:$ZZ$1, 0))} -> https://innisfree-taiwan.myshopify.com/blogs/event/tagged/active | V15: {=INDEX('raw-sheet'!$A$2:$ZZ$1000, ROW(V14), MATCH(V$1, 'raw-sheet'!$A$1:$ZZ$1, 0))} -> 活動 | INNISFREE Taiwan | ... X15: {=INDEX('raw-sheet'!$A$2:$ZZ$1000, ROW(X14), MATCH(X$1, 'raw-sheet'!$A$1:$ZZ$1, 0))} -> summary_large_image | Y15: duplicate title duplicate desc. | Z15: =VLOOKUP($A15,'raw-schema'!$A:$R,14,0) -> Organization | AA15: =VLOOKUP($A15,'raw-schema'!$A:$R,15,0) -> 0 | AB15: =VLOOKUP($A15,'raw-schema'!$A:$R,16,0) -> 0 | AC15: =VLOOKUP($A15,'raw-schema'!$A:$R,17,0) -> 0 | AD15: =VLOOKUP($A15,'raw-schema'!$A:$R,18,0) -> 0 | AE15: Schema 보강 필요 (Blog)
A16: {=INDEX('raw-sheet'!$A$2:$ZZ$1000, ROW(A15), MATCH(A$1, 'raw-sheet'!$A$1:$ZZ$1, 0))} -> https://innisfree-taiwan.myshopify.com/blogs/event/tagged/inactive | B16: Pass | C16: {=INDEX('raw-sheet'!$A$2:$ZZ$1000, ROW(C15), MATCH(C$1, 'raw-sheet'!$A$1:$ZZ$1, 0))} -> Blog Page | D16: {=INDEX('raw-sheet'!$A$2:$ZZ$1000, ROW(D15), MATCH(D$1, 'raw-sheet'!$A$1:$ZZ$1, 0))} -> 200 | E16: =IF(D16=200,"Pass","Not") -> Pass | F16: {=INDEX('raw-sheet'!$A$2:$ZZ$1000, ROW(F15), MATCH(F$1, 'raw-sheet'!$A$1:$ZZ$1, 0))} -> 活動_x000D_ – tagged "inactive" | INNISFREE Taiwan | G16: duplicate | H16: {=INDEX('raw-sheet'!$A$2:$ZZ$1000, ROW(H15), MATCH(H$1, 'raw-sheet'!$A$1:$ZZ$1, 0))} -> 0 | I16: missing | J16: {=INDEX('raw-sheet'!$A$2:$ZZ$1000, ROW(J15), MATCH(J$1, 'raw-sheet'!$A$1:$ZZ$1, 0))} -> 活動 | K16: {=INDEX('raw-sheet'!$A$2:$ZZ$1000, ROW(K15), MATCH(K$1, 'raw-sheet'!$A$1:$ZZ$1, 0))} -> 1 | L16: duplicate | M16: {=INDEX('raw-sheet'!$A$2:$ZZ$1000, ROW(M15), MATCH(M$1, 'raw-sheet'!$A$1:$ZZ$1, 0))} -> https://innisfree-taiwan.myshopify.com/blogs/event/tagged/inactive | N16: =IF(A16=M16,"Pass","Not") -> Pass | O16: {=INDEX('raw-sheet'!$A$2:$ZZ$1000, ROW(O15), MATCH(O$1, 'raw-sheet'!$A$1:$ZZ$1, 0))} -> 活動 | INNISFREE Taiwan | P16: {=INDEX('raw-sheet'!$A$2:$ZZ$1000, ROW(P15), MATCH(P$1, 'raw-sheet'!$A$1:$ZZ$1, 0))} -> innisfree 來自韓國濟州島的No.1自然主義美妝保養品牌，不僅將濟州島清新潔淨的空氣、溫暖和煦的陽光、純淨天然的水源、肥沃健康的土壤、自然純粹的植物養分注入保養品，更為消費者打造健康與美麗。| innisfree Taiwan | Q16: {=INDEX('raw-sheet'!$A$2:$ZZ$1000, ROW(Q15), MATCH(Q$1, 'raw-sheet'!$A$1:$ZZ$1, 0))} -> website | R16: {=INDEX('raw-sheet'!$A$2:$ZZ$1000, ROW(R15), MATCH(R$1, 'raw-sheet'!$A$1:$ZZ$1, 0))} -> INNISFREE Taiwan | S16: {=INDEX('raw-sheet'!$A$2:$ZZ$1000, ROW(S15), MATCH(S$1, 'raw-sheet'!$A$1:$ZZ$1, 0))} -> http://innisfree-taiwan.myshopify.com/cdn/shop/files/logo.png?v=1767594135 | T16: {=INDEX('raw-sheet'!$A$2:$ZZ$1000, ROW(T15), MATCH(T$1, 'raw-sheet'!$A$1:$ZZ$1, 0))} -> https://innisfree-taiwan.myshopify.com/cdn/shop/files/logo.png?v=1767594135 | U16: {=INDEX('raw-sheet'!$A$2:$ZZ$1000, ROW(U15), MATCH(U$1, 'raw-sheet'!$A$1:$ZZ$1, 0))} -> https://innisfree-taiwan.myshopify.com/blogs/event/tagged/inactive | V16: {=INDEX('raw-sheet'!$A$2:$ZZ$1000, ROW(V15), MATCH(V$1, 'raw-sheet'!$A$1:$ZZ$1, 0))} -> 活動 | INNISFREE Taiwan | ... X16: {=INDEX('raw-sheet'!$A$2:$ZZ$1000, ROW(X15), MATCH(X$1, 'raw-sheet'!$A$1:$ZZ$1, 0))} -> summary_large_image | Y16: duplicate title duplicate desc. | Z16: =VLOOKUP($A16,'raw-schema'!$A:$R,14,0) -> Organization | AA16: =VLOOKUP($A16,'raw-schema'!$A:$R,15,0) -> 0 | AB16: =VLOOKUP($A16,'raw-schema'!$A:$R,16,0) -> 0 | AC16: =VLOOKUP($A16,'raw-schema'!$A:$R,17,0) -> 0 | AD16: =VLOOKUP($A16,'raw-schema'!$A:$R,18,0) -> 0 | AE16: Schema 보강 필요 (Blog)
A17: {=INDEX('raw-sheet'!$A$2:$ZZ$1000, ROW(A16), MATCH(A$1, 'raw-sheet'!$A$1:$ZZ$1, 0))} -> https://innisfree-taiwan.myshopify.com/blogs/event/tagged/inactive?page=1 | B17: Pass | C17: {=INDEX('raw-sheet'!$A$2:$ZZ$1000, ROW(C16), MATCH(C$1, 'raw-sheet'!$A$1:$ZZ$1, 0))} -> Blog Page | D17: {=INDEX('raw-sheet'!$A$2:$ZZ$1000, ROW(D16), MATCH(D$1, 'raw-sheet'!$A$1:$ZZ$1, 0))} -> 200 | E17: =IF(D17=200,"Pass","Not") -> Pass | F17: {=INDEX('raw-sheet'!$A$2:$ZZ$1000, ROW(F16), MATCH(F$1, 'raw-sheet'!$A$1:$ZZ$1, 0))} -> 活動_x000D_ – tagged "inactive" | INNISFREE Taiwan | G17: Pass | H17: {=INDEX('raw-sheet'!$A$2:$ZZ$1000, ROW(H16), MATCH(H$1, 'raw-sheet'!$A$1:$ZZ$1, 0))} -> 0 | I17: missing | J17: {=INDEX('raw-sheet'!$A$2:$ZZ$1000, ROW(J16), MATCH(J$1, 'raw-sheet'!$A$1:$ZZ$1, 0))} -> 活動 | K17: {=INDEX('raw-sheet'!$A$2:$ZZ$1000, ROW(K16), MATCH(K$1, 'raw-sheet'!$A$1:$ZZ$1, 0))} -> 1 | L17: duplicate | M17: {=INDEX('raw-sheet'!$A$2:$ZZ$1000, ROW(M16), MATCH(M$1, 'raw-sheet'!$A$1:$ZZ$1, 0))} -> https://innisfree-taiwan.myshopify.com/blogs/event/tagged/inactive | N17: =IF(A17=M17,"Pass","Not") -> Not | O17: {=INDEX('raw-sheet'!$A$2:$ZZ$1000, ROW(O16), MATCH(O$1, 'raw-sheet'!$A$1:$ZZ$1, 0))} -> 活動 | INNISFREE Taiwan | P17: {=INDEX('raw-sheet'!$A$2:$ZZ$1000, ROW(P16), MATCH(P$1, 'raw-sheet'!$A$1:$ZZ$1, 0))} -> innisfree 來自韓國濟州島的No.1自然主義美妝保養品牌，不僅將濟州島清新潔淨的空氣、溫暖和煦的陽光、純淨天然的水源、肥沃健康的土壤、自然純粹的植物養分注入保養品，更為消費者打造健康與美麗。| innisfree Taiwan | Q17: {=INDEX('raw-sheet'!$A$2:$ZZ$1000, ROW(Q16), MATCH(Q$1, 'raw-sheet'!$A$1:$ZZ$1, 0))} -> website | R17: {=INDEX('raw-sheet'!$A$2:$ZZ$1000, ROW(R16), MATCH(R$1, 'raw-sheet'!$A$1:$ZZ$1, 0))} -> INNISFREE Taiwan | S17: {=INDEX('raw-sheet'!$A$2:$ZZ$1000, ROW(S16), MATCH(S$1, 'raw-sheet'!$A$1:$ZZ$1, 0))} -> http://innisfree-taiwan.myshopify.com/cdn/shop/files/logo.png?v=1767594135 | T17: {=INDEX('raw-sheet'!$A$2:$ZZ$1000, ROW(T16), MATCH(T$1, 'raw-sheet'!$A$1:$ZZ$1, 0))} -> https://innisfree-taiwan.myshopify.com/cdn/shop/files/logo.png?v=1767594135 | U17: {=INDEX('raw-sheet'!$A$2:$ZZ$1000, ROW(U16), MATCH(U$1, 'raw-sheet'!$A$1:$ZZ$1, 0))} -> https://innisfree-taiwan.myshopify.com/blogs/event/tagged/inactive | V17: {=INDEX('raw-sheet'!$A$2:$ZZ$1000, ROW(V16), MATCH(V$1, 'raw-sheet'!$A$1:$ZZ$1, 0))} -> 活動 | INNISFREE Taiwan | ... X17: {=INDEX('raw-sheet'!$A$2:$ZZ$1000, ROW(X16), MATCH(X$1, 'raw-sheet'!$A$1:$ZZ$1, 0))} -> summary_large_image | Y17: duplicate title duplicate desc. | Z17: =VLOOKUP($A17,'raw-schema'!$A:$R,14,0) -> Organization | AA17: =VLOOKUP($A17,'raw-schema'!$A:$R,15,0) -> 0 | AB17: =VLOOKUP($A17,'raw-schema'!$A:$R,16,0) -> 0 | AC17: =VLOOKUP($A17,'raw-schema'!$A:$R,17,0) -> 0 | AD17: =VLOOKUP($A17,'raw-schema'!$A:$R,18,0) -> 0 | AE17: Schema 보강 필요 (Blog) | AF17: 예외 적용 (Pagination - Canonical)
A18: {=INDEX('raw-sheet'!$A$2:$ZZ$1000, ROW(A17), MATCH(A$1, 'raw-sheet'!$A$1:$ZZ$1, 0))} -> https://innisfree-taiwan.myshopify.com/blogs/event/tagged/inactive?page=2 | B18: Pass | C18: {=INDEX('raw-sheet'!$A$2:$ZZ$1000, ROW(C17), MATCH(C$1, 'raw-sheet'!$A$1:$ZZ$1, 0))} -> Blog Page | D18: {=INDEX('raw-sheet'!$A$2:$ZZ$1000, ROW(D17), MATCH(D$1, 'raw-sheet'!$A$1:$ZZ$1, 0))} -> 200 | E18: =IF(D18=200,"Pass","Not") -> Pass | F18: {=INDEX('raw-sheet'!$A$2:$ZZ$1000, ROW(F17), MATCH(F$1, 'raw-sheet'!$A$1:$ZZ$1, 0))} -> 活動_x000D_ – tagged "inactive" – Page 2 | INNISFREE Taiwan | G18: Pass | H18: {=INDEX('raw-sheet'!$A$2:$ZZ$1000, ROW(H17), MATCH(H$1, 'raw-sheet'!$A$1:$ZZ$1, 0))} -> 0 | I18: missing | J18: {=INDEX('raw-sheet'!$A$2:$ZZ$1000, ROW(J17), MATCH(J$1, 'raw-sheet'!$A$1:$ZZ$1, 0))} -> 活動 | K18: {=INDEX('raw-sheet'!$A$2:$ZZ$1000, ROW(K17), MATCH(K$1, 'raw-sheet'!$A$1:$ZZ$1, 0))} -> 1 | L18: duplicate | M18: {=INDEX('raw-sheet'!$A$2:$ZZ$1000, ROW(M17), MATCH(M$1, 'raw-sheet'!$A$1:$ZZ$1, 0))} -> https://innisfree-taiwan.myshopify.com/blogs/event/tagged/inactive?page=2 | N18: =IF(A18=M18,"Pass","Not") -> Pass | O18: {=INDEX('raw-sheet'!$A$2:$ZZ$1000, ROW(O17), MATCH(O$1, 'raw-sheet'!$A$1:$ZZ$1, 0))} -> 活動 | INNISFREE Taiwan | P18: {=INDEX('raw-sheet'!$A$2:$ZZ$1000, ROW(P17), MATCH(P$1, 'raw-sheet'!$A$1:$ZZ$1, 0))} -> innisfree 來自韓國濟州島的No.1自然主義美妝保養品牌，不僅將濟州島清新潔淨的空氣、溫暖和煦的陽光、純淨天然的水源、肥沃健康的土壤、自然純粹的植物養分注入保養品，更為消費者打造健康與美麗。| innisfree Taiwan | Q18: {=INDEX('raw-sheet'!$A$2:$ZZ$1000, ROW(Q17), MATCH(Q$1, 'raw-sheet'!$A$1:$ZZ$1, 0))} -> website | R18: {=INDEX('raw-sheet'!$A$2:$ZZ$1000, ROW(R17), MATCH(R$1, 'raw-sheet'!$A$1:$ZZ$1, 0))} -> INNISFREE Taiwan | S18: {=INDEX('raw-sheet'!$A$2:$ZZ$1000, ROW(S17), MATCH(S$1, 'raw-sheet'!$A$1:$ZZ$1, 0))} -> http://innisfree-taiwan.myshopify.com/cdn/shop/files/logo.png?v=1767594135 | T18: {=INDEX('raw-sheet'!$A$2:$ZZ$1000, ROW(T17), MATCH(T$1, 'raw-sheet'!$A$1:$ZZ$1, 0))} -> https://innisfree-taiwan.myshopify.com/cdn/shop/files/logo.png?v=1767594135 | U18: {=INDEX('raw-sheet'!$A$2:$ZZ$1000, ROW(U17), MATCH(U$1, 'raw-sheet'!$A$1:$ZZ$1, 0))} -> https://innisfree-taiwan.myshopify.com/blogs/event/tagged/inactive?page=2 | V18: {=INDEX('raw-sheet'!$A$2:$ZZ$1000, ROW(V17), MATCH(V$1, 'raw-sheet'!$A$1:$ZZ$1, 0))} -> 活動 | INNISFREE Taiwan | ... X18: {=INDEX('raw-sheet'!$A$2:$ZZ$1000, ROW(X17), MATCH(X$1, 'raw-sheet'!$A$1:$ZZ$1, 0))} -> summary_large_image | Y18: duplicate title duplicate desc. | Z18: =VLOOKUP($A18,'raw-schema'!$A:$R,14,0) -> Organization | AA18: =VLOOKUP($A18,'raw-schema'!$A:$R,15,0) -> 0 | AB18: =VLOOKUP($A18,'raw-schema'!$A:$R,16,0) -> 0 | AC18: =VLOOKUP($A18,'raw-schema'!$A:$R,17,0) -> 0 | AD18: =VLOOKUP($A18,'raw-schema'!$A:$R,18,0) -> 0 | AE18: Schema 보강 필요 (Blog) | AF18: 예외 적용 (Pagination - Canonical)
A19: {=INDEX('raw-sheet'!$A$2:$ZZ$1000, ROW(A18), MATCH(A$1, 'raw-sheet'!$A$1:$ZZ$1, 0))} -> https://innisfree-taiwan.myshopify.com/blogs/event/tagged/inactive?page=3 | B19: Pass | C19: {=INDEX('raw-sheet'!$A$2:$ZZ$1000, ROW(C18), MATCH(C$1, 'raw-sheet'!$A$1:$ZZ$1, 0))} -> Blog Page | D19: {=INDEX('raw-sheet'!$A$2:$ZZ$1000, ROW(D18), MATCH(D$1, 'raw-sheet'!$A$1:$ZZ$1, 0))} -> 200 | E19: =IF(D19=200,"Pass","Not") -> Pass | F19: {=INDEX('raw-sheet'!$A$2:$ZZ$1000, ROW(F18), MATCH(F$1, 'raw-sheet'!$A$1:$ZZ$1, 0))} -> 活動_x000D_ – tagged "inactive" – Page 3 | INNISFREE Taiwan | G19: Pass | H19: {=INDEX('raw-sheet'!$A$2:$ZZ$1000, ROW(H18), MATCH(H$1, 'raw-sheet'!$A$1:$ZZ$1, 0))} -> 0 | I19: missing | J19: {=INDEX('raw-sheet'!$A$2:$ZZ$1000, ROW(J18), MATCH(J$1, 'raw-sheet'!$A$1:$ZZ$1, 0))} -> 活動 | K19: {=INDEX('raw-sheet'!$A$2:$ZZ$1000, ROW(K18), MATCH(K$1, 'raw-sheet'!$A$1:$ZZ$1, 0))} -> 1 | L19: duplicate | M19: {=INDEX('raw-sheet'!$A$2:$ZZ$1000, ROW(M18), MATCH(M$1, 'raw-sheet'!$A$1:$ZZ$1, 0))} -> https://innisfree-taiwan.myshopify.com/blogs/event/tagged/inactive?page=3 | N19: =IF(A19=M19,"Pass","Not") -> Pass | O19: {=INDEX('raw-sheet'!$A$2:$ZZ$1000, ROW(O18), MATCH(O$1, 'raw-sheet'!$A$1:$ZZ$1, 0))} -> 活動 | INNISFREE Taiwan | P19: {=INDEX('raw-sheet'!$A$2:$ZZ$1000, ROW(P18), MATCH(P$1, 'raw-sheet'!$A$1:$ZZ$1, 0))} -> innisfree 來自韓國濟州島的No.1自然主義美妝保養品牌，不僅將濟州島清新潔淨的空氣、溫暖和煦的陽光、純淨天然的水源、肥沃健康的土壤、自然純粹的植物養分注入保養品，更為消費者打造健康與美麗。| innisfree Taiwan | Q19: {=INDEX('raw-sheet'!$A$2:$ZZ$1000, ROW(Q18), MATCH(Q$1, 'raw-sheet'!$A$1:$ZZ$1, 0))} -> website | R19: {=INDEX('raw-sheet'!$A$2:$ZZ$1000, ROW(R18), MATCH(R$1, 'raw-sheet'!$A$1:$ZZ$1, 0))} -> INNISFREE Taiwan | S19: {=INDEX('raw-sheet'!$A$2:$ZZ$1000, ROW(S18), MATCH(S$1, 'raw-sheet'!$A$1:$ZZ$1, 0))} -> http://innisfree-taiwan.myshopify.com/cdn/shop/files/logo.png?v=1767594135 | T19: {=INDEX('raw-sheet'!$A$2:$ZZ$1000, ROW(T18), MATCH(T$1, 'raw-sheet'!$A$1:$ZZ$1, 0))} -> https://innisfree-taiwan.myshopify.com/cdn/shop/files/logo.png?v=1767594135 | U19: {=INDEX('raw-sheet'!$A$2:$ZZ$1000, ROW(U18), MATCH(U$1, 'raw-sheet'!$A$1:$ZZ$1, 0))} -> https://innisfree-taiwan.myshopify.com/blogs/event/tagged/inactive?page=3 | V19: {=INDEX('raw-sheet'!$A$2:$ZZ$1000, ROW(V18), MATCH(V$1, 'raw-sheet'!$A$1:$ZZ$1, 0))} -> 活動 | INNISFREE Taiwan | ... X19: {=INDEX('raw-sheet'!$A$2:$ZZ$1000, ROW(X18), MATCH(X$1, 'raw-sheet'!$A$1:$ZZ$1, 0))} -> summary_large_image | Y19: duplicate title duplicate desc. | Z19: =VLOOKUP($A19,'raw-schema'!$A:$R,14,0) -> Organization | AA19: =VLOOKUP($A19,'raw-schema'!$A:$R,15,0) -> 0 | AB19: =VLOOKUP($A19,'raw-schema'!$A:$R,16,0) -> 0 | AC19: =VLOOKUP($A19,'raw-schema'!$A:$R,17,0) -> 0 | AD19: =VLOOKUP($A19,'raw-schema'!$A:$R,18,0) -> 0 | AE19: Schema 보강 필요 (Blog) | AF19: 예외 적용 (Pagination - Canonical)
A20: {=INDEX('raw-sheet'!$A$2:$ZZ$1000, ROW(A19), MATCH(A$1, 'raw-sheet'!$A$1:$ZZ$1, 0))} -> https://innisfree-taiwan.myshopify.com/blogs/event/tagged/inactive?page=4 | B20: Pass | C20: {=INDEX('raw-sheet'!$A$2:$ZZ$1000, ROW(C19), MATCH(C$1, 'raw-sheet'!$A$1:$ZZ$1, 0))} -> Blog Page | D20: {=INDEX('raw-sheet'!$A$2:$ZZ$1000, ROW(D19), MATCH(D$1, 'raw-sheet'!$A$1:$ZZ$1, 0))} -> 200 | E20: =IF(D20=200,"Pass","Not") -> Pass | F20: {=INDEX('raw-sheet'!$A$2:$ZZ$1000, ROW(F19), MATCH(F$1, 'raw-sheet'!$A$1:$ZZ$1, 0))} -> 活動_x000D_ – tagged "inactive" – Page 4 | INNISFREE Taiwan | G20: Pass | H20: {=INDEX('raw-sheet'!$A$2:$ZZ$1000, ROW(H19), MATCH(H$1, 'raw-sheet'!$A$1:$ZZ$1, 0))} -> 0 | I20: missing | J20: {=INDEX('raw-sheet'!$A$2:$ZZ$1000, ROW(J19), MATCH(J$1, 'raw-sheet'!$A$1:$ZZ$1, 0))} -> 活動 | K20: {=INDEX('raw-sheet'!$A$2:$ZZ$1000, ROW(K19), MATCH(K$1, 'raw-sheet'!$A$1:$ZZ$1, 0))} -> 1 | L20: duplicate | M20: {=INDEX('raw-sheet'!$A$2:$ZZ$1000, ROW(M19), MATCH(M$1, 'raw-sheet'!$A$1:$ZZ$1, 0))} -> https://innisfree-taiwan.myshopify.com/blogs/event/tagged/inactive?page=4 | N20: =IF(A20=M20,"Pass","Not") -> Pass | O20: {=INDEX('raw-sheet'!$A$2:$ZZ$1000, ROW(O19), MATCH(O$1, 'raw-sheet'!$A$1:$ZZ$1, 0))} -> 活動 | INNISFREE Taiwan | P20: {=INDEX('raw-sheet'!$A$2:$ZZ$1000, ROW(P19), MATCH(P$1, 'raw-sheet'!$A$1:$ZZ$1, 0))} -> innisfree 來自韓國濟州島的No.1自然主義美妝保養品牌，不僅將濟州島清新潔淨的空氣、溫暖和煦的陽光、純淨天然的水源、肥沃健康的土壤、自然純粹的植物養分注入保養品，更為消費者打造健康與美麗。| innisfree Taiwan | Q20: {=INDEX('raw-sheet'!$A$2:$ZZ$1000, ROW(Q19), MATCH(Q$1, 'raw-sheet'!$A$1:$ZZ$1, 0))} -> website | R20: {=INDEX('raw-sheet'!$A$2:$ZZ$1000, ROW(R19), MATCH(R$1, 'raw-sheet'!$A$1:$ZZ$1, 0))} -> INNISFREE Taiwan | S20: {=INDEX('raw-sheet'!$A$2:$ZZ$1000, ROW(S19), MATCH(S$1, 'raw-sheet'!$A$1:$ZZ$1, 0))} -> http://innisfree-taiwan.myshopify.com/cdn/shop/files/logo.png?v=1767594135 | T20: {=INDEX('raw-sheet'!$A$2:$ZZ$1000, ROW(T19), MATCH(T$1, 'raw-sheet'!$A$1:$ZZ$1, 0))} -> https://innisfree-taiwan.myshopify.com/cdn/shop/files/logo.png?v=1767594135 | U20: {=INDEX('raw-sheet'!$A$2:$ZZ$1000, ROW(U19), MATCH(U$1, 'raw-sheet'!$A$1:$ZZ$1, 0))} -> https://innisfree-taiwan.myshopify.com/blogs/event/tagged/inactive?page=4 | V20: {=INDEX('raw-sheet'!$A$2:$ZZ$1000, ROW(V19), MATCH(V$1, 'raw-sheet'!$A$1:$ZZ$1, 0))} -> 活動 | INNISFREE Taiwan | ... X20: {=INDEX('raw-sheet'!$A$2:$ZZ$1000, ROW(X19), MATCH(X$1, 'raw-sheet'!$A$1:$ZZ$1, 0))} -> summary_large_image | Y20: duplicate title duplicate desc. | Z20: =VLOOKUP($A20,'raw-schema'!$A:$R,14,0) -> Organization | AA20: =VLOOKUP($A20,'raw-schema'!$A:$R,15,0) -> 0 | AB20: =VLOOKUP($A20,'raw-schema'!$A:$R,16,0) -> 0 | AC20: =VLOOKUP($A20,'raw-schema'!$A:$R,17,0) -> 0 | AD20: =VLOOKUP($A20,'raw-schema'!$A:$R,18,0) -> 0 | AE20: Schema 보강 필요 (Blog) | AF20: 예외 적용 (Pagination - Canonical)
