Workbook

Sheet Summary
B2: 설화수 JP QA Result
C3: 1차 | D3: 2차
B4: QA Date | C4: 2026.04.16 | D4: 2026.04.24
B5: Overall Pass Rate | C5: 0.67 | D5: =1-AVERAGE(D9:D15) -> 0.75824176
B8: QA Elements | C8: Total | D8: Error Rate | E8: Pass | F8: Issue | G8: 비고 | H8: To-Be
B9: Status/Indexability | C9: =COUNTA(TOBE!A:A)-1 -> 26 | D9: =IFERROR(F9/C9,0) -> 0.19230769 | E9: =COUNTIF(TOBE!F:F,"Pass") -> 16 | F9: =COUNTIF(TOBE!F:F,"Fail") -> 5 | G9: NoIndex 처리 필요 | H9: TOBE 참고
B10: Title | C10: =COUNTA(TOBE!A:A)-1 -> 26 | D10: =IFERROR(F10/C10,0) -> 0 | E10: =COUNTIF(TOBE!H:H,"Pass") -> 16 | F10: =COUNTIF(TOBE!H:H,"Fail") -> 0 | G10: 브랜드명 수정 필요 | H10: N/A
B11: Meta Description | C11: =COUNTA(TOBE!A:A)-1 -> 26 | D11: =IFERROR(F11/C11,0) -> 0.26923077 | E11: =COUNTIF(TOBE!K:K,"Pass") -> 9 | F11: =COUNTIF(TOBE!K:K,"Fail") -> 7 | G11: 일부 권장 길이 미달/중복 | H11: TOBE 참고
B12: H1 | C12: =COUNTA(TOBE!A:A)-1 -> 26 | D12: =IFERROR(F12/C12,0) -> 0.038461538 | E12: =COUNTIF(TOBE!O:O,"Pass") -> 15 | F12: =COUNTIF(TOBE!O:O,"Fail") -> 1 | G12: H1 태그 중복 | H12: TOBE 참고
B13: Canonical | C13: =COUNTA(TOBE!A:A)-1 -> 26 | D13: =IFERROR(F13/C13,0) -> 0 | E13: =COUNTIF(TOBE!Q:Q,"Pass") -> 16 | F13: =COUNTIF(TOBE!Q:Q,"Fail") -> 0 | G13: N/A | H13: N/A
B14: Social Tag | C14: =COUNTA(TOBE!A:A)-1 -> 26 | D14: =IFERROR(F14/C14,0) -> 0.61538462 | E14: =COUNTIF(TOBE!AB:AB,"Pass") -> 0 | F14: =COUNTIF(TOBE!AB:AB,"Fail") -> 16 | G14: 일부 권장 길이 미달/중복/누락 | H14: TOBE 참고
B15: Schema | C15: =COUNTA(TOBE!A:A)-1 -> 26 | D15: =IFERROR(F15/C15,0) -> 0.57692308 | E15: =COUNTIF(TOBE!AI:AI,"Pass") -> 1 | F15: =COUNTIF(TOBE!AI:AI,"Fail") -> 15 | G15: 알맞지 않은 스키마 적용 (추후 작업 필요) | H15: TOBE 참고
B16: URL | C16: =COUNTA(TOBE!A:A)-1 -> 26 | D16: =IFERROR(F16/C16,0) -> 0 | E16: =COUNTIF(TOBE!C:C,"Pass") -> 16 | F16: =COUNTIF(TOBE!C:C,"Fail") -> 0 | G16: N/A | H16: N/A

Sheet TOBE
A1: Address | B1: 비고 | C1: Address QA | D1: Indexability | E1: Status Code | F1: Status/Indexability QA | G1: Title 1 | H1: Title QA | I1: Title to-be | J1: Meta Description 1 | K1: Meta Description QA | L1: Meta Description to-be | M1: H1-1 | N1: H1-2 | O1: H1 QA | P1: Canonical Link Element 1 | Q1: Canonical QA | R1: OG Title 1 | S1: OG Description 1 | T1: OG Type 1 | U1: OG Site Name 1 | V1: OG image 1 | W1: OG url 1 | X1: Twitter Card 1 | Y1: Twitter Title 1 | Z1: Twitter Site 1 | AA1: Twitter URL 1 | AB1: Social Tag QA | AC1: Type-1 | AD1: Updated | AE1: Type-2 | AF1: Type-3 | AG1: Type-4 | AH1: Type-5 | AI1: Schema QA
A2: https://sulwhasoo-jp.myshopify.com/pages/store-locator | C2: N/A | D2: Non-Indexable | E2: 404 | F2: N/A | G2: Store Locator | Sulwhasoo Japan | H2: N/A | J2: Store Locator is loading from Storemapper plugin... | K2: N/A | L2: This is the Sulwhasoo store locator page. Check the locations and information of nearby stores. | O2: N/A | P2: https://sulwhasoo-jp.myshopify.com/pages/store-locator | Q2: N/A | R2: Store Locator | Sulwhasoo Japan | S2: Meta Description to-be 내용 넣기 | T2: website | U2: Sulwhasoo Japan | V2: 설화수 로고 및 대표 이미지 넣기 - KR참고 | W2: https://sulwhasoo-jp.myshopify.com/pages/store-locator | X2: summary_large_image | Y2: Store Locator | Sulwhasoo Japan | AA2: url 채우기 | AB2: N/A | AC2: Organization | AI2: N/A
A3: https://sulwhasoo-jp.myshopify.com/pages/site-map | C3: Pass | D3: Indexable | E3: 200 | F3: Pass | G3: Site Map | Sulwhasoo Japan | H3: Pass | K3: Pass | L3: Sulwhasoo Sitemap. You can view the entire menu and key content of the Sulwhasoo website at a glance. | M3: Site Map | O3: Pass | P3: https://sulwhasoo-jp.myshopify.com/pages/site-map | Q3: Pass | R3: Site Map | Sulwhasoo Japan | S3: Sulwhasoo Sitemap. You can view the entire menu and key content of the Sulwhasoo website at a glance. | T3: website | U3: Sulwhasoo Japan | V3: http://sulwhasoo-jp.myshopify.com/cdn/shop/articles/Sulwhasoo_JP.webp?v=1776042225 | W3: https://sulwhasoo-jp.myshopify.com/pages/site-map | X3: summary_large_image | Y3: Site Map | Sulwhasoo Japan | AA3: url 채우기 | AB3: Fail | AC3: Organization | AI3: Fail
A4: https://sulwhasoo-jp.myshopify.com/pages/shopping-guide | C4: Pass | D4: Indexable | E4: 200 | F4: Pass | G4: Shopping Guide | Sulwhasoo Japan | H4: Pass | K4: Fail | L4: Shop Sulwhasoo Japan with ease. Free shipping on orders over ¥6,000. We support PayPay, Rakuten Pay & credit cards. See our guide for ordering & delivery info. | M4: ご注文について | O4: Pass | P4: https://sulwhasoo-jp.myshopify.com/pages/shopping-guide | Q4: Pass | R4: Shopping Guide | Sulwhasoo Japan | S4: Meta Description to-be 내용 넣기 | T4: website | U4: Sulwhasoo Japan | V4: http://sulwhasoo-jp.myshopify.com/cdn/shop/articles/Sulwhasoo_JP.webp?v=1776042225 | W4: https://sulwhasoo-jp.myshopify.com/pages/shopping-guide | X4: summary_large_image | Y4: Shopping Guide | Sulwhasoo Japan | AA4: url 채우기 | AB4: Fail | AC4: Organization | AI4: Fail
A5: https://sulwhasoo-jp.myshopify.com/pages/shop-info | C5: N/A | D5: Non-Indexable | E5: 404 | F5: N/A | G5: Shop Info | Sulwhasoo Japan | H5: N/A | K5: N/A | L5: Discover the heritage of Sulwhasoo Japan. View official store information, brand philosophy, and legal notices for our online and offline presence. | M5: Shop Info | O5: N/A | P5: https://sulwhasoo-jp.myshopify.com/pages/shop-info | Q5: N/A | R5: Shop Info | Sulwhasoo Japan | S5: Meta Description to-be 내용 넣기 | T5: website | U5: Sulwhasoo Japan | V5: 설화수 로고 및 대표 이미지 넣기 - KR참고 | W5: https://sulwhasoo-jp.myshopify.com/pages/shop-info | X5: summary_large_image | Y5: Shop Info | Sulwhasoo Japan | AA5: url 채우기 | AB5: N/A | AC5: Organization | AI5: N/A
A6: https://sulwhasoo-jp.myshopify.com/pages/point-list | C6: N/A | D6: Indexable | E6: 200 | F6: Fail | G6: Point List | Sulwhasoo Japan | H6: N/A | K6: N/A | M6: ポイント情報 | O6: N/A | P6: https://sulwhasoo-jp.myshopify.com/pages/point-list | Q6: N/A | R6: Point List | Sulwhasoo Japan | S6: Sulwhasoo Japan | T6: website | U6: Sulwhasoo Japan | W6: https://sulwhasoo-jp.myshopify.com/pages/point-list | X6: summary_large_image | Y6: Point List | Sulwhasoo Japan | AB6: N/A | AC6: Organization | AI6: N/A
A7: https://sulwhasoo-jp.myshopify.com/pages/order-list | C7: N/A | D7: Indexable | E7: 200 | F7: Fail | G7: Order List | Sulwhasoo Japan | H7: N/A | K7: N/A | M7: ご注文管理 | O7: N/A | P7: https://sulwhasoo-jp.myshopify.com/pages/order-list | Q7: N/A | R7: Order List | Sulwhasoo Japan | S7: Sulwhasoo Japan | T7: website | U7: Sulwhasoo Japan | W7: https://sulwhasoo-jp.myshopify.com/pages/order-list | X7: summary_large_image | Y7: Order List | Sulwhasoo Japan | AB7: N/A | AC7: Organization | AI7: N/A
A8: https://sulwhasoo-jp.myshopify.com/pages/mypage | C8: N/A | D8: Indexable | E8: 200 | F8: Fail | G8: mypage | Sulwhasoo Japan | H8: N/A | K8: N/A | M8: マイページ | O8: N/A | P8: https://sulwhasoo-jp.myshopify.com/pages/mypage | Q8: N/A | R8: mypage | Sulwhasoo Japan | S8: Sulwhasoo Japan | T8: website | U8: Sulwhasoo Japan | W8: https://sulwhasoo-jp.myshopify.com/pages/mypage | X8: summary_large_image | Y8: mypage | Sulwhasoo Japan | AB8: N/A | AC8: Organization | AI8: N/A
A9: https://sulwhasoo-jp.myshopify.com/pages/my-address | C9: N/A | D9: Indexable | E9: 200 | F9: Fail | G9: my-address | Sulwhasoo Japan | H9: N/A | K9: N/A | M9: My Page | O9: N/A | P9: https://sulwhasoo-jp.myshopify.com/pages/my-address | Q9: N/A | R9: my-address | Sulwhasoo Japan | S9: Sulwhasoo Japan | T9: website | U9: Sulwhasoo Japan | W9: https://sulwhasoo-jp.myshopify.com/pages/my-address | X9: summary_large_image | Y9: my-address | Sulwhasoo Japan | AB9: N/A | AC9: Organization | AI9: N/A
A10: https://sulwhasoo-jp.myshopify.com/pages/membership | C10: Pass | D10: Indexable | E10: 200 | F10: Pass | G10: Membership | Sulwhasoo Japan | H10: Pass | K10: Fail | L10: Bergabung dengan keanggotaan Sulwhasoo dan dapatkan beragam keistimewaan. | M10: メンバーシップ | O10: Pass | P10: https://sulwhasoo-jp.myshopify.com/pages/membership | Q10: Pass | R10: Membership | Sulwhasoo Japan | S10: Meta Description to-be 내용 넣기 | T10: website | U10: Sulwhasoo Japan | V10: http://sulwhasoo-jp.myshopify.com/cdn/shop/articles/Sulwhasoo_JP.webp?v=1776042225 | W10: https://sulwhasoo-jp.myshopify.com/pages/membership | X10: summary_large_image | Y10: Membership | Sulwhasoo Japan | AA10: url 채우기 | AB10: Fail | AC10: Organization | AI10: Fail
A11: https://sulwhasoo-jp.myshopify.com/pages/legal-notice | C11: N/A | D11: Non-Indexable | E11: 404 | F11: N/A | G11: 特定商取引法に基づく表記 | Sulwhasoo Japan | H11: N/A | J11: 事業者名 アモーレパシフィックジャパン株式会社 所在地 〒150-0012 東京都渋谷区広尾１－１３－７ 恵比寿イーストビル2階 代表者 代表 松井 理奈 お問い合わせ Sulwhasoo カスタマーサポート TEL：0120-929-744 受付時間： 月~金 10:00 ~ 18:00＜祝祭日、年末年始・夏期休暇を除く＞ フォームでのお問い合わせはこちら URL https://jp.sulwhasoo.com/ 販売価格 各商品詳細ページに表示された価格に基づきます。表示価格は本体価格に消費税額を加えた「お支払い総額（税込価格）」となっております。 商品代金以外の必要料金 ■送料：通常配送料金は、550円（税込）※沖縄、北海 | K11: N/A | O11: N/A | P11: https://sulwhasoo-jp.myshopify.com/pages/legal-notice | Q11: N/A | R11: 特定商取引法に基づく表記 | Sulwhasoo Japan | S11: 事業者名 アモーレパシフィックジャパン株式会社 所在地 〒150-0012 東京都渋谷区広尾１－１３－７ 恵比寿イーストビル2階 代表者 代表 松井 理奈 お問い合わせ Sulwhasoo カスタマーサポート TEL：0120-929-744 受付時間： 月~金 10:00 ~ 18:00＜祝祭日、年末年始・夏期休暇を除く＞ フォームでのお問い合わせはこちら URL https://jp.sulwhasoo.com/ 販売価格 各商品詳細ページに表示された価格に基づきます。表示価格は本体価格に消費税額を加えた「お支払い総額（税込価格）」となっております。 商品代金以外の必要料金 ■送料：通常配送料金は、550円（税込）※沖縄、北海 | T11: website | U11: Sulwhasoo Japan | V11: 설화수 로고 및 대표 이미지 넣기 - KR참고 | W11: https://sulwhasoo-jp.myshopify.com/pages/legal-notice | X11: summary_large_image | Y11: 特定商取引法に基づく表記 | Sulwhasoo Japan | AA11: url 채우기 | AB11: N/A | AC11: Organization | AI11: N/A
A12: https://sulwhasoo-jp.myshopify.com/pages/faq | C12: Pass | D12: Indexable | E12: 200 | F12: Pass | G12: FAQ | Sulwhasoo Japan | H12: Pass | K12: Fail | L12: Sulwhasoo FAQ. Find quick answers to your questions about order status, payment methods, shipping tracking, and product inquiries in one place. | M12: よくあるご質問 | O12: Pass | P12: https://sulwhasoo-jp.myshopify.com/pages/faq | Q12: Pass | R12: FAQ | Sulwhasoo Japan | S12: Meta Description to-be 내용 넣기 | T12: website | U12: Sulwhasoo Japan | V12: http://sulwhasoo-jp.myshopify.com/cdn/shop/articles/Sulwhasoo_JP.webp?v=1776042225 | W12: https://sulwhasoo-jp.myshopify.com/pages/faq | X12: summary_large_image | Y12: FAQ | Sulwhasoo Japan | AA12: url 채우기 | AB12: Fail | AC12: Organization | AI12: Fail
A13: https://sulwhasoo-jp.myshopify.com/pages/exchange-return | C13: Pass | D13: Indexable | E13: 200 | F13: Pass | G13: Exchange Return | Sulwhasoo Japan | H13: Pass | K13: Fail | L13: Sulwhasoo Exchange & Return. Guide for returning damaged or incorrect items. Contact our support team to request an exchange or refund under our policy. | M13: 交換・返品について | O13: Pass | P13: https://sulwhasoo-jp.myshopify.com/pages/exchange-return | Q13: Pass | R13: Exchange Return | Sulwhasoo Japan | S13: Meta Description to-be 내용 넣기 | T13: website | U13: Sulwhasoo Japan | V13: http://sulwhasoo-jp.myshopify.com/cdn/shop/articles/Sulwhasoo_JP.webp?v=1776042225 | W13: https://sulwhasoo-jp.myshopify.com/pages/exchange-return | X13: summary_large_image | Y13: Exchange Return | Sulwhasoo Japan | AA13: url 채우기 | AB13: Fail | AC13: Organization | AI13: Fail
A14: https://sulwhasoo-jp.myshopify.com/pages/edit-account | C14: N/A | D14: Indexable | E14: 200 | F14: Fail | G14: Edit Account | Sulwhasoo Japan | H14: N/A | K14: N/A | M14: 個人情報の修正 | O14: N/A | P14: https://sulwhasoo-jp.myshopify.com/pages/edit-account | Q14: N/A | R14: Edit Account | Sulwhasoo Japan | S14: Sulwhasoo Japan | T14: website | U14: Sulwhasoo Japan | W14: https://sulwhasoo-jp.myshopify.com/pages/edit-account | X14: summary_large_image | Y14: Edit Account | Sulwhasoo Japan | AB14: N/A | AC14: Organization | AI14: N/A
A15: https://sulwhasoo-jp.myshopify.com/pages/contact | C15: Pass | D15: Indexable | E15: 200 | F15: Pass | G15: Contact | Sulwhasoo Japan | H15: Pass | K15: Fail | L15: Contact Sulwhasoo for inquiries on products, orders, or shipping. Please fill out the form below for assistance. | M15: お問い合わせ | O15: Pass | P15: https://sulwhasoo-jp.myshopify.com/pages/contact | Q15: Pass | R15: Contact | Sulwhasoo Japan | S15: Meta Description to-be 내용 넣기 | T15: website | U15: Sulwhasoo Japan | V15: http://sulwhasoo-jp.myshopify.com/cdn/shop/articles/Sulwhasoo_JP.webp?v=1776042225 | W15: https://sulwhasoo-jp.myshopify.com/pages/contact | X15: summary_large_image | Y15: Contact | Sulwhasoo Japan | AA15: url 채우기 | AB15: Fail | AC15: Organization | AI15: Fail
A16: https://sulwhasoo-jp.myshopify.com/pages/brand-sustainability | C16: Pass | D16: Indexable | E16: 200 | F16: Pass | G16: Brand Sustainability – Earth & Culture | Sulwhasoo Japan | H16: Pass | J16: Sulwhasoo’s sustainable beauty is built on Ginseng Science, Environmental Care, and Cultural Heritage to shape a better future. | K16: Pass | M16: Brand Sustainability | Sulwhasoo Japan | N16: 持続可能な未来のための約束 | O16: Fail | P16: https://sulwhasoo-jp.myshopify.com/pages/brand-sustainability | Q16: Pass | R16: Brand Sustainability – Earth & Culture | Sulwhasoo Japan | S16: Sulwhasoo’s sustainable beauty is built on Ginseng Science, Environmental Care, and Cultural Heritage to shape a better future. | T16: website | U16: Sulwhasoo Japan | V16: http://sulwhasoo-jp.myshopify.com/cdn/shop/articles/Sulwhasoo_JP.webp?v=1776042225 | W16: https://sulwhasoo-jp.myshopify.com/pages/brand-sustainability | X16: summary_large_image | Y16: Brand Sustainability – Earth & Culture | Sulwhasoo Japan | AA16: url 채우기 | AB16: Fail | AC16: Organization | AI16: Fail
A17: https://sulwhasoo-jp.myshopify.com/pages/brand-story | C17: Pass | D17: Indexable | E17: 200 | F17: Pass | G17: Brand Story | Sulwhasoo Japan | H17: Pass | J17: Sulwhasoo fuses Korean tradition with cutting-edge science, using JAUM Activator® and ginseng research for youthful, radiant skin | K17: Pass | M17: Brand Story | Sulwhasoo Japan | N17: 時の流れにゆるがない美しさへの旅 | O17: Pass | P17: https://sulwhasoo-jp.myshopify.com/pages/brand-story | Q17: Pass | R17: Brand Story | Sulwhasoo Japan | S17: Sulwhasoo fuses Korean tradition with cutting-edge science, using JAUM Activator® and ginseng research for youthful, radiant skin | T17: website | U17: Sulwhasoo Japan | V17: http://sulwhasoo-jp.myshopify.com/cdn/shop/articles/Sulwhasoo_JP.webp?v=1776042225 | W17: https://sulwhasoo-jp.myshopify.com/pages/brand-story | X17: summary_large_image | Y17: Brand Story | Sulwhasoo Japan | AA17: url 채우기 | AB17: Fail | AC17: Organization | AI17: Fail
A18: https://sulwhasoo-jp.myshopify.com/pages/activate-account-form | C18: N/A | D18: Non-Indexable | E18: 404 | F18: N/A | G18: Activate Account Form | Sulwhasoo Japan | H18: N/A | K18: N/A | O18: N/A | P18: https://sulwhasoo-jp.myshopify.com/pages/activate-account-form | Q18: N/A | R18: Activate Account Form | Sulwhasoo Japan | S18: Sulwhasoo Japan | T18: website | U18: Sulwhasoo Japan | W18: https://sulwhasoo-jp.myshopify.com/pages/activate-account-form | X18: summary_large_image | Y18: Activate Account Form | Sulwhasoo Japan | AB18: N/A | AC18: Organization | AI18: N/A
A19: https://sulwhasoo-jp.myshopify.com/blogs/sulwhasoo-post/journey-to-holistic-beauty-時の流れに揺るがない美しさへの旅 | C19: Pass | D19: Indexable | E19: 200 | F19: Pass | G19: 「Journey to Holistic Beauty」時の流れに揺るがない美しさへの旅 | Sulwhasoo Japan | H19: Pass | J19: 時を超えて愛される韓国発ラグジュアリービューティーブランド、Sulwhasoo（雪花秀／ソルファス）。その世界観と高麗人参サイエンスを体験できる「Sulwhasoo Lounge（ソルファスラウンジ）」が、5月6日（水）より@cosme TOKYOにて1週間限定オープン。 アモーレパシフィックジャパン株式会社（所在地：東京都渋谷区 代表：羅政均）が展開する、韓国発ラグジュアリービューティーブランド『Sulwhasoo（雪花秀/ソルファス）』は、5月6日（水）から12日（火）までの1週間、@cosme TOKYO ポップアップストア1階にて「Sulwhasoo Lounge（ソルファスラウンジ）」を開催します。 長年にわたり韓国ビュー | K19: Pass | O19: Pass | P19: https://sulwhasoo-jp.myshopify.com/blogs/sulwhasoo-post/journey-to-holistic-beauty-時の流れに揺るがない美しさへの旅 | Q19: Pass | R19: 「Journey to Holistic Beauty」時の流れに揺るがない美しさへの旅 | Sulwhasoo Japan | S19: 時を超えて愛される韓国発ラグジュアリービューティーブランド、Sulwhasoo（雪花秀／ソルファス）。その世界観と高麗人参サイエンスを体験できる「Sulwhasoo Lounge（ソルファスラウンジ）」が、5月6日（水）より@cosme TOKYOにて1週間限定オープン。 アモーレパシフィックジャパン株式会社（所在地：東京都渋谷区 代表：羅政均）が展開する、韓国発ラグジュアリービューティーブランド『Sulwhasoo（雪花秀/ソルファス）』は、5月6日（水）から12日（火）までの1週間、@cosme TOKYO ポップアップストア1階にて「Sulwhasoo Lounge（ソルファスラウンジ）」を開催します。 長年にわたり韓国ビュー | T19: article | U19: Sulwhasoo Japan | V19: http://sulwhasoo-jp.myshopify.com/cdn/shop/articles/Sulwhasoo_JP.webp?v=1776042225 | W19: https://sulwhasoo-jp.myshopify.com/blogs/sulwhasoo-post/journey-to-holistic-beauty-%e6%99%82%e3%81%ae%e6%b5%81%e3%82%8c%e3%81%ab%e6%8f%ba%e3%82%8b%e3%81%8c%e3%81%aa%e3%81%84%e7%be%8e%e3%81%97%e3%81%95%e3%81%b8%e3%81%ae%e6%97%85 | X19: summary_large_image | Y19: 「Journey to Holistic Beauty」時の流れに揺るがない美しさへの旅 | Sulwhasoo Japan | AA19: url 채우기 | AB19: Fail | AC19: Organization | AE19: Article | AF19: WebPage | AG19: Person | AH19: Organization | AI19: Fail
A20: https://sulwhasoo-jp.myshopify.com/blogs/sulwhasoo-post/concentrated-ginseng-rejuvenating-cream | C20: Pass | D20: Indexable | E20: 200 | F20: Pass | G20: Concentrated Ginseng Rejuvenating Cream | Sulwhasoo Japan | H20: Pass | J20: Discover 60 years of Ginseng science with Sulwhasoo’s Concentrated Ginseng Rejuvenating Cream, boosting elasticity for a youthful glow. | K20: Pass | M20: Concentrated Ginseng Rejuvenating Cream | O20: Pass | P20: https://sulwhasoo-jp.myshopify.com/blogs/sulwhasoo-post/concentrated-ginseng-rejuvenating-cream | Q20: Pass | R20: Concentrated Ginseng Rejuvenating Cream | Sulwhasoo Japan | S20: Discover 60 years of Ginseng science with Sulwhasoo’s Concentrated Ginseng Rejuvenating Cream, boosting elasticity for a youthful glow. | T20: article | U20: Sulwhasoo Japan | V20: http://sulwhasoo-jp.myshopify.com/cdn/shop/articles/Sulwhasoo_JP.webp?v=1776042225 | W20: https://sulwhasoo-jp.myshopify.com/blogs/sulwhasoo-post/concentrated-ginseng-rejuvenating-cream | X20: summary_large_image | Y20: Concentrated Ginseng Rejuvenating Cream | Sulwhasoo Japan | AA20: url 채우기 | AB20: Fail | AC20: Organization | AE20: Article | AF20: WebPage | AG20: Person | AH20: Organization | AI20: Fail
A21: https://sulwhasoo-jp.myshopify.com/blogs/sulwhasoo-post/2025-first-care-activating-serum-introduction | C21: Pass | D21: Indexable | E21: 200 | F21: Pass | G21: FIRST CARE ACTIVATING SERUM – Sulwhasoo Japan | H21: Pass | I21: FIRST CARE ACTIVATING SERUM | Sulwhasoo Japan | J21: REVITALIZE YOUR SKIN FOR A HEALTHY, YOUTHFUL COMPLEXION | K21: Pass | M21: 2025 FIRST CARE ACTIVATING SERUM | N21: 潤燥ユンジョ ファーストケア アクティブセラム VI | O21: Pass | P21: https://sulwhasoo-jp.myshopify.com/blogs/sulwhasoo-post/2025-first-care-activating-serum-introduction | Q21: Pass | R21: FIRST CARE ACTIVATING SERUM – Sulwhasoo Japan | S21: REVITALIZE YOUR SKIN FOR A HEALTHY, YOUTHFUL COMPLEXION | T21: article | U21: Sulwhasoo Japan | V21: http://sulwhasoo-jp.myshopify.com/cdn/shop/articles/Sulwhasoo_JP.webp?v=1776042225 | W21: https://sulwhasoo-jp.myshopify.com/blogs/sulwhasoo-post/2025-first-care-activating-serum-introduction | X21: summary_large_image | Y21: FIRST CARE ACTIVATING SERUM – Sulwhasoo Japan | AA21: url 채우기 | AB21: Fail | AC21: Organization | AE21: Article | AF21: WebPage | AG21: Person | AH21: Organization | AI21: Fail
A22: https://sulwhasoo-jp.myshopify.com/blogs/sulwhasoo-post | C22: Pass | D22: Indexable | E22: 200 | F22: Pass | G22: Brand News | Heritage-Inspired Luxury | Sulwhasoo Japan | H22: Pass | J22: Sulwhasoo, an iconic luxury beauty brand, dates back to 1932. Known for its pioneering spirit, it was the first to create products infused with ginseng. | K22: Pass | M22: BRAND NEWS | O22: Pass | P22: https://sulwhasoo-jp.myshopify.com/blogs/sulwhasoo-post | Q22: Pass | R22: Brand News | Heritage-Inspired Luxury | Sulwhasoo Japan | S22: Sulwhasoo, an iconic luxury beauty brand, dates back to 1932. Known for its pioneering spirit, it was the first to create products infused with ginseng. | T22: website | U22: Sulwhasoo Japan | V22: http://sulwhasoo-jp.myshopify.com/cdn/shop/articles/Sulwhasoo_JP.webp?v=1776042225 | W22: https://sulwhasoo-jp.myshopify.com/blogs/sulwhasoo-post | X22: summary_large_image | Y22: Brand News | Heritage-Inspired Luxury | Sulwhasoo Japan | AA22: url 채우기 | AB22: Fail | AC22: Organization | AI22: Fail
A23: https://sulwhasoo-jp.myshopify.com/blogs/notice | C23: Pass | D23: Indexable | E23: 200 | F23: Pass | G23: Notice | Sulwhasoo Japan | H23: Pass | K23: Fail | L23: Sulwhasoo Notice. Stay updated with the latest news, service announcements, and shipping schedules from our official store. | M23: お知らせ | O23: Pass | P23: https://sulwhasoo-jp.myshopify.com/blogs/notice | Q23: Pass | R23: Notice | Sulwhasoo Japan | S23: Meta Description to-be 내용 넣기 | T23: website | U23: Sulwhasoo Japan | V23: http://sulwhasoo-jp.myshopify.com/cdn/shop/articles/Sulwhasoo_JP.webp?v=1776042225 | W23: https://sulwhasoo-jp.myshopify.com/blogs/notice | X23: summary_large_image | Y23: Notice | Sulwhasoo Japan | AA23: url 채우기 | AB23: Fail | AC23: Organization | AI23: Fail
A24: https://sulwhasoo-jp.myshopify.com/blogs/event/公式ストアオープン記念-レビューキャンペーン | C24: Pass | D24: Indexable | E24: 200 | F24: Pass | G24: 公式ストアオープン記念 レビューキャンペーン | Sulwhasoo Japan | H24: Pass | J24: 公式ストアオープン記念レビューキャンペーン。 キャンペーン期間は2026年4月28日から6月30日までです。 対象商品レビュー投稿者の中から抽選で5名様にスペシャルギフトをプレゼントします。 | K24: Pass | O24: Pass | P24: https://sulwhasoo-jp.myshopify.com/blogs/event/公式ストアオープン記念-レビューキャンペーン | Q24: Pass | R24: 公式ストアオープン記念 レビューキャンペーン | Sulwhasoo Japan | S24: 公式ストアオープン記念レビューキャンペーン。 キャンペーン期間は2026年4月28日から6月30日までです。 対象商品レビュー投稿者の中から抽選で5名様にスペシャルギフトをプレゼントします。 | T24: article | U24: Sulwhasoo Japan | V24: http://sulwhasoo-jp.myshopify.com/cdn/shop/articles/Sulwhasoo_JP.webp?v=1776042225 | W24: https://sulwhasoo-jp.myshopify.com/blogs/event/%e5%85%ac%e5%bc%8f%e3%82%b9%e3%83%88%e3%82%a2%e3%82%aa%e3%83%bc%e3%83%97%e3%83%b3%e8%a8%98%e5%bf%b5-%e3%83%ac%e3%83%93%e3%83%a5%e3%83%bc%e3%82%ad%e3%83%a3%e3%83%b3%e3%83%9a%e3%83%bc%e3%83%b3 | X24: summary_large_image | Y24: 公式ストアオープン記念 レビューキャンペーン | Sulwhasoo Japan | AA24: url 채우기 | AB24: Fail | AC24: Organization | AE24: Article | AF24: WebPage | AG24: Person | AH24: Organization | AI24: Fail
A25: https://sulwhasoo-jp.myshopify.com/blogs/event/cosme-store-tokyoにてpopupstore開催 | C25: N/A | D25: Non-Indexable | E25: 404 | F25: N/A | G25: @cosme store TOKYOにてPOPUPSTORE開催 | Sulwhasoo Japan | H25: N/A | J25: 韓国発ラグジュアリースキンケアブランド「Sulwhasoo（ソルファス）」は、2026年5月6日から5月12日までの期間、＠cosme storeにてPOPUPSTOREを開催いたします【POPUP STORE開催概要】 期間：2026年5月6日～2026年5月12日 開催時間：11:00～21:00 場所：@cosme TOKYO 住所：東京都渋谷区神宮前1-14-27 | K25: N/A | M25: @cosme store TOKYOにてPOPUPSTORE開催 | O25: N/A | P25: https://sulwhasoo-jp.myshopify.com/blogs/event/cosme-store-tokyoにてpopupstore開催 | Q25: N/A | R25: @cosme store TOKYOにてPOPUPSTORE開催 | Sulwhasoo Japan | S25: 韓国発ラグジュアリースキンケアブランド「Sulwhasoo（ソルファス）」は、2026年5月6日から5月12日までの期間、＠cosme storeにてPOPUPSTOREを開催いたします【POPUP STORE開催概要】 期間：2026年5月6日～2026年5月12日 開催時間：11:00～21:00 場所：@cosme TOKYO 住所：東京都渋谷区神宮前1-14-27 | T25: article | U25: Sulwhasoo Japan | V25: http://sulwhasoo-jp.myshopify.com/cdn/shop/articles/111170002325_01_d50df340-e78c-4d41-ae4f-ea577d47fb7b.jpg?v=1776047739 | W25: https://sulwhasoo-jp.myshopify.com/blogs/event/cosme-store-tokyo%e3%81%ab%e3%81%a6popupstore%e9%96%8b%e5%82%ac | X25: summary_large_image | Y25: @cosme store TOKYOにてPOPUPSTORE開催 | Sulwhasoo Japan | AA25: url 채우기 | AB25: N/A | AC25: Organization | AE25: Article | AF25: WebPage | AG25: Person | AH25: Organization | AI25: N/A
A26: https://sulwhasoo-jp.myshopify.com/blogs/event | C26: Pass | D26: Indexable | E26: 200 | F26: Pass | G26: Event | Sulwhasoo Japan | H26: Pass | K26: Fail | L26: Sulwhasoo Events. Discover exclusive promotions, gift-with-purchase offers, and seasonal specials for our members. Check out our current events now. | M26: イベント | O26: Pass | P26: https://sulwhasoo-jp.myshopify.com/blogs/event | Q26: Pass | R26: Event | Sulwhasoo Japan | S26: Meta Description to-be 내용 넣기 | T26: website | U26: Sulwhasoo Japan | V26: http://sulwhasoo-jp.myshopify.com/cdn/shop/articles/Sulwhasoo_JP.webp?v=1776042225 | W26: https://sulwhasoo-jp.myshopify.com/blogs/event | X26: summary_large_image | Y26: Event | Sulwhasoo Japan | AA26: url 채우기 | AB26: Fail | AC26: Organization | AI26: Fail
A27: https://sulwhasoo-jp.myshopify.com/ | C27: Pass | D27: Indexable | E27: 200 | F27: Pass | G27: Sulwhasoo Japan | H27: Pass | K27: Pass | L27: Sulwhasoo Japan Official Website. Experience our luxury skincare line featuring First Care Activating Serum. Shop now for radiant beauty. | M27: Sulwhasoo Japan | O27: Pass | P27: https://sulwhasoo-jp.myshopify.com/ | Q27: Pass | R27: Sulwhasoo Japan | S27: Sulwhasoo（ソルファス）Japan公式オンラインストア。韓国伝統の知恵と最先端の現代技術を融合させたスキンケアブランド「雪花秀」公式ストアです | T27: website | U27: Sulwhasoo Japan | V27: http://sulwhasoo-jp.myshopify.com/cdn/shop/articles/Sulwhasoo_JP.webp?v=1776042225 | W27: https://sulwhasoo-jp.myshopify.com/ | X27: summary_large_image | Y27: Sulwhasoo Japan | AA27: url 채우기 | AB27: Fail | AC27: Organization | AE27: WebSite | AF27: SearchAction | AI27: Pass

Sheet TOBE-1차
A1: Address | B1: 비고 | C1: Address QA | D1: Indexability | E1: Updated | F1: Status Code | G1: Status/Indexability QA | H1: Title 1 | I1: Title QA | J1: Title to-be | K1: Meta Description 1 | L1: Meta Description QA | M1: Meta Description to-be | N1: H1-1 | O1: H1-2 | P1: H1 QA | Q1: Canonical Link Element 1 | R1: Canonical QA | S1: OG Title 1 | T1: OG Description 1 | U1: OG Type 1 | V1: OG Site Name 1 | W1: OG image 1 | X1: OG url 1 | Y1: Twitter Card 1 | Z1: Twitter Title 1 | AA1: Twitter Site 1 | AB1: Twitter URL 1 | AC1: Social Tag QA | AD1: Type-1 | AE1: Type-2 | AF1: Type-3 | AG1: Type-4 | AH1: Type-5 | AI1: Schema QA
A2: https://sulwhasoo-jp.myshopify.com/pages/store-locator | C2: Pass | D2: Indexable | E2: 확인 불가 | F2: 200 | G2: Pass | H2: Store Locator | Sulwhasoo Japan | I2: Pass | K2: Store Locator is loading from Storemapper plugin... | L2: Fail | M2: This is the Sulwhasoo store locator page. Check the locations and information of nearby stores. | P2: Pass | Q2: https://sulwhasoo-jp.myshopify.com/pages/store-locator | R2: Pass | S2: Store Locator | Sulwhasoo Japan | T2: Meta Description to-be 내용 넣기 | U2: website | V2: Sulwhasoo Japan | W2: 설화수 로고 및 대표 이미지 넣기 - KR참고 | X2: https://sulwhasoo-jp.myshopify.com/pages/store-locator | Y2: summary_large_image | Z2: Store Locator | Sulwhasoo Japan | AB2: url 채우기 | AC2: Fail | AD2: Organization | AI2: Fail
A3: https://sulwhasoo-jp.myshopify.com/pages/site-map | C3: Pass | D3: Indexable | E3: O | F3: 200 | G3: Pass | H3: Site Map | Sulwhasoo Japan | I3: Pass | L3: Fail | M3: Sulwhasoo Sitemap. You can view the entire menu and key content of the Sulwhasoo website at a glance. | N3: Site Map | P3: Pass | Q3: https://sulwhasoo-jp.myshopify.com/pages/site-map | R3: Pass | S3: Site Map | Sulwhasoo Japan | T3: Meta Description to-be 내용 넣기 | U3: website | V3: Sulwhasoo Japan | W3: 설화수 로고 및 대표 이미지 넣기 - KR참고 | X3: https://sulwhasoo-jp.myshopify.com/pages/site-map | Y3: summary_large_image | Z3: Site Map | Sulwhasoo Japan | AB3: url 채우기 | AC3: Fail | AD3: Organization | AI3: Fail
A4: https://sulwhasoo-jp.myshopify.com/pages/shopping-guide | C4: Pass | D4: Indexable | E4: O | F4: 200 | G4: Pass | H4: Shopping Guide | Sulwhasoo Japan | I4: Pass | L4: Fail | M4: Shop Sulwhasoo Japan with ease. Free shipping on orders over ¥6,000. We support PayPay, Rakuten Pay & credit cards. See our guide for ordering & delivery info. | N4: ご注文について | P4: Pass | Q4: https://sulwhasoo-jp.myshopify.com/pages/shopping-guide | R4: Pass | S4: Shopping Guide | Sulwhasoo Japan | T4: Meta Description to-be 내용 넣기 | U4: website | V4: Sulwhasoo Japan | W4: 설화수 로고 및 대표 이미지 넣기 - KR참고 | X4: https://sulwhasoo-jp.myshopify.com/pages/shopping-guide | Y4: summary_large_image | Z4: Shopping Guide | Sulwhasoo Japan | AB4: url 채우기 | AC4: Fail | AD4: Organization | AI4: Fail
A5: https://sulwhasoo-jp.myshopify.com/pages/shop-info | C5: Pass | D5: Indexable | E5: O | F5: 200 | G5: Pass | H5: Shop Info | Sulwhasoo Japan | I5: Pass | L5: Fail | M5: Discover the heritage of Sulwhasoo Japan. View official store information, brand philosophy, and legal notices for our online and offline presence. | N5: Shop Info | P5: Pass | Q5: https://sulwhasoo-jp.myshopify.com/pages/shop-info | R5: Pass | S5: Shop Info | Sulwhasoo Japan | T5: Meta Description to-be 내용 넣기 | U5: website | V5: Sulwhasoo Japan | W5: 설화수 로고 및 대표 이미지 넣기 - KR참고 | X5: https://sulwhasoo-jp.myshopify.com/pages/shop-info | Y5: summary_large_image | Z5: Shop Info | Sulwhasoo Japan | AB5: url 채우기 | AC5: Fail | AD5: Organization | AI5: Fail
A6: https://sulwhasoo-jp.myshopify.com/pages/point-list | C6: N/A | D6: Indexable | E6: O | F6: 200 | G6: Fail | H6: Point List | Sulwhasoo Japan | I6: N/A | L6: N/A | N6: ポイント情報 | P6: N/A | Q6: https://sulwhasoo-jp.myshopify.com/pages/point-list | R6: N/A | S6: Point List | Sulwhasoo Japan | T6: Sulwhasoo Japan | U6: website | V6: Sulwhasoo Japan | X6: https://sulwhasoo-jp.myshopify.com/pages/point-list | Y6: summary_large_image | Z6: Point List | Sulwhasoo Japan | AC6: N/A | AD6: Organization | AI6: N/A
A7: https://sulwhasoo-jp.myshopify.com/pages/order-list | C7: N/A | D7: Indexable | E7: O | F7: 200 | G7: Fail | H7: Order List | Sulwhasoo Japan | I7: N/A | L7: N/A | N7: ご注文管理 | P7: N/A | Q7: https://sulwhasoo-jp.myshopify.com/pages/order-list | R7: N/A | S7: Order List | Sulwhasoo Japan | T7: Sulwhasoo Japan | U7: website | V7: Sulwhasoo Japan | X7: https://sulwhasoo-jp.myshopify.com/pages/order-list | Y7: summary_large_image | Z7: Order List | Sulwhasoo Japan | AC7: N/A | AD7: Organization | AI7: N/A
A8: https://sulwhasoo-jp.myshopify.com/pages/mypage | C8: N/A | D8: Indexable | E8: O | F8: 200 | G8: Fail | H8: mypage | Sulwhasoo Japan | I8: N/A | L8: N/A | N8: マイページ | P8: N/A | Q8: https://sulwhasoo-jp.myshopify.com/pages/mypage | R8: N/A | S8: mypage | Sulwhasoo Japan | T8: Sulwhasoo Japan | U8: website | V8: Sulwhasoo Japan | X8: https://sulwhasoo-jp.myshopify.com/pages/mypage | Y8: summary_large_image | Z8: mypage | Sulwhasoo Japan | AC8: N/A | AD8: Organization | AI8: N/A
A9: https://sulwhasoo-jp.myshopify.com/pages/my-address | C9: N/A | D9: Indexable | E9: O | F9: 200 | G9: Fail | H9: my-address | Sulwhasoo Japan | I9: N/A | L9: N/A | N9: My Page | P9: N/A | Q9: https://sulwhasoo-jp.myshopify.com/pages/my-address | R9: N/A | S9: my-address | Sulwhasoo Japan | T9: Sulwhasoo Japan | U9: website | V9: Sulwhasoo Japan | X9: https://sulwhasoo-jp.myshopify.com/pages/my-address | Y9: summary_large_image | Z9: my-address | Sulwhasoo Japan | AC9: N/A | AD9: Organization | AI9: N/A
A10: https://sulwhasoo-jp.myshopify.com/pages/membership | C10: Pass | D10: Indexable | E10: O | F10: 200 | G10: Pass | H10: Membership | Sulwhasoo Japan | I10: Pass | L10: Fail | M10: Bergabung dengan keanggotaan Sulwhasoo dan dapatkan beragam keistimewaan. | N10: メンバーシップ | P10: Pass | Q10: https://sulwhasoo-jp.myshopify.com/pages/membership | R10: Pass | S10: Membership | Sulwhasoo Japan | T10: Meta Description to-be 내용 넣기 | U10: website | V10: Sulwhasoo Japan | W10: 설화수 로고 및 대표 이미지 넣기 - KR참고 | X10: https://sulwhasoo-jp.myshopify.com/pages/membership | Y10: summary_large_image | Z10: Membership | Sulwhasoo Japan | AB10: url 채우기 | AC10: Fail | AD10: Organization | AI10: Fail
A11: https://sulwhasoo-jp.myshopify.com/pages/legal-notice | C11: Pass | D11: Indexable | E11: 확인 불가 | F11: 200 | G11: Pass | H11: 特定商取引法に基づく表記 | Sulwhasoo Japan | I11: Pass | K11: 事業者名 アモーレパシフィックジャパン株式会社 所在地 〒150-0012 東京都渋谷区広尾１－１３－７ 恵比寿イーストビル2階 代表者 代表 松井 理奈 お問い合わせ Sulwhasoo カスタマーサポート TEL：0120-929-744 受付時間： 月~金 10:00 ~ 18:00＜祝祭日、年末年始・夏期休暇を除く＞ フォームでのお問い合わせはこちら URL https://jp.sulwhasoo.com/ 販売価格 各商品詳細ページに表示された価格に基づきます。表示価格は本体価格に消費税額を加えた「お支払い総額（税込価格）」となっております。 商品代金以外の必要料金 ■送料：通常配送料金は、550円（税込）※沖縄、北海 | L11: Pass | P11: Pass | Q11: https://sulwhasoo-jp.myshopify.com/pages/legal-notice | R11: Pass | S11: 特定商取引法に基づく表記 | Sulwhasoo Japan | T11: 事業者名 アモーレパシフィックジャパン株式会社 所在地 〒150-0012 東京都渋谷区広尾１－１３－７ 恵比寿イーストビル2階 代表者 代表 松井 理奈 お問い合わせ Sulwhasoo カスタマーサポート TEL：0120-929-744 受付時間： 月~金 10:00 ~ 18:00＜祝祭日、年末年始・夏期休暇を除く＞ フォームでのお問い合わせはこちら URL https://jp.sulwhasoo.com/ 販売価格 各商品詳細ページに表示された価格に基づきます。表示価格は本体価格に消費税額を加えた「お支払い総額（税込価格）」となっております。 商品代金以外の必要料金 ■送料：通常配送料金は、550円（税込）※沖縄、北海 | U11: website | V11: Sulwhasoo Japan | W11: 설화수 로고 및 대표 이미지 넣기 - KR참고 | X11: https://sulwhasoo-jp.myshopify.com/pages/legal-notice | Y11: summary_large_image | Z11: 特定商取引法に基づく表記 | Sulwhasoo Japan | AB11: url 채우기 | AC11: Fail | AD11: Organization | AI11: Fail
A12: https://sulwhasoo-jp.myshopify.com/pages/faq | C12: Pass | D12: Indexable | E12: O | F12: 200 | G12: Pass | H12: FAQ | Sulwhasoo Japan | I12: Pass | L12: Fail | M12: Sulwhasoo FAQ. Find quick answers to your questions about order status, payment methods, shipping tracking, and product inquiries in one place. | N12: よくあるご質問 | P12: Pass | Q12: https://sulwhasoo-jp.myshopify.com/pages/faq | R12: Pass | S12: FAQ | Sulwhasoo Japan | T12: Meta Description to-be 내용 넣기 | U12: website | V12: Sulwhasoo Japan | W12: 설화수 로고 및 대표 이미지 넣기 - KR참고 | X12: https://sulwhasoo-jp.myshopify.com/pages/faq | Y12: summary_large_image | Z12: FAQ | Sulwhasoo Japan | AB12: url 채우기 | AC12: Fail | AD12: Organization | AI12: Fail
A13: https://sulwhasoo-jp.myshopify.com/pages/exchange-return | C13: Pass | D13: Indexable | E13: O | F13: 200 | G13: Pass | H13: Exchange Return | Sulwhasoo Japan | I13: Pass | L13: Fail | M13: Sulwhasoo Exchange & Return. Guide for returning damaged or incorrect items. Contact our support team to request an exchange or refund under our policy. | N13: 交換・返品について | P13: Pass | Q13: https://sulwhasoo-jp.myshopify.com/pages/exchange-return | R13: Pass | S13: Exchange Return | Sulwhasoo Japan | T13: Meta Description to-be 내용 넣기 | U13: website | V13: Sulwhasoo Japan | W13: 설화수 로고 및 대표 이미지 넣기 - KR참고 | X13: https://sulwhasoo-jp.myshopify.com/pages/exchange-return | Y13: summary_large_image | Z13: Exchange Return | Sulwhasoo Japan | AB13: url 채우기 | AC13: Fail | AD13: Organization | AI13: Fail
A14: https://sulwhasoo-jp.myshopify.com/pages/edit-account | C14: N/A | D14: Indexable | E14: O | F14: 200 | G14: Fail | H14: Edit Account | Sulwhasoo Japan | I14: N/A | L14: N/A | N14: 個人情報の修正 | P14: N/A | Q14: https://sulwhasoo-jp.myshopify.com/pages/edit-account | R14: N/A | S14: Edit Account | Sulwhasoo Japan | T14: Sulwhasoo Japan | U14: website | V14: Sulwhasoo Japan | X14: https://sulwhasoo-jp.myshopify.com/pages/edit-account | Y14: summary_large_image | Z14: Edit Account | Sulwhasoo Japan | AC14: N/A | AD14: Organization | AI14: N/A
A15: https://sulwhasoo-jp.myshopify.com/pages/contact | C15: Pass | D15: Indexable | E15: O | F15: 200 | G15: Pass | H15: Contact | Sulwhasoo Japan | I15: Pass | L15: Fail | M15: Contact Sulwhasoo for inquiries on products, orders, or shipping. Please fill out the form below for assistance. | N15: お問い合わせ | P15: Pass | Q15: https://sulwhasoo-jp.myshopify.com/pages/contact | R15: Pass | S15: Contact | Sulwhasoo Japan | T15: Meta Description to-be 내용 넣기 | U15: website | V15: Sulwhasoo Japan | W15: 설화수 로고 및 대표 이미지 넣기 - KR참고 | X15: https://sulwhasoo-jp.myshopify.com/pages/contact | Y15: summary_large_image | Z15: Contact | Sulwhasoo Japan | AB15: url 채우기 | AC15: Fail | AD15: Organization | AI15: Fail
A16: https://sulwhasoo-jp.myshopify.com/pages/brand-sustainability | C16: Pass | D16: Indexable | E16: O | F16: 200 | G16: Pass | H16: Brand Sustainability – Earth & Culture | Sulwhasoo Japan | I16: Pass | K16: Sulwhasoo’s sustainable beauty is built on Ginseng Science, Environmental Care, and Cultural Heritage to shape a better future. | L16: Pass | N16: Brand Sustainability | Sulwhasoo Japan | O16: 持続可能な未来のための約束 | P16: Fail | Q16: https://sulwhasoo-jp.myshopify.com/pages/brand-sustainability | R16: Pass | S16: Brand Sustainability – Earth & Culture | Sulwhasoo Japan | T16: Sulwhasoo’s sustainable beauty is built on Ginseng Science, Environmental Care, and Cultural Heritage to shape a better future. | U16: website | V16: Sulwhasoo Japan | W16: 설화수 로고 및 대표 이미지 넣기 - KR참고 | X16: https://sulwhasoo-jp.myshopify.com/pages/brand-sustainability | Y16: summary_large_image | Z16: Brand Sustainability – Earth & Culture | Sulwhasoo Japan | AB16: url 채우기 | AC16: Fail | AD16: Organization | AI16: Fail
A17: https://sulwhasoo-jp.myshopify.com/pages/brand-story | C17: Pass | D17: Indexable | E17: O | F17: 200 | G17: Pass | H17: Brand Story | Sulwhasoo Japan | I17: Pass | K17: Sulwhasoo fuses Korean tradition with cutting-edge science, using JAUM Activator® and ginseng research for youthful, radiant skin | L17: Pass | N17: Brand Story | Sulwhasoo Japan | O17: 時の流れにゆるがない美しさへの旅 | P17: Fail | Q17: https://sulwhasoo-jp.myshopify.com/pages/brand-story | R17: Pass | S17: Brand Story | Sulwhasoo Japan | T17: Sulwhasoo fuses Korean tradition with cutting-edge science, using JAUM Activator® and ginseng research for youthful, radiant skin | U17: website | V17: Sulwhasoo Japan | W17: 설화수 로고 및 대표 이미지 넣기 - KR참고 | X17: https://sulwhasoo-jp.myshopify.com/pages/brand-story | Y17: summary_large_image | Z17: Brand Story | Sulwhasoo Japan | AB17: url 채우기 | AC17: Fail | AD17: Organization | AI17: Fail
A18: https://sulwhasoo-jp.myshopify.com/pages/activate-account-form | C18: N/A | D18: Indexable | E18: 확인 불가 | F18: 200 | G18: Fail | H18: Activate Account Form | Sulwhasoo Japan | I18: N/A | L18: N/A | P18: N/A | Q18: https://sulwhasoo-jp.myshopify.com/pages/activate-account-form | R18: N/A | S18: Activate Account Form | Sulwhasoo Japan | T18: Sulwhasoo Japan | U18: website | V18: Sulwhasoo Japan | X18: https://sulwhasoo-jp.myshopify.com/pages/activate-account-form | Y18: summary_large_image | Z18: Activate Account Form | Sulwhasoo Japan | AC18: N/A | AD18: Organization | AI18: N/A
A19: https://sulwhasoo-jp.myshopify.com/blogs/sulwhasoo-post/journey-to-holistic-beauty-時の流れに揺るがない美しさへの旅 | C19: Pass | D19: Indexable | E19: O | F19: 200 | G19: Pass | H19: 「Journey to Holistic Beauty」時の流れに揺るがない美しさへの旅 | Sulwhasoo Japan | I19: Pass | K19: 時を超えて愛される韓国発ラグジュアリービューティーブランド、Sulwhasoo（雪花秀／ソルファス）。その世界観と高麗人参サイエンスを体験できる「Sulwhasoo Lounge（ソルファスラウンジ）」が、5月6日（水）より@cosme TOKYOにて1週間限定オープン。 アモーレパシフィックジャパン株式会社（所在地：東京都渋谷区 代表：羅政均）が展開する、韓国発ラグジュアリービューティーブランド『Sulwhasoo（雪花秀/ソルファス）』は、5月6日（水）から12日（火）までの1週間、@cosme TOKYO ポップアップストア1階にて「Sulwhasoo Lounge（ソルファスラウンジ）」を開催します。 長年にわたり韓国ビュー | L19: Pass | P19: Pass | Q19: https://sulwhasoo-jp.myshopify.com/blogs/sulwhasoo-post/journey-to-holistic-beauty-時の流れに揺るがない美しさへの旅 | R19: Pass | S19: 「Journey to Holistic Beauty」時の流れに揺るがない美しさへの旅 | Sulwhasoo Japan | T19: 時を超えて愛される韓国発ラグジュアリービューティーブランド、Sulwhasoo（雪花秀／ソルファス）。その世界観と高麗人参サイエンスを体験できる「Sulwhasoo Lounge（ソルファスラウンジ）」が、5月6日（水）より@cosme TOKYOにて1週間限定オープン。 アモーレパシフィックジャパン株式会社（所在地：東京都渋谷区 代表：羅政均）が展開する、韓国発ラグジュアリービューティーブランド『Sulwhasoo（雪花秀/ソルファス）』は、5月6日（水）から12日（火）までの1週間、@cosme TOKYO ポップアップストア1階にて「Sulwhasoo Lounge（ソルファスラウンジ）」を開催します。 長年にわたり韓国ビュー | U19: article | V19: Sulwhasoo Japan | W19: http://sulwhasoo-jp.myshopify.com/cdn/shop/articles/Sulwhasoo_JP.webp?v=1776042225 | X19: https://sulwhasoo-jp.myshopify.com/blogs/sulwhasoo-post/journey-to-holistic-beauty-%e6%99%82%e3%81%ae%e6%b5%81%e3%82%8c%e3%81%ab%e6%8f%ba%e3%82%8b%e3%81%8c%e3%81%aa%e3%81%84%e7%be%8e%e3%81%97%e3%81%95%e3%81%b8%e3%81%ae%e6%97%85 | Y19: summary_large_image | Z19: 「Journey to Holistic Beauty」時の流れに揺るがない美しさへの旅 | Sulwhasoo Japan | AB19: url 채우기 | AC19: Fail | AD19: Organization | AE19: Article | AF19: WebPage | AG19: Person | AH19: Organization | AI19: Fail
A20: https://sulwhasoo-jp.myshopify.com/blogs/sulwhasoo-post/concentrated-ginseng-rejuvenating-cream | C20: Pass | D20: Indexable | E20: O | F20: 200 | G20: Pass | H20: Concentrated Ginseng Rejuvenating Cream | Sulwhasoo Japan | I20: Pass | K20: Discover 60 years of Ginseng science with Sulwhasoo’s Concentrated Ginseng Rejuvenating Cream, boosting elasticity for a youthful glow. | L20: Pass | N20: Concentrated Ginseng Rejuvenating Cream | P20: Pass | Q20: https://sulwhasoo-jp.myshopify.com/blogs/sulwhasoo-post/concentrated-ginseng-rejuvenating-cream | R20: Pass | S20: Concentrated Ginseng Rejuvenating Cream | Sulwhasoo Japan | T20: Discover 60 years of Ginseng science with Sulwhasoo’s Concentrated Ginseng Rejuvenating Cream, boosting elasticity for a youthful glow. | U20: article | V20: Sulwhasoo Japan | W20: http://sulwhasoo-jp.myshopify.com/cdn/shop/articles/240816_final_SG_concentrated-ginseng-rejuvenating-cream-cover_500x500_360x_83aa104d-76f3-4112-8d3b-ba15e6385f17.webp?v=1776072597 | X20: https://sulwhasoo-jp.myshopify.com/blogs/sulwhasoo-post/concentrated-ginseng-rejuvenating-cream | Y20: summary_large_image | Z20: Concentrated Ginseng Rejuvenating Cream | Sulwhasoo Japan | AB20: url 채우기 | AC20: Fail | AD20: Organization | AE20: Article | AF20: WebPage | AG20: Person | AH20: Organization | AI20: Fail
A21: https://sulwhasoo-jp.myshopify.com/blogs/sulwhasoo-post/2025-first-care-activating-serum-introduction | C21: Pass | D21: Indexable | E21: O | F21: 200 | G21: Pass | H21: FIRST CARE ACTIVATING SERUM – Sulwhasoo Japan | I21: Fail | J21: FIRST CARE ACTIVATING SERUM | Sulwhasoo Japan | K21: REVITALIZE YOUR SKIN FOR A HEALTHY, YOUTHFUL COMPLEXION | L21: Pass | N21: 2025 FIRST CARE ACTIVATING SERUM | O21: 潤燥ユンジョ ファーストケア アクティブセラム VI | P21: Fail | Q21: https://sulwhasoo-jp.myshopify.com/blogs/sulwhasoo-post/2025-first-care-activating-serum-introduction | R21: Pass | S21: FIRST CARE ACTIVATING SERUM – Sulwhasoo Japan | T21: REVITALIZE YOUR SKIN FOR A HEALTHY, YOUTHFUL COMPLEXION | U21: article | V21: Sulwhasoo Japan | W21: http://sulwhasoo-jp.myshopify.com/cdn/shop/articles/251120_final_TH_brand-news_thumbnail_720x_9f9a8857-59ec-48da-9861-5472e1a130e3.webp?v=1776043398 | X21: https://sulwhasoo-jp.myshopify.com/blogs/sulwhasoo-post/2025-first-care-activating-serum-introduction | Y21: summary_large_image | Z21: FIRST CARE ACTIVATING SERUM – Sulwhasoo Japan | AB21: url 채우기 | AC21: Fail | AD21: Organization | AE21: Article | AF21: WebPage | AG21: Person | AH21: Organization | AI21: Fail
A22: https://sulwhasoo-jp.myshopify.com/blogs/sulwhasoo-post | C22: Pass | D22: Indexable | E22: O | F22: 200 | G22: Pass | H22: Brand News | Heritage-Inspired Luxury | Sulwhasoo Japan | I22: Pass | K22: Sulwhasoo, an iconic luxury beauty brand, dates back to 1932. Known for its pioneering spirit, it was the first to create products infused with ginseng. | L22: Pass | N22: BRAND NEWS | P22: Pass | Q22: https://sulwhasoo-jp.myshopify.com/blogs/sulwhasoo-post | R22: Pass | S22: Brand News | Heritage-Inspired Luxury | Sulwhasoo Japan | T22: Sulwhasoo, an iconic luxury beauty brand, dates back to 1932. Known for its pioneering spirit, it was the first to create products infused with ginseng. | U22: website | V22: Sulwhasoo Japan | W22: 설화수 로고 및 대표 이미지 넣기 - KR참고 | X22: https://sulwhasoo-jp.myshopify.com/blogs/sulwhasoo-post | Y22: summary_large_image | Z22: Brand News | Heritage-Inspired Luxury | Sulwhasoo Japan | AB22: url 채우기 | AC22: Fail | AD22: Organization | AI22: Fail
A23: https://sulwhasoo-jp.myshopify.com/blogs/notice | C23: Pass | D23: Indexable | E23: O | F23: 200 | G23: Pass | H23: Notice | Sulwhasoo Japan | I23: Pass | L23: Fail | M23: Sulwhasoo Notice. Stay updated with the latest news, service announcements, and shipping schedules from our official store. | N23: お知らせ | P23: Pass | Q23: https://sulwhasoo-jp.myshopify.com/blogs/notice | R23: Pass | S23: Notice | Sulwhasoo Japan | T23: Meta Description to-be 내용 넣기 | U23: website | V23: Sulwhasoo Japan | W23: 설화수 로고 및 대표 이미지 넣기 - KR참고 | X23: https://sulwhasoo-jp.myshopify.com/blogs/notice | Y23: summary_large_image | Z23: Notice | Sulwhasoo Japan | AB23: url 채우기 | AC23: Fail | AD23: Organization | AI23: Fail
A24: https://sulwhasoo-jp.myshopify.com/blogs/event/公式ストアオープン記念-レビューキャンペーン | C24: Pass | D24: Indexable | E24: O | F24: 200 | G24: Pass | H24: 公式ストアオープン記念 レビューキャンペーン | Sulwhasoo Japan | I24: Pass | K24: 公式ストアオープン記念レビューキャンペーン。 キャンペーン期間は2026年4月28日から6月30日までです。 対象商品レビュー投稿者の中から抽選で5名様にスペシャルギフトをプレゼントします。 | L24: Pass | P24: Pass | Q24: https://sulwhasoo-jp.myshopify.com/blogs/event/公式ストアオープン記念-レビューキャンペーン | R24: Pass | S24: 公式ストアオープン記念 レビューキャンペーン | Sulwhasoo Japan | T24: 公式ストアオープン記念レビューキャンペーン。 キャンペーン期間は2026年4月28日から6月30日までです。 対象商品レビュー投稿者の中から抽選で5名様にスペシャルギフトをプレゼントします。 | U24: article | V24: Sulwhasoo Japan | X24: https://sulwhasoo-jp.myshopify.com/blogs/event/%e5%85%ac%e5%bc%8f%e3%82%b9%e3%83%88%e3%82%a2%e3%82%aa%e3%83%bc%e3%83%97%e3%83%b3%e8%a8%98%e5%bf%b5-%e3%83%ac%e3%83%93%e3%83%a5%e3%83%bc%e3%82%ad%e3%83%a3%e3%83%b3%e3%83%9a%e3%83%bc%e3%83%b3 | Y24: summary_large_image | Z24: 公式ストアオープン記念 レビューキャンペーン | Sulwhasoo Japan | AB24: url 채우기 | AC24: Fail | AD24: Organization | AE24: Article | AF24: WebPage | AG24: Person | AH24: Organization | AI24: Fail
A25: https://sulwhasoo-jp.myshopify.com/blogs/event/cosme-store-tokyoにてpopupstore開催 | C25: Pass | D25: Indexable | E25: O | F25: 200 | G25: Pass | H25: @cosme store TOKYOにてPOPUPSTORE開催 | Sulwhasoo Japan | I25: Pass | K25: 韓国発ラグジュアリースキンケアブランド「Sulwhasoo（ソルファス）」は、2026年5月6日から5月12日までの期間、＠cosme storeにてPOPUPSTOREを開催いたします【POPUP STORE開催概要】 期間：2026年5月6日～2026年5月12日 開催時間：11:00～21:00 場所：@cosme TOKYO 住所：東京都渋谷区神宮前1-14-27 | L25: Pass | N25: @cosme store TOKYOにてPOPUPSTORE開催 | P25: Pass | Q25: https://sulwhasoo-jp.myshopify.com/blogs/event/cosme-store-tokyoにてpopupstore開催 | R25: Pass | S25: @cosme store TOKYOにてPOPUPSTORE開催 | Sulwhasoo Japan | T25: 韓国発ラグジュアリースキンケアブランド「Sulwhasoo（ソルファス）」は、2026年5月6日から5月12日までの期間、＠cosme storeにてPOPUPSTOREを開催いたします【POPUP STORE開催概要】 期間：2026年5月6日～2026年5月12日 開催時間：11:00～21:00 場所：@cosme TOKYO 住所：東京都渋谷区神宮前1-14-27 | U25: article | V25: Sulwhasoo Japan | W25: http://sulwhasoo-jp.myshopify.com/cdn/shop/articles/111170002325_01_d50df340-e78c-4d41-ae4f-ea577d47fb7b.jpg?v=1776047739 | X25: https://sulwhasoo-jp.myshopify.com/blogs/event/cosme-store-tokyo%e3%81%ab%e3%81%a6popupstore%e9%96%8b%e5%82%ac | Y25: summary_large_image | Z25: @cosme store TOKYOにてPOPUPSTORE開催 | Sulwhasoo Japan | AB25: url 채우기 | AC25: Fail | AD25: Organization | AE25: Article | AF25: WebPage | AG25: Person | AH25: Organization | AI25: Fail
A26: https://sulwhasoo-jp.myshopify.com/blogs/event | C26: Pass | D26: Indexable | E26: O | F26: 200 | G26: Pass | H26: Event | Sulwhasoo Japan | I26: Pass | L26: Fail | M26: Sulwhasoo Events. Discover exclusive promotions, gift-with-purchase offers, and seasonal specials for our members. Check out our current events now. | N26: イベント | P26: Pass | Q26: https://sulwhasoo-jp.myshopify.com/blogs/event | R26: Pass | S26: Event | Sulwhasoo Japan | T26: Meta Description to-be 내용 넣기 | U26: website | V26: Sulwhasoo Japan | W26: 설화수 로고 및 대표 이미지 넣기 - KR참고 | X26: https://sulwhasoo-jp.myshopify.com/blogs/event | Y26: summary_large_image | Z26: Event | Sulwhasoo Japan | AB26: url 채우기 | AC26: Fail | AD26: Organization | AI26: Fail
A27: https://sulwhasoo-jp.myshopify.com/ | C27: Pass | D27: Indexable | E27: O | F27: 200 | G27: Pass | H27: Sulwhasoo Japan | I27: Pass | L27: Fail | M27: Sulwhasoo Japan Official Website. Experience our luxury skincare line featuring First Care Activating Serum. Shop now for radiant beauty. | N27: Sulwhasoo Japan | P27: Pass | Q27: https://sulwhasoo-jp.myshopify.com/ | R27: Pass | S27: Sulwhasoo Japan | T27: Meta Description to-be 내용 넣기 | U27: website | V27: Sulwhasoo Japan | W27: 설화수 로고 및 대표 이미지 넣기 - KR참고 | X27: https://sulwhasoo-jp.myshopify.com/ | Y27: summary_large_image | Z27: Sulwhasoo Japan | AB27: url 채우기 | AC27: Fail | AD27: Organization | AE27: WebSite | AF27: SearchAction | AI27: Pass

Sheet data
A1: Address | B1: Content Type | C1: Status Code | D1: Status | E1: Indexability | F1: Indexability Status | G1: Title 1 | H1: Title 1 Length | I1: Title 1 Pixel Width | J1: Meta Description 1 | K1: Meta Description 1 Length | L1: Meta Description 1 Pixel Width | M1: Meta Keywords 1 | N1: Meta Keywords 1 Length | O1: H1-1 | P1: H1-1 Length | Q1: H1-2 | R1: H1-2 Length | S1: H2-1 | T1: H2-1 Length | U1: H2-2 | V1: H2-2 Length | W1: Meta Robots 1 | X1: X-Robots-Tag 1 | Y1: Meta Refresh 1 | Z1: Canonical Link Element 1 | AA1: rel="next" 1 | AB1: rel="prev" 1 | AC1: HTTP rel="next" 1 | AD1: HTTP rel="prev" 1 | AE1: amphtml Link Element | AF1: Size (bytes) | AG1: Transferred (bytes) | AH1: Word Count | AI1: Sentence Count | AJ1: Average Words Per Sentence | AK1: Flesch Reading Ease Score | AL1: Readability | AM1: Text Ratio | AN1: Crawl Depth | AO1: Folder Depth | AP1: Link Score | AQ1: Inlinks | AR1: Unique Inlinks | AS1: Unique JS Inlinks | AT1: % of Total | AU1: Outlinks | AV1: Unique Outlinks | AW1: Unique JS Outlinks | AX1: External Outlinks | AY1: Unique External Outlinks | AZ1: Unique External JS Outlinks | BA1: Closest Similarity Match | BB1: No. Near Duplicates | BC1: Spelling Errors | BD1: Grammar Errors | BE1: Hash | BF1: Response Time | BG1: Last Modified | BH1: Redirect URL | BI1: Redirect Type | BJ1: Cookies | BK1: HTTP Version | BL1: OG Title 1 | BM1: OG Description 1 | BN1: OG Type 1 | BO1: OG Site Name 1 | BP1: OG image 1 | BQ1: OG url 1 | BR1: Twitter Card 1 | BS1: Twitter Title 1 | BT1: Twitter Site 1 | BU1: Twitter URL 1 | BV1: type 1 | BW1: alternate 1 | BX1: URL Encoded Address | BY1: Crawl Timestamp | BZ1: type 2 | CA1: type 3 | CB1: type 4 | CC1: type 5
A2: https://sulwhasoo-jp.myshopify.com/ | B2: text/html; charset=utf-8 | C2: 200 | D2: OK | E2: Indexable | G2: Sulwhasoo Japan | H2: 15 | I2: 157 | K2: 0 | L2: 0 | N2: 0 | O2: Sulwhasoo Japan | P2: 15 | R2: 0 | S2: カート0 | T2: 4 | U2: おすすめのキーワード | V2: 10 | Z2: https://sulwhasoo-jp.myshopify.com/ | AF2: 697593 | AG2: 124600 | AH2: 333 | AI2: 195 | AJ2: 1.708 | AK2: 100 | AL2: Very Easy | AM2: 0.497 | AN2: 0 | AO2: 0 | AQ2: 94 | AR2: 30 | AS2: 0 | AT2: 93.75 | AU2: 148 | AV2: 60 | AW2: 0 | BE2: fc66ae26996816501e3132b0408658e0 | BF2: 0.207 | BK2: 1.1 | BL2: Sulwhasoo Japan | BM2: Sulwhasoo Japan | BN2: website | BO2: Sulwhasoo Japan | BQ2: https://sulwhasoo-jp.myshopify.com/ | BR2: summary_large_image | BS2: Sulwhasoo Japan | BV2: Organization | BX2: https://sulwhasoo-jp.myshopify.com/ | BY2: 46128.603 | BZ2: WebSite | CA2: SearchAction
A3: https://sulwhasoo-jp.myshopify.com/pages/contact | B3: text/html; charset=utf-8 | C3: 200 | D3: OK | E3: Indexable | G3: Contact | Sulwhasoo Japan | H3: 26 | I3: 242 | K3: 0 | L3: 0 | N3: 0 | O3: お問い合わせ | P3: 6 | R3: 0 | S3: カート0 | T3: 4 | U3: おすすめのキーワード | V3: 10 | Z3: https://sulwhasoo-jp.myshopify.com/pages/contact | AF3: 532180 | AG3: 115111 | AH3: 149 | AI3: 79 | AJ3: 1.886 | AK3: 100 | AL3: Very Easy | AM3: 0.436 | AN3: 0 | AO3: 1 | AQ3: 52 | AR3: 30 | AS3: 0 | AT3: 93.75 | AU3: 118 | AV3: 51 | AW3: 0 | BE3: 31fe67b129cc962dea2844bc8e615e86 | BF3: 0.52 | BK3: 1.1 | BL3: Contact | Sulwhasoo Japan | BM3: Sulwhasoo Japan | BN3: website | BO3: Sulwhasoo Japan | BQ3: https://sulwhasoo-jp.myshopify.com/pages/contact | BR3: summary_large_image | BS3: Contact | Sulwhasoo Japan | BV3: Organization | BX3: https://sulwhasoo-jp.myshopify.com/pages/contact | BY3: 46128.603
A4: https://sulwhasoo-jp.myshopify.com/pages/site-map | B4: text/html; charset=utf-8 | C4: 200 | D4: OK | E4: Indexable | G4: Site Map | Sulwhasoo Japan | H4: 27 | I4: 251 | K4: 0 | L4: 0 | N4: 0 | O4: Site Map | P4: 8 | R4: 0 | S4: カート0 | T4: 4 | U4: おすすめのキーワード | V4: 10 | Z4: https://sulwhasoo-jp.myshopify.com/pages/site-map | AF4: 530986 | AG4: 113301 | AH4: 263 | AI4: 129 | AJ4: 2.039 | AK4: 100 | AL4: Very Easy | AM4: 0.468 | AN4: 0 | AO4: 1 | AQ4: 37 | AR4: 30 | AS4: 0 | AT4: 93.75 | AU4: 154 | AV4: 52 | AW4: 0 | BE4: ddb9f201e6491401344e72e84eea542e | BF4: 0.355 | BK4: 1.1 | BL4: Site Map | Sulwhasoo Japan | BM4: Sulwhasoo Japan | BN4: website | BO4: Sulwhasoo Japan | BQ4: https://sulwhasoo-jp.myshopify.com/pages/site-map | BR4: summary_large_image | BS4: Site Map | Sulwhasoo Japan | BV4: Organization | BX4: https://sulwhasoo-jp.myshopify.com/pages/site-map | BY4: 46128.603
A5: https://sulwhasoo-jp.myshopify.com/pages/order-list | B5: text/html; charset=utf-8 | C5: 200 | D5: OK | E5: Indexable | G5: Order List | Sulwhasoo Japan | H5: 29 | I5: 260 | K5: 0 | L5: 0 | N5: 0 | O5: ご注文管理 | P5: 5 | R5: 0 | S5: カート0 | T5: 4 | U5: おすすめのキーワード | V5: 10 | Z5: https://sulwhasoo-jp.myshopify.com/pages/order-list | AF5: 519000 | AG5: 111802 | AH5: 148 | AI5: 72 | AJ5: 2.056 | AK5: 100 | AL5: Very Easy | AM5: 0.414 | AN5: 0 | AO5: 1 | AQ5: 15 | AR5: 4 | AS5: 0 | AT5: 12.5 | AU5: 116 | AV5: 57 | AW5: 0 | BE5: d1929f20a52521d5e5d23860752a0c2b | BF5: 0.366 | BK5: 1.1 | BL5: Order List | Sulwhasoo Japan | BM5: Sulwhasoo Japan | BN5: website | BO5: Sulwhasoo Japan | BQ5: https://sulwhasoo-jp.myshopify.com/pages/order-list | BR5: summary_large_image | BS5: Order List | Sulwhasoo Japan | BV5: Organization | BX5: https://sulwhasoo-jp.myshopify.com/pages/order-list | BY5: 46128.603
A6: https://sulwhasoo-jp.myshopify.com/pages/point-list | B6: text/html; charset=utf-8 | C6: 200 | D6: OK | E6: Indexable | G6: Point List | Sulwhasoo Japan | H6: 29 | I6: 257 | K6: 0 | L6: 0 | N6: 0 | O6: ポイント情報 | P6: 6 | R6: 0 | S6: カート0 | T6: 4 | U6: おすすめのキーワード | V6: 10 | Z6: https://sulwhasoo-jp.myshopify.com/pages/point-list | AF6: 519540 | AG6: 112778 | AH6: 138 | AI6: 68 | AJ6: 2.029 | AK6: 100 | AL6: Very Easy | AM6: 0.393 | AN6: 0 | AO6: 1 | AQ6: 16 | AR6: 4 | AS6: 0 | AT6: 12.5 | AU6: 116 | AV6: 57 | AW6: 0 | BE6: 1dfc1b48630cd8026fe7f2aca10f4aa8 | BF6: 0.366 | BK6: 1.1 | BL6: Point List | Sulwhasoo Japan | BM6: Sulwhasoo Japan | BN6: website | BO6: Sulwhasoo Japan | BQ6: https://sulwhasoo-jp.myshopify.com/pages/point-list | BR6: summary_large_image | BS6: Point List | Sulwhasoo Japan | BV6: Organization | BX6: https://sulwhasoo-jp.myshopify.com/pages/point-list | BY6: 46128.603
A7: https://sulwhasoo-jp.myshopify.com/pages/faq | B7: text/html; charset=utf-8 | C7: 200 | D7: OK | E7: Indexable | G7: FAQ | Sulwhasoo Japan | H7: 22 | I7: 210 | K7: 0 | L7: 0 | N7: 0 | O7: よくあるご質問 | P7: 7 | R7: 0 | S7: カート0 | T7: 4 | U7: おすすめのキーワード | V7: 10 | Z7: https://sulwhasoo-jp.myshopify.com/pages/faq | AF7: 567771 | AG7: 115641 | AH7: 223 | AI7: 153 | AJ7: 1.458 | AK7: 100 | AL7: Very Easy | AM7: 0.75 | AN7: 0 | AO7: 1 | AQ7: 52 | AR7: 30 | AS7: 0 | AT7: 93.75 | AU7: 118 | AV7: 51 | AW7: 0 | BE7: 26143999126c2e43eaf649f024566bec | BF7: 0.34 | BK7: 1.1 | BL7: FAQ | Sulwhasoo Japan | BM7: Sulwhasoo Japan | BN7: website | BO7: Sulwhasoo Japan | BQ7: https://sulwhasoo-jp.myshopify.com/pages/faq | BR7: summary_large_image | BS7: FAQ | Sulwhasoo Japan | BV7: Organization | BX7: https://sulwhasoo-jp.myshopify.com/pages/faq | BY7: 46128.603
A8: https://sulwhasoo-jp.myshopify.com/pages/exchange-return | B8: text/html; charset=utf-8 | C8: 200 | D8: OK | E8: Indexable | G8: Exchange Return | Sulwhasoo Japan | H8: 34 | I8: 322 | K8: 0 | L8: 0 | N8: 0 | O8: 交換・返品について | P8: 9 | R8: 0 | S8: カート0 | T8: 4 | U8: おすすめのキーワード | V8: 10 | Z8: https://sulwhasoo-jp.myshopify.com/pages/exchange-return | AF8: 527405 | AG8: 114240 | AH8: 180 | AI8: 93 | AJ8: 1.935 | AK8: 100 | AL8: Very Easy | AM8: 0.611 | AN8: 0 | AO8: 1 | AQ8: 52 | AR8: 30 | AS8: 0 | AT8: 93.75 | AU8: 119 | AV8: 51 | AW8: 0 | BE8: ecdca370c527ebd2c44cc47fc05447a5 | BF8: 0.753 | BK8: 1.1 | BL8: Exchange Return | Sulwhasoo Japan | BM8: Sulwhasoo Japan | BN8: website | BO8: Sulwhasoo Japan | BQ8: https://sulwhasoo-jp.myshopify.com/pages/exchange-return | BR8: summary_large_image | BS8: Exchange Return | Sulwhasoo Japan | BV8: Organization | BX8: https://sulwhasoo-jp.myshopify.com/pages/exchange-return | BY8: 46128.603
A9: https://sulwhasoo-jp.myshopify.com/pages/membership | B9: text/html; charset=utf-8 | C9: 200 | D9: OK | E9: Indexable | G9: Membership | Sulwhasoo Japan | H9: 29 | I9: 284 | K9: 0 | L9: 0 | N9: 0 | O9: メンバーシップ | P9: 7 | R9: 0 | S9: カート0 | T9: 4 | U9: おすすめのキーワード | V9: 10 | Z9: https://sulwhasoo-jp.myshopify.com/pages/membership | AF9: 529474 | AG9: 114847 | AH9: 211 | AI9: 103 | AJ9: 2.049 | AK9: 100 | AL9: Very Easy | AM9: 0.636 | AN9: 0 | AO9: 1 | AQ9: 155 | AR9: 30 | AS9: 0 | AT9: 93.75 | AU9: 119 | AV9: 51 | AW9: 0 | BE9: 2902fd37c8f205946caf414c4c97685d | BF9: 0.46 | BK9: 1.1 | BL9: Membership | Sulwhasoo Japan | BM9: Sulwhasoo Japan | BN9: website | BO9: Sulwhasoo Japan | BQ9: https://sulwhasoo-jp.myshopify.com/pages/membership | BR9: summary_large_image | BS9: Membership | Sulwhasoo Japan | BV9: Organization | BX9: https://sulwhasoo-jp.myshopify.com/pages/membership | BY9: 46128.603
A10: https://sulwhasoo-jp.myshopify.com/pages/edit-account | B10: text/html; charset=utf-8 | C10: 200 | D10: OK | E10: Indexable | G10: Edit Account | Sulwhasoo Japan | H10: 31 | I10: 284 | K10: 0 | L10: 0 | N10: 0 | O10: 個人情報の修正 | P10: 7 | R10: 0 | S10: カート0 | T10: 4 | U10: おすすめのキーワード | V10: 10 | Z10: https://sulwhasoo-jp.myshopify.com/pages/edit-account | AF10: 523711 | AG10: 113662 | AH10: 138 | AI10: 68 | AJ10: 2.029 | AK10: 100 | AL10: Very Easy | AM10: 0.391 | AN10: 0 | AO10: 1 | AQ10: 15 | AR10: 4 | AS10: 0 | AT10: 12.5 | AU10: 116 | AV10: 57 | AW10: 0 | BE10: eef09dc9509699f825109fbf1d5e892 | BF10: 0.323 | BK10: 1.1 | BL10: Edit Account | Sulwhasoo Japan | BM10: Sulwhasoo Japan | BN10: website | BO10: Sulwhasoo Japan | BQ10: https://sulwhasoo-jp.myshopify.com/pages/edit-account | BR10: summary_large_image | BS10: Edit Account | Sulwhasoo Japan | BV10: Organization | BX10: https://sulwhasoo-jp.myshopify.com/pages/edit-account | BY10: 46128.603
A11: https://sulwhasoo-jp.myshopify.com/pages/shopping-guide | B11: text/html; charset=utf-8 | C11: 200 | D11: OK | E11: Indexable | G11: Shopping Guide | Sulwhasoo Japan | H11: 33 | I11: 312 | K11: 0 | L11: 0 | N11: 0 | O11: ご注文について | P11: 7 | R11: 0 | S11: カート0 | T11: 4 | U11: おすすめのキーワード | V11: 10 | Z11: https://sulwhasoo-jp.myshopify.com/pages/shopping-guide | AF11: 529563 | AG11: 114714 | AH11: 242 | AI11: 126 | AJ11: 1.921 | AK11: 100 | AL11: Very Easy | AM11: 0.695 | AN11: 0 | AO11: 1 | AQ11: 52 | AR11: 30 | AS11: 0 | AT11: 93.75 | AU11: 119 | AV11: 51 | AW11: 0 | BE11: bea393938a3e1768f21a1b5887468e6f | BF11: 0.331 | BK11: 1.1 | BL11: Shopping Guide | Sulwhasoo Japan | BM11: Sulwhasoo Japan | BN11: website | BO11: Sulwhasoo Japan | BQ11: https://sulwhasoo-jp.myshopify.com/pages/shopping-guide | BR11: summary_large_image | BS11: Shopping Guide | Sulwhasoo Japan | BV11: Organization | BX11: https://sulwhasoo-jp.myshopify.com/pages/shopping-guide | BY11: 46128.603
A12: https://sulwhasoo-jp.myshopify.com/pages/activate-account-form | B12: text/html; charset=utf-8 | C12: 200 | D12: OK | E12: Indexable | G12: Activate Account Form | Sulwhasoo Japan | H12: 40 | I12: 376 | K12: 0 | L12: 0 | N12: 0 | P12: 0 | R12: 0 | S12: カート0 | T12: 4 | U12: おすすめのキーワード | V12: 10 | Z12: https://sulwhasoo-jp.myshopify.com/pages/activate-account-form | AF12: 512305 | AG12: 112066 | AH12: 136 | AI12: 66 | AJ12: 2.061 | AK12: 100 | AL12: Very Easy | AM12: 0.374 | AN12: 0 | AO12: 1 | AQ12: 7 | AR12: 1 | AS12: 0 | AT12: 3.13 | AU12: 104 | AV12: 52 | AW12: 0 | BE12: 705301e5d37e8f8f939b0b5e779f5851 | BF12: 0.324 | BK12: 1.1 | BL12: Activate Account Form | Sulwhasoo Japan | BM12: Sulwhasoo Japan | BN12: website | BO12: Sulwhasoo Japan | BQ12: https://sulwhasoo-jp.myshopify.com/pages/activate-account-form | BR12: summary_large_image | BS12: Activate Account Form | Sulwhasoo Japan | BV12: Organization | BX12: https://sulwhasoo-jp.myshopify.com/pages/activate-account-form | BY12: 46128.603
